File: G03999.csv
[Measurement conditions]
Sample identification,25%Ag-EA
Comment - 1,"Configuration=Programmable xy with programmable z platforms, Owner=User, Creation date=02/07/2021 13:22:25"
Comment - 2,"Goniometer=Theta/Theta; Minimum step size 2Theta:0.0001; Minimum step size Omega:0.0001"
Comment - 3,"Sample stage=Programmable xy-platform with programmable z-adjustment; Minimum step size X:0.01; Minimum step size Y:0.01; Minimum step size Z:0.001"
Comment - 4,"Diffractometer system=EMPYREAN"
Comment - 5,"Measurement program=C:\PANalytical\Data Collector\Programs\Knapp Group (CK)\Songming Liu\20-80°, 0.05° step, 0.5s-step.xrdmp, Created identifier={D6D0720B-9417-4404-86A5-80CEFF14CAE1}, Created by=User, Id=WL:EMPYREANGI:User, Creation date=20/06/2024 10:10:34"
Anode material,Cu
K-Alpha1 wavelength,1.5405980
K-Alpha2 wavelength,1.5444260
Ratio K-Alpha2/K-Alpha1,0.500
Divergence slit,Fixed,0.76mm
Monochromator used,NO
Generator voltage, 40
Tube current, 40
File date and time,15/Jul/2024 11:46
Unit cell,
h k l, 0 0 0
Scan axis,2Theta
Scan range,20.00000,80.00000
Scan step size,0.0500000
No. of points, 1200
Scan type,CONTINUOUS
Omega,1.0000
X,1.09
Y,-2.50
Z,20.282
Time per step,0.50
[Scan points]
Angle, TimePerStep, Intensity, ESD
20.02500, 0.50, 73.0, 8.5440
20.07500, 0.50, 61.0, 7.8102
20.12500, 0.50, 55.0, 7.4162
20.17500, 0.50, 50.0, 7.0711
20.22500, 0.50, 60.0, 7.7460
20.27500, 0.50, 53.0, 7.2801
20.32500, 0.50, 53.0, 7.2801
20.37500, 0.50, 57.0, 7.5498
20.42500, 0.50, 42.0, 6.4807
20.47500, 0.50, 55.0, 7.4162
20.52500, 0.50, 69.0, 8.3066
20.57500, 0.50, 50.0, 7.0711
20.62500, 0.50, 52.0, 7.2111
20.67500, 0.50, 53.0, 7.2801
20.72500, 0.50, 49.0, 7.0000
20.77500, 0.50, 39.0, 6.2450
20.82500, 0.50, 51.0, 7.1414
20.87500, 0.50, 50.0, 7.0711
20.92500, 0.50, 51.0, 7.1414
20.97500, 0.50, 46.0, 6.7823
21.02500, 0.50, 50.0, 7.0711
21.07500, 0.50, 59.0, 7.6811
21.12500, 0.50, 49.0, 7.0000
21.17500, 0.50, 55.0, 7.4162
21.22500, 0.50, 48.0, 6.9282
21.27500, 0.50, 54.0, 7.3485
21.32500, 0.50, 40.0, 6.3246
21.37500, 0.50, 46.0, 6.7823
21.42500, 0.50, 51.0, 7.1414
21.47500, 0.50, 59.0, 7.6811
21.52500, 0.50, 55.0, 7.4162
21.57500, 0.50, 45.0, 6.7082
21.62500, 0.50, 46.0, 6.7823
21.67500, 0.50, 61.0, 7.8102
21.72500, 0.50, 39.0, 6.2450
21.77500, 0.50, 51.0, 7.1414
21.82500, 0.50, 55.0, 7.4162
21.87500, 0.50, 46.0, 6.7823
21.92500, 0.50, 48.0, 6.9282
21.97500, 0.50, 62.0, 7.8740
22.02500, 0.50, 64.0, 8.0000
22.07500, 0.50, 47.0, 6.8557
22.12500, 0.50, 45.0, 6.7082
22.17500, 0.50, 55.0, 7.4162
22.22500, 0.50, 41.0, 6.4031
22.27500, 0.50, 55.0, 7.4162
22.32500, 0.50, 42.0, 6.4807
22.37500, 0.50, 53.0, 7.2801
22.42500, 0.50, 36.0, 6.0000
22.47500, 0.50, 46.0, 6.7823
22.52500, 0.50, 42.0, 6.4807
22.57500, 0.50, 58.0, 7.6158
22.62500, 0.50, 49.0, 7.0000
22.67500, 0.50, 37.0, 6.0828
22.72500, 0.50, 50.0, 7.0711
22.77500, 0.50, 52.0, 7.2111
22.82500, 0.50, 48.0, 6.9282
22.87500, 0.50, 44.0, 6.6332
22.92500, 0.50, 55.0, 7.4162
22.97500, 0.50, 43.0, 6.5574
23.02500, 0.50, 49.0, 7.0000
23.07500, 0.50, 36.0, 6.0000
23.12500, 0.50, 50.0, 7.0711
23.17500, 0.50, 35.0, 5.9161
23.22500, 0.50, 48.0, 6.9282
23.27500, 0.50, 38.0, 6.1644
23.32500, 0.50, 47.0, 6.8557
23.37500, 0.50, 42.0, 6.4807
23.42500, 0.50, 46.0, 6.7823
23.47500, 0.50, 53.0, 7.2801
23.52500, 0.50, 39.0, 6.2450
23.57500, 0.50, 51.0, 7.1414
23.62500, 0.50, 32.0, 5.6569
23.67500, 0.50, 56.0, 7.4833
23.72500, 0.50, 49.0, 7.0000
23.77500, 0.50, 48.0, 6.9282
23.82500, 0.50, 42.0, 6.4807
23.87500, 0.50, 45.0, 6.7082
23.92500, 0.50, 42.0, 6.4807
23.97500, 0.50, 41.0, 6.4031
24.02500, 0.50, 40.0, 6.3246
24.07500, 0.50, 46.0, 6.7823
24.12500, 0.50, 52.0, 7.2111
24.17500, 0.50, 34.0, 5.8310
24.22500, 0.50, 35.0, 5.9161
24.27500, 0.50, 34.0, 5.8310
24.32500, 0.50, 45.0, 6.7082
24.37500, 0.50, 41.0, 6.4031
24.42500, 0.50, 47.0, 6.8557
24.47500, 0.50, 53.0, 7.2801
24.52500, 0.50, 42.0, 6.4807
24.57500, 0.50, 35.0, 5.9161
24.62500, 0.50, 44.0, 6.6332
24.67500, 0.50, 42.0, 6.4807
24.72500, 0.50, 35.0, 5.9161
24.77500, 0.50, 51.0, 7.1414
24.82500, 0.50, 45.0, 6.7082
24.87500, 0.50, 40.0, 6.3246
24.92500, 0.50, 52.0, 7.2111
24.97500, 0.50, 41.0, 6.4031
25.02500, 0.50, 40.0, 6.3246
25.07500, 0.50, 48.0, 6.9282
25.12500, 0.50, 59.0, 7.6811
25.17500, 0.50, 38.0, 6.1644
25.22500, 0.50, 54.0, 7.3485
25.27500, 0.50, 47.0, 6.8557
25.32500, 0.50, 33.0, 5.7446
25.37500, 0.50, 39.0, 6.2450
25.42500, 0.50, 32.0, 5.6569
25.47500, 0.50, 41.0, 6.4031
25.52500, 0.50, 36.0, 6.0000
25.57500, 0.50, 32.0, 5.6569
25.62500, 0.50, 44.0, 6.6332
25.67500, 0.50, 38.0, 6.1644
25.72500, 0.50, 33.0, 5.7446
25.77500, 0.50, 42.0, 6.4807
25.82500, 0.50, 42.0, 6.4807
25.87500, 0.50, 31.0, 5.5678
25.92500, 0.50, 33.0, 5.7446
25.97500, 0.50, 26.0, 5.0990
26.02500, 0.50, 28.0, 5.2915
26.07500, 0.50, 36.0, 6.0000
26.12500, 0.50, 42.0, 6.4807
26.17500, 0.50, 29.0, 5.3852
26.22500, 0.50, 38.0, 6.1644
26.27500, 0.50, 28.0, 5.2915
26.32500, 0.50, 37.0, 6.0828
26.37500, 0.50, 40.0, 6.3246
26.42500, 0.50, 28.0, 5.2915
26.47500, 0.50, 50.0, 7.0711
26.52500, 0.50, 36.0, 6.0000
26.57500, 0.50, 38.0, 6.1644
26.62500, 0.50, 49.0, 7.0000
26.67500, 0.50, 34.0, 5.8310
26.72500, 0.50, 44.0, 6.6332
26.77500, 0.50, 28.0, 5.2915
26.82500, 0.50, 29.0, 5.3852
26.87500, 0.50, 27.0, 5.1962
26.92500, 0.50, 31.0, 5.5678
26.97500, 0.50, 36.0, 6.0000
27.02500, 0.50, 29.0, 5.3852
27.07500, 0.50, 33.0, 5.7446
27.12500, 0.50, 34.0, 5.8310
27.17500, 0.50, 33.0, 5.7446
27.22500, 0.50, 32.0, 5.6569
27.27500, 0.50, 33.0, 5.7446
27.32500, 0.50, 32.0, 5.6569
27.37500, 0.50, 32.0, 5.6569
27.42500, 0.50, 48.0, 6.9282
27.47500, 0.50, 35.0, 5.9161
27.52500, 0.50, 35.0, 5.9161
27.57500, 0.50, 34.0, 5.8310
27.62500, 0.50, 20.0, 4.4721
27.67500, 0.50, 32.0, 5.6569
27.72500, 0.50, 25.0, 5.0000
27.77500, 0.50, 35.0, 5.9161
27.82500, 0.50, 24.0, 4.8990
27.87500, 0.50, 21.0, 4.5826
27.92500, 0.50, 31.0, 5.5678
27.97500, 0.50, 29.0, 5.3852
28.02500, 0.50, 29.0, 5.3852
28.07500, 0.50, 28.0, 5.2915
28.12500, 0.50, 37.0, 6.0828
28.17500, 0.50, 32.0, 5.6569
28.22500, 0.50, 34.0, 5.8310
28.27500, 0.50, 41.0, 6.4031
28.32500, 0.50, 35.0, 5.9161
28.37500, 0.50, 32.0, 5.6569
28.42500, 0.50, 31.0, 5.5678
28.47500, 0.50, 27.0, 5.1962
28.52500, 0.50, 35.0, 5.9161
28.57500, 0.50, 33.0, 5.7446
28.62500, 0.50, 23.0, 4.7958
28.67500, 0.50, 19.0, 4.3589
28.72500, 0.50, 29.0, 5.3852
28.77500, 0.50, 38.0, 6.1644
28.82500, 0.50, 43.0, 6.5574
28.87500, 0.50, 29.0, 5.3852
28.92500, 0.50, 24.0, 4.8990
28.97500, 0.50, 28.0, 5.2915
29.02500, 0.50, 31.0, 5.5678
29.07500, 0.50, 31.0, 5.5678
29.12500, 0.50, 33.0, 5.7446
29.17500, 0.50, 30.0, 5.4772
29.22500, 0.50, 33.0, 5.7446
29.27500, 0.50, 30.0, 5.4772
29.32500, 0.50, 37.0, 6.0828
29.37500, 0.50, 27.0, 5.1962
29.42500, 0.50, 30.0, 5.4772
29.47500, 0.50, 30.0, 5.4772
29.52500, 0.50, 27.0, 5.1962
29.57500, 0.50, 25.0, 5.0000
29.62500, 0.50, 26.0, 5.0990
29.67500, 0.50, 25.0, 5.0000
29.72500, 0.50, 28.0, 5.2915
29.77500, 0.50, 20.0, 4.4721
29.82500, 0.50, 30.0, 5.4772
29.87500, 0.50, 29.0, 5.3852
29.92500, 0.50, 24.0, 4.8990
29.97500, 0.50, 32.0, 5.6569
30.02500, 0.50, 26.0, 5.0990
30.07500, 0.50, 33.0, 5.7446
30.12500, 0.50, 30.0, 5.4772
30.17500, 0.50, 18.0, 4.2426
30.22500, 0.50, 27.0, 5.1962
30.27500, 0.50, 20.0, 4.4721
30.32500, 0.50, 24.0, 4.8990
30.37500, 0.50, 36.0, 6.0000
30.42500, 0.50, 24.0, 4.8990
30.47500, 0.50, 20.0, 4.4721
30.52500, 0.50, 25.0, 5.0000
30.57500, 0.50, 23.0, 4.7958
30.62500, 0.50, 17.0, 4.1231
30.67500, 0.50, 22.0, 4.6904
30.72500, 0.50, 19.0, 4.3589
30.77500, 0.50, 17.0, 4.1231
30.82500, 0.50, 25.0, 5.0000
30.87500, 0.50, 34.0, 5.8310
30.92500, 0.50, 22.0, 4.6904
30.97500, 0.50, 22.0, 4.6904
31.02500, 0.50, 22.0, 4.6904
31.07500, 0.50, 29.0, 5.3852
31.12500, 0.50, 26.0, 5.0990
31.17500, 0.50, 19.0, 4.3589
31.22500, 0.50, 16.0, 4.0000
31.27500, 0.50, 24.0, 4.8990
31.32500, 0.50, 30.0, 5.4772
31.37500, 0.50, 20.0, 4.4721
31.42500, 0.50, 14.0, 3.7417
31.47500, 0.50, 20.0, 4.4721
31.52500, 0.50, 19.0, 4.3589
31.57500, 0.50, 17.0, 4.1231
31.62500, 0.50, 20.0, 4.4721
31.67500, 0.50, 21.0, 4.5826
31.72500, 0.50, 29.0, 5.3852
31.77500, 0.50, 24.0, 4.8990
31.82500, 0.50, 29.0, 5.3852
31.87500, 0.50, 24.0, 4.8990
31.92500, 0.50, 26.0, 5.0990
31.97500, 0.50, 34.0, 5.8310
32.02500, 0.50, 19.0, 4.3589
32.07500, 0.50, 18.0, 4.2426
32.12500, 0.50, 22.0, 4.6904
32.17500, 0.50, 23.0, 4.7958
32.22500, 0.50, 18.0, 4.2426
32.27500, 0.50, 21.0, 4.5826
32.32500, 0.50, 30.0, 5.4772
32.37500, 0.50, 8.0, 2.8284
32.42500, 0.50, 25.0, 5.0000
32.47500, 0.50, 18.0, 4.2426
32.52500, 0.50, 20.0, 4.4721
32.57500, 0.50, 20.0, 4.4721
32.62500, 0.50, 23.0, 4.7958
32.67500, 0.50, 25.0, 5.0000
32.72500, 0.50, 18.0, 4.2426
32.77500, 0.50, 30.0, 5.4772
32.82500, 0.50, 24.0, 4.8990
32.87500, 0.50, 17.0, 4.1231
32.92500, 0.50, 19.0, 4.3589
32.97500, 0.50, 18.0, 4.2426
33.02500, 0.50, 27.0, 5.1962
33.07500, 0.50, 23.0, 4.7958
33.12500, 0.50, 15.0, 3.8730
33.17500, 0.50, 22.0, 4.6904
33.22500, 0.50, 20.0, 4.4721
33.27500, 0.50, 15.0, 3.8730
33.32500, 0.50, 24.0, 4.8990
33.37500, 0.50, 22.0, 4.6904
33.42500, 0.50, 23.0, 4.7958
33.47500, 0.50, 33.0, 5.7446
33.52500, 0.50, 25.0, 5.0000
33.57500, 0.50, 15.0, 3.8730
33.62500, 0.50, 22.0, 4.6904
33.67500, 0.50, 15.0, 3.8730
33.72500, 0.50, 26.0, 5.0990
33.77500, 0.50, 17.0, 4.1231
33.82500, 0.50, 12.0, 3.4641
33.87500, 0.50, 16.0, 4.0000
33.92500, 0.50, 19.0, 4.3589
33.97500, 0.50, 26.0, 5.0990
34.02500, 0.50, 22.0, 4.6904
34.07500, 0.50, 26.0, 5.0990
34.12500, 0.50, 17.0, 4.1231
34.17500, 0.50, 19.0, 4.3589
34.22500, 0.50, 23.0, 4.7958
34.27500, 0.50, 18.0, 4.2426
34.32500, 0.50, 18.0, 4.2426
34.37500, 0.50, 17.0, 4.1231
34.42500, 0.50, 20.0, 4.4721
34.47500, 0.50, 30.0, 5.4772
34.52500, 0.50, 22.0, 4.6904
34.57500, 0.50, 20.0, 4.4721
34.62500, 0.50, 19.0, 4.3589
34.67500, 0.50, 26.0, 5.0990
34.72500, 0.50, 15.0, 3.8730
34.77500, 0.50, 18.0, 4.2426
34.82500, 0.50, 13.0, 3.6056
34.87500, 0.50, 21.0, 4.5826
34.92500, 0.50, 7.0, 2.6458
34.97500, 0.50, 16.0, 4.0000
35.02500, 0.50, 26.0, 5.0990
35.07500, 0.50, 19.0, 4.3589
35.12500, 0.50, 18.0, 4.2426
35.17500, 0.50, 13.0, 3.6056
35.22500, 0.50, 19.0, 4.3589
35.27500, 0.50, 21.0, 4.5826
35.32500, 0.50, 18.0, 4.2426
35.37500, 0.50, 27.0, 5.1962
35.42500, 0.50, 20.0, 4.4721
35.47500, 0.50, 24.0, 4.8990
35.52500, 0.50, 18.0, 4.2426
35.57500, 0.50, 16.0, 4.0000
35.62500, 0.50, 21.0, 4.5826
35.67500, 0.50, 16.0, 4.0000
35.72500, 0.50, 15.0, 3.8730
35.77500, 0.50, 18.0, 4.2426
35.82500, 0.50, 20.0, 4.4721
35.87500, 0.50, 18.0, 4.2426
35.92500, 0.50, 25.0, 5.0000
35.97500, 0.50, 16.0, 4.0000
36.02500, 0.50, 25.0, 5.0000
36.07500, 0.50, 23.0, 4.7958
36.12500, 0.50, 16.0, 4.0000
36.17500, 0.50, 19.0, 4.3589
36.22500, 0.50, 32.0, 5.6569
36.27500, 0.50, 24.0, 4.8990
36.32500, 0.50, 27.0, 5.1962
36.37500, 0.50, 35.0, 5.9161
36.42500, 0.50, 33.0, 5.7446
36.47500, 0.50, 22.0, 4.6904
36.52500, 0.50, 19.0, 4.3589
36.57500, 0.50, 19.0, 4.3589
36.62500, 0.50, 22.0, 4.6904
36.67500, 0.50, 24.0, 4.8990
36.72500, 0.50, 31.0, 5.5678
36.77500, 0.50, 20.0, 4.4721
36.82500, 0.50, 19.0, 4.3589
36.87500, 0.50, 13.0, 3.6056
36.92500, 0.50, 25.0, 5.0000
36.97500, 0.50, 21.0, 4.5826
37.02500, 0.50, 23.0, 4.7958
37.07500, 0.50, 23.0, 4.7958
37.12500, 0.50, 16.0, 4.0000
37.17500, 0.50, 31.0, 5.5678
37.22500, 0.50, 26.0, 5.0990
37.27500, 0.50, 33.0, 5.7446
37.32500, 0.50, 30.0, 5.4772
37.37500, 0.50, 16.0, 4.0000
37.42500, 0.50, 43.0, 6.5574
37.47500, 0.50, 33.0, 5.7446
37.52500, 0.50, 30.0, 5.4772
37.57500, 0.50, 38.0, 6.1644
37.62500, 0.50, 58.0, 7.6158
37.67500, 0.50, 53.0, 7.2801
37.72500, 0.50, 71.0, 8.4261
37.77500, 0.50, 126.0, 11.2250
37.82500, 0.50, 164.0, 12.8062
37.87500, 0.50, 256.0, 16.0000
37.92500, 0.50, 452.0, 21.2603
37.97500, 0.50, 609.0, 24.6779
38.02500, 0.50, 977.0, 31.2570
38.07500, 0.50, 1128.0, 33.5857
38.12500, 0.50, 1014.0, 31.8434
38.17500, 0.50, 782.0, 27.9643
38.22500, 0.50, 505.0, 22.4722
38.27500, 0.50, 211.0, 14.5258
38.32500, 0.50, 112.0, 10.5830
38.37500, 0.50, 61.0, 7.8102
38.42500, 0.50, 39.0, 6.2450
38.47500, 0.50, 38.0, 6.1644
38.52500, 0.50, 41.0, 6.4031
38.57500, 0.50, 30.0, 5.4772
38.62500, 0.50, 24.0, 4.8990
38.67500, 0.50, 32.0, 5.6569
38.72500, 0.50, 26.0, 5.0990
38.77500, 0.50, 27.0, 5.1962
38.82500, 0.50, 30.0, 5.4772
38.87500, 0.50, 20.0, 4.4721
38.92500, 0.50, 22.0, 4.6904
38.97500, 0.50, 16.0, 4.0000
39.02500, 0.50, 22.0, 4.6904
39.07500, 0.50, 18.0, 4.2426
39.12500, 0.50, 16.0, 4.0000
39.17500, 0.50, 19.0, 4.3589
39.22500, 0.50, 12.0, 3.4641
39.27500, 0.50, 24.0, 4.8990
39.32500, 0.50, 26.0, 5.0990
39.37500, 0.50, 15.0, 3.8730
39.42500, 0.50, 12.0, 3.4641
39.47500, 0.50, 19.0, 4.3589
39.52500, 0.50, 18.0, 4.2426
39.57500, 0.50, 14.0, 3.7417
39.62500, 0.50, 20.0, 4.4721
39.67500, 0.50, 23.0, 4.7958
39.72500, 0.50, 14.0, 3.7417
39.77500, 0.50, 12.0, 3.4641
39.82500, 0.50, 19.0, 4.3589
39.87500, 0.50, 21.0, 4.5826
39.92500, 0.50, 12.0, 3.4641
39.97500, 0.50, 12.0, 3.4641
40.02500, 0.50, 14.0, 3.7417
40.07500, 0.50, 19.0, 4.3589
40.12500, 0.50, 10.0, 3.1623
40.17500, 0.50, 19.0, 4.3589
40.22500, 0.50, 13.0, 3.6056
40.27500, 0.50, 21.0, 4.5826
40.32500, 0.50, 18.0, 4.2426
40.37500, 0.50, 13.0, 3.6056
40.42500, 0.50, 19.0, 4.3589
40.47500, 0.50, 17.0, 4.1231
40.52500, 0.50, 15.0, 3.8730
40.57500, 0.50, 11.0, 3.3166
40.62500, 0.50, 10.0, 3.1623
40.67500, 0.50, 10.0, 3.1623
40.72500, 0.50, 12.0, 3.4641
40.77500, 0.50, 14.0, 3.7417
40.82500, 0.50, 9.0, 3.0000
40.87500, 0.50, 15.0, 3.8730
40.92500, 0.50, 17.0, 4.1231
40.97500, 0.50, 8.0, 2.8284
41.02500, 0.50, 13.0, 3.6056
41.07500, 0.50, 23.0, 4.7958
41.12500, 0.50, 25.0, 5.0000
41.17500, 0.50, 14.0, 3.7417
41.22500, 0.50, 15.0, 3.8730
41.27500, 0.50, 19.0, 4.3589
41.32500, 0.50, 14.0, 3.7417
41.37500, 0.50, 11.0, 3.3166
41.42500, 0.50, 17.0, 4.1231
41.47500, 0.50, 21.0, 4.5826
41.52500, 0.50, 14.0, 3.7417
41.57500, 0.50, 20.0, 4.4721
41.62500, 0.50, 16.0, 4.0000
41.67500, 0.50, 20.0, 4.4721
41.72500, 0.50, 18.0, 4.2426
41.77500, 0.50, 20.0, 4.4721
41.82500, 0.50, 19.0, 4.3589
41.87500, 0.50, 11.0, 3.3166
41.92500, 0.50, 24.0, 4.8990
41.97500, 0.50, 21.0, 4.5826
42.02500, 0.50, 16.0, 4.0000
42.07500, 0.50, 21.0, 4.5826
42.12500, 0.50, 28.0, 5.2915
42.17500, 0.50, 13.0, 3.6056
42.22500, 0.50, 17.0, 4.1231
42.27500, 0.50, 15.0, 3.8730
42.32500, 0.50, 22.0, 4.6904
42.37500, 0.50, 21.0, 4.5826
42.42500, 0.50, 20.0, 4.4721
42.47500, 0.50, 22.0, 4.6904
42.52500, 0.50, 17.0, 4.1231
42.57500, 0.50, 23.0, 4.7958
42.62500, 0.50, 22.0, 4.6904
42.67500, 0.50, 30.0, 5.4772
42.72500, 0.50, 23.0, 4.7958
42.77500, 0.50, 29.0, 5.3852
42.82500, 0.50, 33.0, 5.7446
42.87500, 0.50, 46.0, 6.7823
42.92500, 0.50, 48.0, 6.9282
42.97500, 0.50, 69.0, 8.3066
43.02500, 0.50, 105.0, 10.2470
43.07500, 0.50, 151.0, 12.2882
43.12500, 0.50, 248.0, 15.7480
43.17500, 0.50, 340.0, 18.4391
43.22500, 0.50, 504.0, 22.4499
43.27500, 0.50, 580.0, 24.0832
43.32500, 0.50, 539.0, 23.2164
43.37500, 0.50, 466.0, 21.5870
43.42500, 0.50, 333.0, 18.2483
43.47500, 0.50, 187.0, 13.6748
43.52500, 0.50, 103.0, 10.1489
43.57500, 0.50, 55.0, 7.4162
43.62500, 0.50, 53.0, 7.2801
43.67500, 0.50, 43.0, 6.5574
43.72500, 0.50, 42.0, 6.4807
43.77500, 0.50, 43.0, 6.5574
43.82500, 0.50, 45.0, 6.7082
43.87500, 0.50, 50.0, 7.0711
43.92500, 0.50, 51.0, 7.1414
43.97500, 0.50, 74.0, 8.6023
44.02500, 0.50, 103.0, 10.1489
44.07500, 0.50, 171.0, 13.0767
44.12500, 0.50, 249.0, 15.7797
44.17500, 0.50, 289.0, 17.0000
44.22500, 0.50, 335.0, 18.3030
44.27500, 0.50, 360.0, 18.9737
44.32500, 0.50, 329.0, 18.1384
44.37500, 0.50, 269.0, 16.4012
44.42500, 0.50, 218.0, 14.7648
44.47500, 0.50, 138.0, 11.7473
44.52500, 0.50, 99.0, 9.9499
44.57500, 0.50, 51.0, 7.1414
44.62500, 0.50, 40.0, 6.3246
44.67500, 0.50, 24.0, 4.8990
44.72500, 0.50, 19.0, 4.3589
44.77500, 0.50, 31.0, 5.5678
44.82500, 0.50, 22.0, 4.6904
44.87500, 0.50, 20.0, 4.4721
44.92500, 0.50, 18.0, 4.2426
44.97500, 0.50, 16.0, 4.0000
45.02500, 0.50, 19.0, 4.3589
45.07500, 0.50, 13.0, 3.6056
45.12500, 0.50, 7.0, 2.6458
45.17500, 0.50, 18.0, 4.2426
45.22500, 0.50, 6.0, 2.4495
45.27500, 0.50, 20.0, 4.4721
45.32500, 0.50, 14.0, 3.7417
45.37500, 0.50, 12.0, 3.4641
45.42500, 0.50, 10.0, 3.1623
45.47500, 0.50, 16.0, 4.0000
45.52500, 0.50, 13.0, 3.6056
45.57500, 0.50, 14.0, 3.7417
45.62500, 0.50, 13.0, 3.6056
45.67500, 0.50, 10.0, 3.1623
45.72500, 0.50, 13.0, 3.6056
45.77500, 0.50, 9.0, 3.0000
45.82500, 0.50, 11.0, 3.3166
45.87500, 0.50, 10.0, 3.1623
45.92500, 0.50, 20.0, 4.4721
45.97500, 0.50, 14.0, 3.7417
46.02500, 0.50, 8.0, 2.8284
46.07500, 0.50, 8.0, 2.8284
46.12500, 0.50, 11.0, 3.3166
46.17500, 0.50, 15.0, 3.8730
46.22500, 0.50, 13.0, 3.6056
46.27500, 0.50, 9.0, 3.0000
46.32500, 0.50, 10.0, 3.1623
46.37500, 0.50, 12.0, 3.4641
46.42500, 0.50, 11.0, 3.3166
46.47500, 0.50, 8.0, 2.8284
46.52500, 0.50, 8.0, 2.8284
46.57500, 0.50, 13.0, 3.6056
46.62500, 0.50, 13.0, 3.6056
46.67500, 0.50, 8.0, 2.8284
46.72500, 0.50, 11.0, 3.3166
46.77500, 0.50, 10.0, 3.1623
46.82500, 0.50, 11.0, 3.3166
46.87500, 0.50, 6.0, 2.4495
46.92500, 0.50, 10.0, 3.1623
46.97500, 0.50, 15.0, 3.8730
47.02500, 0.50, 12.0, 3.4641
47.07500, 0.50, 6.0, 2.4495
47.12500, 0.50, 8.0, 2.8284
47.17500, 0.50, 12.0, 3.4641
47.22500, 0.50, 7.0, 2.6458
47.27500, 0.50, 14.0, 3.7417
47.32500, 0.50, 20.0, 4.4721
47.37500, 0.50, 11.0, 3.3166
47.42500, 0.50, 6.0, 2.4495
47.47500, 0.50, 5.0, 2.2361
47.52500, 0.50, 9.0, 3.0000
47.57500, 0.50, 6.0, 2.4495
47.62500, 0.50, 7.0, 2.6458
47.67500, 0.50, 11.0, 3.3166
47.72500, 0.50, 9.0, 3.0000
47.77500, 0.50, 12.0, 3.4641
47.82500, 0.50, 9.0, 3.0000
47.87500, 0.50, 10.0, 3.1623
47.92500, 0.50, 10.0, 3.1623
47.97500, 0.50, 12.0, 3.4641
48.02500, 0.50, 12.0, 3.4641
48.07500, 0.50, 11.0, 3.3166
48.12500, 0.50, 9.0, 3.0000
48.17500, 0.50, 7.0, 2.6458
48.22500, 0.50, 14.0, 3.7417
48.27500, 0.50, 17.0, 4.1231
48.32500, 0.50, 9.0, 3.0000
48.37500, 0.50, 11.0, 3.3166
48.42500, 0.50, 5.0, 2.2361
48.47500, 0.50, 10.0, 3.1623
48.52500, 0.50, 11.0, 3.3166
48.57500, 0.50, 11.0, 3.3166
48.62500, 0.50, 11.0, 3.3166
48.67500, 0.50, 10.0, 3.1623
48.72500, 0.50, 11.0, 3.3166
48.77500, 0.50, 10.0, 3.1623
48.82500, 0.50, 14.0, 3.7417
48.87500, 0.50, 12.0, 3.4641
48.92500, 0.50, 14.0, 3.7417
48.97500, 0.50, 12.0, 3.4641
49.02500, 0.50, 8.0, 2.8284
49.07500, 0.50, 9.0, 3.0000
49.12500, 0.50, 9.0, 3.0000
49.17500, 0.50, 6.0, 2.4495
49.22500, 0.50, 13.0, 3.6056
49.27500, 0.50, 10.0, 3.1623
49.32500, 0.50, 12.0, 3.4641
49.37500, 0.50, 6.0, 2.4495
49.42500, 0.50, 10.0, 3.1623
49.47500, 0.50, 11.0, 3.3166
49.52500, 0.50, 13.0, 3.6056
49.57500, 0.50, 10.0, 3.1623
49.62500, 0.50, 8.0, 2.8284
49.67500, 0.50, 11.0, 3.3166
49.72500, 0.50, 12.0, 3.4641
49.77500, 0.50, 19.0, 4.3589
49.82500, 0.50, 12.0, 3.4641
49.87500, 0.50, 7.0, 2.6458
49.92500, 0.50, 25.0, 5.0000
49.97500, 0.50, 22.0, 4.6904
50.02500, 0.50, 35.0, 5.9161
50.07500, 0.50, 34.0, 5.8310
50.12500, 0.50, 34.0, 5.8310
50.17500, 0.50, 68.0, 8.2462
50.22500, 0.50, 84.0, 9.1652
50.27500, 0.50, 121.0, 11.0000
50.32500, 0.50, 145.0, 12.0416
50.37500, 0.50, 183.0, 13.5277
50.42500, 0.50, 183.0, 13.5277
50.47500, 0.50, 161.0, 12.6886
50.52500, 0.50, 163.0, 12.7671
50.57500, 0.50, 137.0, 11.7047
50.62500, 0.50, 88.0, 9.3808
50.67500, 0.50, 60.0, 7.7460
50.72500, 0.50, 48.0, 6.9282
50.77500, 0.50, 34.0, 5.8310
50.82500, 0.50, 30.0, 5.4772
50.87500, 0.50, 15.0, 3.8730
50.92500, 0.50, 15.0, 3.8730
50.97500, 0.50, 13.0, 3.6056
51.02500, 0.50, 13.0, 3.6056
51.07500, 0.50, 15.0, 3.8730
51.12500, 0.50, 12.0, 3.4641
51.17500, 0.50, 10.0, 3.1623
51.22500, 0.50, 7.0, 2.6458
51.27500, 0.50, 11.0, 3.3166
51.32500, 0.50, 6.0, 2.4495
51.37500, 0.50, 15.0, 3.8730
51.42500, 0.50, 12.0, 3.4641
51.47500, 0.50, 6.0, 2.4495
51.52500, 0.50, 12.0, 3.4641
51.57500, 0.50, 7.0, 2.6458
51.62500, 0.50, 12.0, 3.4641
51.67500, 0.50, 9.0, 3.0000
51.72500, 0.50, 6.0, 2.4495
51.77500, 0.50, 11.0, 3.3166
51.82500, 0.50, 12.0, 3.4641
51.87500, 0.50, 4.0, 2.0000
51.92500, 0.50, 6.0, 2.4495
51.97500, 0.50, 10.0, 3.1623
52.02500, 0.50, 8.0, 2.8284
52.07500, 0.50, 7.0, 2.6458
52.12500, 0.50, 11.0, 3.3166
52.17500, 0.50, 9.0, 3.0000
52.22500, 0.50, 5.0, 2.2361
52.27500, 0.50, 3.0, 1.7321
52.32500, 0.50, 11.0, 3.3166
52.37500, 0.50, 11.0, 3.3166
52.42500, 0.50, 8.0, 2.8284
52.47500, 0.50, 8.0, 2.8284
52.52500, 0.50, 9.0, 3.0000
52.57500, 0.50, 9.0, 3.0000
52.62500, 0.50, 5.0, 2.2361
52.67500, 0.50, 5.0, 2.2361
52.72500, 0.50, 9.0, 3.0000
52.77500, 0.50, 7.0, 2.6458
52.82500, 0.50, 10.0, 3.1623
52.87500, 0.50, 11.0, 3.3166
52.92500, 0.50, 6.0, 2.4495
52.97500, 0.50, 6.0, 2.4495
53.02500, 0.50, 7.0, 2.6458
53.07500, 0.50, 6.0, 2.4495
53.12500, 0.50, 9.0, 3.0000
53.17500, 0.50, 8.0, 2.8284
53.22500, 0.50, 9.0, 3.0000
53.27500, 0.50, 10.0, 3.1623
53.32500, 0.50, 11.0, 3.3166
53.37500, 0.50, 4.0, 2.0000
53.42500, 0.50, 14.0, 3.7417
53.47500, 0.50, 9.0, 3.0000
53.52500, 0.50, 6.0, 2.4495
53.57500, 0.50, 5.0, 2.2361
53.62500, 0.50, 5.0, 2.2361
53.67500, 0.50, 6.0, 2.4495
53.72500, 0.50, 5.0, 2.2361
53.77500, 0.50, 9.0, 3.0000
53.82500, 0.50, 5.0, 2.2361
53.87500, 0.50, 7.0, 2.6458
53.92500, 0.50, 7.0, 2.6458
53.97500, 0.50, 7.0, 2.6458
54.02500, 0.50, 6.0, 2.4495
54.07500, 0.50, 9.0, 3.0000
54.12500, 0.50, 10.0, 3.1623
54.17500, 0.50, 10.0, 3.1623
54.22500, 0.50, 7.0, 2.6458
54.27500, 0.50, 5.0, 2.2361
54.32500, 0.50, 5.0, 2.2361
54.37500, 0.50, 9.0, 3.0000
54.42500, 0.50, 9.0, 3.0000
54.47500, 0.50, 9.0, 3.0000
54.52500, 0.50, 7.0, 2.6458
54.57500, 0.50, 5.0, 2.2361
54.62500, 0.50, 8.0, 2.8284
54.67500, 0.50, 8.0, 2.8284
54.72500, 0.50, 8.0, 2.8284
54.77500, 0.50, 8.0, 2.8284
54.82500, 0.50, 14.0, 3.7417
54.87500, 0.50, 8.0, 2.8284
54.92500, 0.50, 2.0, 1.4142
54.97500, 0.50, 6.0, 2.4495
55.02500, 0.50, 9.0, 3.0000
55.07500, 0.50, 11.0, 3.3166
55.12500, 0.50, 7.0, 2.6458
55.17500, 0.50, 5.0, 2.2361
55.22500, 0.50, 8.0, 2.8284
55.27500, 0.50, 8.0, 2.8284
55.32500, 0.50, 5.0, 2.2361
55.37500, 0.50, 7.0, 2.6458
55.42500, 0.50, 11.0, 3.3166
55.47500, 0.50, 2.0, 1.4142
55.52500, 0.50, 5.0, 2.2361
55.57500, 0.50, 3.0, 1.7321
55.62500, 0.50, 8.0, 2.8284
55.67500, 0.50, 8.0, 2.8284
55.72500, 0.50, 6.0, 2.4495
55.77500, 0.50, 5.0, 2.2361
55.82500, 0.50, 3.0, 1.7321
55.87500, 0.50, 3.0, 1.7321
55.92500, 0.50, 8.0, 2.8284
55.97500, 0.50, 4.0, 2.0000
56.02500, 0.50, 3.0, 1.7321
56.07500, 0.50, 3.0, 1.7321
56.12500, 0.50, 9.0, 3.0000
56.17500, 0.50, 8.0, 2.8284
56.22500, 0.50, 7.0, 2.6458
56.27500, 0.50, 6.0, 2.4495
56.32500, 0.50, 8.0, 2.8284
56.37500, 0.50, 3.0, 1.7321
56.42500, 0.50, 5.0, 2.2361
56.47500, 0.50, 8.0, 2.8284
56.52500, 0.50, 4.0, 2.0000
56.57500, 0.50, 8.0, 2.8284
56.62500, 0.50, 9.0, 3.0000
56.67500, 0.50, 8.0, 2.8284
56.72500, 0.50, 6.0, 2.4495
56.77500, 0.50, 6.0, 2.4495
56.82500, 0.50, 6.0, 2.4495
56.87500, 0.50, 6.0, 2.4495
56.92500, 0.50, 4.0, 2.0000
56.97500, 0.50, 7.0, 2.6458
57.02500, 0.50, 3.0, 1.7321
57.07500, 0.50, 5.0, 2.2361
57.12500, 0.50, 8.0, 2.8284
57.17500, 0.50, 12.0, 3.4641
57.22500, 0.50, 4.0, 2.0000
57.27500, 0.50, 12.0, 3.4641
57.32500, 0.50, 6.0, 2.4495
57.37500, 0.50, 4.0, 2.0000
57.42500, 0.50, 5.0, 2.2361
57.47500, 0.50, 11.0, 3.3166
57.52500, 0.50, 7.0, 2.6458
57.57500, 0.50, 9.0, 3.0000
57.62500, 0.50, 7.0, 2.6458
57.67500, 0.50, 2.0, 1.4142
57.72500, 0.50, 7.0, 2.6458
57.77500, 0.50, 10.0, 3.1623
57.82500, 0.50, 7.0, 2.6458
57.87500, 0.50, 8.0, 2.8284
57.92500, 0.50, 9.0, 3.0000
57.97500, 0.50, 9.0, 3.0000
58.02500, 0.50, 7.0, 2.6458
58.07500, 0.50, 4.0, 2.0000
58.12500, 0.50, 9.0, 3.0000
58.17500, 0.50, 9.0, 3.0000
58.22500, 0.50, 6.0, 2.4495
58.27500, 0.50, 9.0, 3.0000
58.32500, 0.50, 9.0, 3.0000
58.37500, 0.50, 9.0, 3.0000
58.42500, 0.50, 7.0, 2.6458
58.47500, 0.50, 8.0, 2.8284
58.52500, 0.50, 3.0, 1.7321
58.57500, 0.50, 4.0, 2.0000
58.62500, 0.50, 8.0, 2.8284
58.67500, 0.50, 4.0, 2.0000
58.72500, 0.50, 10.0, 3.1623
58.77500, 0.50, 9.0, 3.0000
58.82500, 0.50, 2.0, 1.4142
58.87500, 0.50, 7.0, 2.6458
58.92500, 0.50, 3.0, 1.7321
58.97500, 0.50, 5.0, 2.2361
59.02500, 0.50, 6.0, 2.4495
59.07500, 0.50, 7.0, 2.6458
59.12500, 0.50, 7.0, 2.6458
59.17500, 0.50, 8.0, 2.8284
59.22500, 0.50, 8.0, 2.8284
59.27500, 0.50, 6.0, 2.4495
59.32500, 0.50, 8.0, 2.8284
59.37500, 0.50, 6.0, 2.4495
59.42500, 0.50, 9.0, 3.0000
59.47500, 0.50, 0.0, 0.0000
59.52500, 0.50, 2.0, 1.4142
59.57500, 0.50, 9.0, 3.0000
59.62500, 0.50, 7.0, 2.6458
59.67500, 0.50, 7.0, 2.6458
59.72500, 0.50, 7.0, 2.6458
59.77500, 0.50, 3.0, 1.7321
59.82500, 0.50, 5.0, 2.2361
59.87500, 0.50, 5.0, 2.2361
59.92500, 0.50, 4.0, 2.0000
59.97500, 0.50, 4.0, 2.0000
60.02500, 0.50, 6.0, 2.4495
60.07500, 0.50, 9.0, 3.0000
60.12500, 0.50, 5.0, 2.2361
60.17500, 0.50, 6.0, 2.4495
60.22500, 0.50, 8.0, 2.8284
60.27500, 0.50, 5.0, 2.2361
60.32500, 0.50, 7.0, 2.6458
60.37500, 0.50, 7.0, 2.6458
60.42500, 0.50, 7.0, 2.6458
60.47500, 0.50, 4.0, 2.0000
60.52500, 0.50, 4.0, 2.0000
60.57500, 0.50, 9.0, 3.0000
60.62500, 0.50, 7.0, 2.6458
60.67500, 0.50, 8.0, 2.8284
60.72500, 0.50, 4.0, 2.0000
60.77500, 0.50, 2.0, 1.4142
60.82500, 0.50, 6.0, 2.4495
60.87500, 0.50, 5.0, 2.2361
60.92500, 0.50, 4.0, 2.0000
60.97500, 0.50, 9.0, 3.0000
61.02500, 0.50, 3.0, 1.7321
61.07500, 0.50, 12.0, 3.4641
61.12500, 0.50, 10.0, 3.1623
61.17500, 0.50, 10.0, 3.1623
61.22500, 0.50, 10.0, 3.1623
61.27500, 0.50, 7.0, 2.6458
61.32500, 0.50, 12.0, 3.4641
61.37500, 0.50, 7.0, 2.6458
61.42500, 0.50, 7.0, 2.6458
61.47500, 0.50, 6.0, 2.4495
61.52500, 0.50, 15.0, 3.8730
61.57500, 0.50, 7.0, 2.6458
61.62500, 0.50, 8.0, 2.8284
61.67500, 0.50, 8.0, 2.8284
61.72500, 0.50, 8.0, 2.8284
61.77500, 0.50, 11.0, 3.3166
61.82500, 0.50, 11.0, 3.3166
61.87500, 0.50, 6.0, 2.4495
61.92500, 0.50, 3.0, 1.7321
61.97500, 0.50, 8.0, 2.8284
62.02500, 0.50, 7.0, 2.6458
62.07500, 0.50, 10.0, 3.1623
62.12500, 0.50, 5.0, 2.2361
62.17500, 0.50, 10.0, 3.1623
62.22500, 0.50, 9.0, 3.0000
62.27500, 0.50, 8.0, 2.8284
62.32500, 0.50, 7.0, 2.6458
62.37500, 0.50, 10.0, 3.1623
62.42500, 0.50, 11.0, 3.3166
62.47500, 0.50, 7.0, 2.6458
62.52500, 0.50, 5.0, 2.2361
62.57500, 0.50, 9.0, 3.0000
62.62500, 0.50, 8.0, 2.8284
62.67500, 0.50, 6.0, 2.4495
62.72500, 0.50, 8.0, 2.8284
62.77500, 0.50, 5.0, 2.2361
62.82500, 0.50, 6.0, 2.4495
62.87500, 0.50, 9.0, 3.0000
62.92500, 0.50, 10.0, 3.1623
62.97500, 0.50, 7.0, 2.6458
63.02500, 0.50, 5.0, 2.2361
63.07500, 0.50, 3.0, 1.7321
63.12500, 0.50, 12.0, 3.4641
63.17500, 0.50, 9.0, 3.0000
63.22500, 0.50, 4.0, 2.0000
63.27500, 0.50, 12.0, 3.4641
63.32500, 0.50, 3.0, 1.7321
63.37500, 0.50, 16.0, 4.0000
63.42500, 0.50, 7.0, 2.6458
63.47500, 0.50, 8.0, 2.8284
63.52500, 0.50, 8.0, 2.8284
63.57500, 0.50, 11.0, 3.3166
63.62500, 0.50, 9.0, 3.0000
63.67500, 0.50, 12.0, 3.4641
63.72500, 0.50, 13.0, 3.6056
63.77500, 0.50, 9.0, 3.0000
63.82500, 0.50, 13.0, 3.6056
63.87500, 0.50, 13.0, 3.6056
63.92500, 0.50, 11.0, 3.3166
63.97500, 0.50, 14.0, 3.7417
64.02500, 0.50, 20.0, 4.4721
64.07500, 0.50, 29.0, 5.3852
64.12500, 0.50, 33.0, 5.7446
64.17500, 0.50, 43.0, 6.5574
64.22500, 0.50, 69.0, 8.3066
64.27500, 0.50, 107.0, 10.3441
64.32500, 0.50, 169.0, 13.0000
64.37500, 0.50, 169.0, 13.0000
64.42500, 0.50, 212.0, 14.5602
64.47500, 0.50, 173.0, 13.1529
64.52500, 0.50, 152.0, 12.3288
64.57500, 0.50, 130.0, 11.4018
64.62500, 0.50, 80.0, 8.9443
64.67500, 0.50, 87.0, 9.3274
64.72500, 0.50, 59.0, 7.6811
64.77500, 0.50, 30.0, 5.4772
64.82500, 0.50, 27.0, 5.1962
64.87500, 0.50, 12.0, 3.4641
64.92500, 0.50, 21.0, 4.5826
64.97500, 0.50, 10.0, 3.1623
65.02500, 0.50, 15.0, 3.8730
65.07500, 0.50, 6.0, 2.4495
65.12500, 0.50, 15.0, 3.8730
65.17500, 0.50, 13.0, 3.6056
65.22500, 0.50, 10.0, 3.1623
65.27500, 0.50, 14.0, 3.7417
65.32500, 0.50, 9.0, 3.0000
65.37500, 0.50, 9.0, 3.0000
65.42500, 0.50, 10.0, 3.1623
65.47500, 0.50, 11.0, 3.3166
65.52500, 0.50, 8.0, 2.8284
65.57500, 0.50, 9.0, 3.0000
65.62500, 0.50, 6.0, 2.4495
65.67500, 0.50, 6.0, 2.4495
65.72500, 0.50, 5.0, 2.2361
65.77500, 0.50, 8.0, 2.8284
65.82500, 0.50, 7.0, 2.6458
65.87500, 0.50, 6.0, 2.4495
65.92500, 0.50, 13.0, 3.6056
65.97500, 0.50, 8.0, 2.8284
66.02500, 0.50, 6.0, 2.4495
66.07500, 0.50, 6.0, 2.4495
66.12500, 0.50, 6.0, 2.4495
66.17500, 0.50, 8.0, 2.8284
66.22500, 0.50, 5.0, 2.2361
66.27500, 0.50, 8.0, 2.8284
66.32500, 0.50, 8.0, 2.8284
66.37500, 0.50, 3.0, 1.7321
66.42500, 0.50, 4.0, 2.0000
66.47500, 0.50, 6.0, 2.4495
66.52500, 0.50, 5.0, 2.2361
66.57500, 0.50, 10.0, 3.1623
66.62500, 0.50, 9.0, 3.0000
66.67500, 0.50, 9.0, 3.0000
66.72500, 0.50, 6.0, 2.4495
66.77500, 0.50, 7.0, 2.6458
66.82500, 0.50, 6.0, 2.4495
66.87500, 0.50, 11.0, 3.3166
66.92500, 0.50, 8.0, 2.8284
66.97500, 0.50, 7.0, 2.6458
67.02500, 0.50, 7.0, 2.6458
67.07500, 0.50, 14.0, 3.7417
67.12500, 0.50, 7.0, 2.6458
67.17500, 0.50, 6.0, 2.4495
67.22500, 0.50, 6.0, 2.4495
67.27500, 0.50, 4.0, 2.0000
67.32500, 0.50, 5.0, 2.2361
67.37500, 0.50, 8.0, 2.8284
67.42500, 0.50, 6.0, 2.4495
67.47500, 0.50, 5.0, 2.2361
67.52500, 0.50, 8.0, 2.8284
67.57500, 0.50, 5.0, 2.2361
67.62500, 0.50, 5.0, 2.2361
67.67500, 0.50, 11.0, 3.3166
67.72500, 0.50, 4.0, 2.0000
67.77500, 0.50, 7.0, 2.6458
67.82500, 0.50, 5.0, 2.2361
67.87500, 0.50, 4.0, 2.0000
67.92500, 0.50, 8.0, 2.8284
67.97500, 0.50, 7.0, 2.6458
68.02500, 0.50, 7.0, 2.6458
68.07500, 0.50, 8.0, 2.8284
68.12500, 0.50, 13.0, 3.6056
68.17500, 0.50, 4.0, 2.0000
68.22500, 0.50, 2.0, 1.4142
68.27500, 0.50, 2.0, 1.4142
68.32500, 0.50, 7.0, 2.6458
68.37500, 0.50, 5.0, 2.2361
68.42500, 0.50, 8.0, 2.8284
68.47500, 0.50, 5.0, 2.2361
68.52500, 0.50, 2.0, 1.4142
68.57500, 0.50, 4.0, 2.0000
68.62500, 0.50, 7.0, 2.6458
68.67500, 0.50, 3.0, 1.7321
68.72500, 0.50, 6.0, 2.4495
68.77500, 0.50, 13.0, 3.6056
68.82500, 0.50, 6.0, 2.4495
68.87500, 0.50, 5.0, 2.2361
68.92500, 0.50, 5.0, 2.2361
68.97500, 0.50, 8.0, 2.8284
69.02500, 0.50, 5.0, 2.2361
69.07500, 0.50, 5.0, 2.2361
69.12500, 0.50, 6.0, 2.4495
69.17500, 0.50, 4.0, 2.0000
69.22500, 0.50, 9.0, 3.0000
69.27500, 0.50, 5.0, 2.2361
69.32500, 0.50, 9.0, 3.0000
69.37500, 0.50, 6.0, 2.4495
69.42500, 0.50, 10.0, 3.1623
69.47500, 0.50, 3.0, 1.7321
69.52500, 0.50, 4.0, 2.0000
69.57500, 0.50, 3.0, 1.7321
69.62500, 0.50, 6.0, 2.4495
69.67500, 0.50, 11.0, 3.3166
69.72500, 0.50, 8.0, 2.8284
69.77500, 0.50, 8.0, 2.8284
69.82500, 0.50, 8.0, 2.8284
69.87500, 0.50, 4.0, 2.0000
69.92500, 0.50, 11.0, 3.3166
69.97500, 0.50, 8.0, 2.8284
70.02500, 0.50, 4.0, 2.0000
70.07500, 0.50, 9.0, 3.0000
70.12500, 0.50, 6.0, 2.4495
70.17500, 0.50, 4.0, 2.0000
70.22500, 0.50, 7.0, 2.6458
70.27500, 0.50, 9.0, 3.0000
70.32500, 0.50, 7.0, 2.6458
70.37500, 0.50, 7.0, 2.6458
70.42500, 0.50, 9.0, 3.0000
70.47500, 0.50, 6.0, 2.4495
70.52500, 0.50, 4.0, 2.0000
70.57500, 0.50, 9.0, 3.0000
70.62500, 0.50, 5.0, 2.2361
70.67500, 0.50, 7.0, 2.6458
70.72500, 0.50, 6.0, 2.4495
70.77500, 0.50, 4.0, 2.0000
70.82500, 0.50, 4.0, 2.0000
70.87500, 0.50, 4.0, 2.0000
70.92500, 0.50, 5.0, 2.2361
70.97500, 0.50, 10.0, 3.1623
71.02500, 0.50, 5.0, 2.2361
71.07500, 0.50, 2.0, 1.4142
71.12500, 0.50, 10.0, 3.1623
71.17500, 0.50, 5.0, 2.2361
71.22500, 0.50, 5.0, 2.2361
71.27500, 0.50, 1.0, 1.0000
71.32500, 0.50, 8.0, 2.8284
71.37500, 0.50, 7.0, 2.6458
71.42500, 0.50, 4.0, 2.0000
71.47500, 0.50, 5.0, 2.2361
71.52500, 0.50, 3.0, 1.7321
71.57500, 0.50, 8.0, 2.8284
71.62500, 0.50, 7.0, 2.6458
71.67500, 0.50, 7.0, 2.6458
71.72500, 0.50, 9.0, 3.0000
71.77500, 0.50, 8.0, 2.8284
71.82500, 0.50, 8.0, 2.8284
71.87500, 0.50, 5.0, 2.2361
71.92500, 0.50, 5.0, 2.2361
71.97500, 0.50, 6.0, 2.4495
72.02500, 0.50, 6.0, 2.4495
72.07500, 0.50, 6.0, 2.4495
72.12500, 0.50, 5.0, 2.2361
72.17500, 0.50, 6.0, 2.4495
72.22500, 0.50, 5.0, 2.2361
72.27500, 0.50, 4.0, 2.0000
72.32500, 0.50, 9.0, 3.0000
72.37500, 0.50, 7.0, 2.6458
72.42500, 0.50, 6.0, 2.4495
72.47500, 0.50, 8.0, 2.8284
72.52500, 0.50, 5.0, 2.2361
72.57500, 0.50, 4.0, 2.0000
72.62500, 0.50, 4.0, 2.0000
72.67500, 0.50, 10.0, 3.1623
72.72500, 0.50, 9.0, 3.0000
72.77500, 0.50, 14.0, 3.7417
72.82500, 0.50, 7.0, 2.6458
72.87500, 0.50, 6.0, 2.4495
72.92500, 0.50, 9.0, 3.0000
72.97500, 0.50, 7.0, 2.6458
73.02500, 0.50, 8.0, 2.8284
73.07500, 0.50, 3.0, 1.7321
73.12500, 0.50, 13.0, 3.6056
73.17500, 0.50, 10.0, 3.1623
73.22500, 0.50, 8.0, 2.8284
73.27500, 0.50, 7.0, 2.6458
73.32500, 0.50, 7.0, 2.6458
73.37500, 0.50, 8.0, 2.8284
73.42500, 0.50, 11.0, 3.3166
73.47500, 0.50, 14.0, 3.7417
73.52500, 0.50, 6.0, 2.4495
73.57500, 0.50, 8.0, 2.8284
73.62500, 0.50, 12.0, 3.4641
73.67500, 0.50, 9.0, 3.0000
73.72500, 0.50, 11.0, 3.3166
73.77500, 0.50, 23.0, 4.7958
73.82500, 0.50, 26.0, 5.0990
73.87500, 0.50, 37.0, 6.0828
73.92500, 0.50, 45.0, 6.7082
73.97500, 0.50, 51.0, 7.1414
74.02500, 0.50, 84.0, 9.1652
74.07500, 0.50, 78.0, 8.8318
74.12500, 0.50, 80.0, 8.9443
74.17500, 0.50, 91.0, 9.5394
74.22500, 0.50, 72.0, 8.4853
74.27500, 0.50, 67.0, 8.1854
74.32500, 0.50, 52.0, 7.2111
74.37500, 0.50, 48.0, 6.9282
74.42500, 0.50, 36.0, 6.0000
74.47500, 0.50, 26.0, 5.0990
74.52500, 0.50, 21.0, 4.5826
74.57500, 0.50, 13.0, 3.6056
74.62500, 0.50, 8.0, 2.8284
74.67500, 0.50, 12.0, 3.4641
74.72500, 0.50, 14.0, 3.7417
74.77500, 0.50, 12.0, 3.4641
74.82500, 0.50, 13.0, 3.6056
74.87500, 0.50, 7.0, 2.6458
74.92500, 0.50, 9.0, 3.0000
74.97500, 0.50, 10.0, 3.1623
75.02500, 0.50, 6.0, 2.4495
75.07500, 0.50, 8.0, 2.8284
75.12500, 0.50, 7.0, 2.6458
75.17500, 0.50, 8.0, 2.8284
75.22500, 0.50, 11.0, 3.3166
75.27500, 0.50, 5.0, 2.2361
75.32500, 0.50, 5.0, 2.2361
75.37500, 0.50, 6.0, 2.4495
75.42500, 0.50, 8.0, 2.8284
75.47500, 0.50, 4.0, 2.0000
75.52500, 0.50, 11.0, 3.3166
75.57500, 0.50, 7.0, 2.6458
75.62500, 0.50, 7.0, 2.6458
75.67500, 0.50, 8.0, 2.8284
75.72500, 0.50, 7.0, 2.6458
75.77500, 0.50, 5.0, 2.2361
75.82500, 0.50, 12.0, 3.4641
75.87500, 0.50, 9.0, 3.0000
75.92500, 0.50, 6.0, 2.4495
75.97500, 0.50, 7.0, 2.6458
76.02500, 0.50, 5.0, 2.2361
76.07500, 0.50, 13.0, 3.6056
76.12500, 0.50, 9.0, 3.0000
76.17500, 0.50, 6.0, 2.4495
76.22500, 0.50, 8.0, 2.8284
76.27500, 0.50, 8.0, 2.8284
76.32500, 0.50, 6.0, 2.4495
76.37500, 0.50, 7.0, 2.6458
76.42500, 0.50, 10.0, 3.1623
76.47500, 0.50, 10.0, 3.1623
76.52500, 0.50, 8.0, 2.8284
76.57500, 0.50, 10.0, 3.1623
76.62500, 0.50, 7.0, 2.6458
76.67500, 0.50, 18.0, 4.2426
76.72500, 0.50, 13.0, 3.6056
76.77500, 0.50, 10.0, 3.1623
76.82500, 0.50, 20.0, 4.4721
76.87500, 0.50, 15.0, 3.8730
76.92500, 0.50, 21.0, 4.5826
76.97500, 0.50, 31.0, 5.5678
77.02500, 0.50, 20.0, 4.4721
77.07500, 0.50, 34.0, 5.8310
77.12500, 0.50, 68.0, 8.2462
77.17500, 0.50, 72.0, 8.4853
77.22500, 0.50, 102.0, 10.0995
77.27500, 0.50, 125.0, 11.1803
77.32500, 0.50, 136.0, 11.6619
77.37500, 0.50, 163.0, 12.7671
77.42500, 0.50, 156.0, 12.4900
77.47500, 0.50, 147.0, 12.1244
77.52500, 0.50, 133.0, 11.5326
77.57500, 0.50, 114.0, 10.6771
77.62500, 0.50, 99.0, 9.9499
77.67500, 0.50, 61.0, 7.8102
77.72500, 0.50, 64.0, 8.0000
77.77500, 0.50, 50.0, 7.0711
77.82500, 0.50, 28.0, 5.2915
77.87500, 0.50, 26.0, 5.0990
77.92500, 0.50, 23.0, 4.7958
77.97500, 0.50, 13.0, 3.6056
78.02500, 0.50, 15.0, 3.8730
78.07500, 0.50, 9.0, 3.0000
78.12500, 0.50, 10.0, 3.1623
78.17500, 0.50, 9.0, 3.0000
78.22500, 0.50, 7.0, 2.6458
78.27500, 0.50, 4.0, 2.0000
78.32500, 0.50, 6.0, 2.4495
78.37500, 0.50, 3.0, 1.7321
78.42500, 0.50, 9.0, 3.0000
78.47500, 0.50, 6.0, 2.4495
78.52500, 0.50, 10.0, 3.1623
78.57500, 0.50, 4.0, 2.0000
78.62500, 0.50, 5.0, 2.2361
78.67500, 0.50, 8.0, 2.8284
78.72500, 0.50, 9.0, 3.0000
78.77500, 0.50, 11.0, 3.3166
78.82500, 0.50, 2.0, 1.4142
78.87500, 0.50, 4.0, 2.0000
78.92500, 0.50, 3.0, 1.7321
78.97500, 0.50, 9.0, 3.0000
79.02500, 0.50, 7.0, 2.6458
79.07500, 0.50, 6.0, 2.4495
79.12500, 0.50, 2.0, 1.4142
79.17500, 0.50, 6.0, 2.4495
79.22500, 0.50, 4.0, 2.0000
79.27500, 0.50, 7.0, 2.6458
79.32500, 0.50, 4.0, 2.0000
79.37500, 0.50, 5.0, 2.2361
79.42500, 0.50, 6.0, 2.4495
79.47500, 0.50, 7.0, 2.6458
79.52500, 0.50, 5.0, 2.2361
79.57500, 0.50, 7.0, 2.6458
79.62500, 0.50, 5.0, 2.2361
79.67500, 0.50, 4.0, 2.0000
79.72500, 0.50, 5.0, 2.2361
79.77500, 0.50, 7.0, 2.6458
79.82500, 0.50, 11.0, 3.3166
79.87500, 0.50, 11.0, 3.3166
79.92500, 0.50, 8.0, 2.8284
79.97500, 0.50, 4.0, 2.0000