File: G04001.csv
[Measurement conditions]
Sample identification,75%Ag-EA
Comment - 1,"Configuration=Programmable xy with programmable z platforms, Owner=User, Creation date=02/07/2021 13:22:25"
Comment - 2,"Goniometer=Theta/Theta; Minimum step size 2Theta:0.0001; Minimum step size Omega:0.0001"
Comment - 3,"Sample stage=Programmable xy-platform with programmable z-adjustment; Minimum step size X:0.01; Minimum step size Y:0.01; Minimum step size Z:0.001"
Comment - 4,"Diffractometer system=EMPYREAN"
Comment - 5,"Measurement program=C:\PANalytical\Data Collector\Programs\Knapp Group (CK)\Songming Liu\20-80°, 0.05° step, 0.5s-step.xrdmp, Created identifier={D6D0720B-9417-4404-86A5-80CEFF14CAE1}, Created by=User, Id=WL:EMPYREANGI:User, Creation date=20/06/2024 10:10:34"
Anode material,Cu
K-Alpha1 wavelength,1.5405980
K-Alpha2 wavelength,1.5444260
Ratio K-Alpha2/K-Alpha1,0.500
Divergence slit,Fixed,0.76mm
Monochromator used,NO
Generator voltage, 40
Tube current, 40
File date and time,15/Jul/2024 12:13
Unit cell,
h k l, 0 0 0
Scan axis,2Theta
Scan range,20.00000,80.00000
Scan step size,0.0500000
No. of points, 1200
Scan type,CONTINUOUS
Omega,1.0000
X,-2.84
Y,1.54
Z,20.079
Time per step,0.50
[Scan points]
Angle, TimePerStep, Intensity, ESD
20.02500, 0.50, 44.0, 6.6332
20.07500, 0.50, 38.0, 6.1644
20.12500, 0.50, 34.0, 5.8310
20.17500, 0.50, 38.0, 6.1644
20.22500, 0.50, 38.0, 6.1644
20.27500, 0.50, 32.0, 5.6569
20.32500, 0.50, 36.0, 6.0000
20.37500, 0.50, 50.0, 7.0711
20.42500, 0.50, 42.0, 6.4807
20.47500, 0.50, 47.0, 6.8557
20.52500, 0.50, 43.0, 6.5574
20.57500, 0.50, 50.0, 7.0711
20.62500, 0.50, 52.0, 7.2111
20.67500, 0.50, 43.0, 6.5574
20.72500, 0.50, 22.0, 4.6904
20.77500, 0.50, 43.0, 6.5574
20.82500, 0.50, 51.0, 7.1414
20.87500, 0.50, 43.0, 6.5574
20.92500, 0.50, 29.0, 5.3852
20.97500, 0.50, 31.0, 5.5678
21.02500, 0.50, 38.0, 6.1644
21.07500, 0.50, 43.0, 6.5574
21.12500, 0.50, 34.0, 5.8310
21.17500, 0.50, 49.0, 7.0000
21.22500, 0.50, 37.0, 6.0828
21.27500, 0.50, 48.0, 6.9282
21.32500, 0.50, 26.0, 5.0990
21.37500, 0.50, 41.0, 6.4031
21.42500, 0.50, 42.0, 6.4807
21.47500, 0.50, 51.0, 7.1414
21.52500, 0.50, 55.0, 7.4162
21.57500, 0.50, 43.0, 6.5574
21.62500, 0.50, 50.0, 7.0711
21.67500, 0.50, 31.0, 5.5678
21.72500, 0.50, 53.0, 7.2801
21.77500, 0.50, 40.0, 6.3246
21.82500, 0.50, 41.0, 6.4031
21.87500, 0.50, 30.0, 5.4772
21.92500, 0.50, 39.0, 6.2450
21.97500, 0.50, 46.0, 6.7823
22.02500, 0.50, 27.0, 5.1962
22.07500, 0.50, 39.0, 6.2450
22.12500, 0.50, 36.0, 6.0000
22.17500, 0.50, 46.0, 6.7823
22.22500, 0.50, 32.0, 5.6569
22.27500, 0.50, 30.0, 5.4772
22.32500, 0.50, 34.0, 5.8310
22.37500, 0.50, 33.0, 5.7446
22.42500, 0.50, 36.0, 6.0000
22.47500, 0.50, 41.0, 6.4031
22.52500, 0.50, 35.0, 5.9161
22.57500, 0.50, 40.0, 6.3246
22.62500, 0.50, 37.0, 6.0828
22.67500, 0.50, 36.0, 6.0000
22.72500, 0.50, 41.0, 6.4031
22.77500, 0.50, 40.0, 6.3246
22.82500, 0.50, 35.0, 5.9161
22.87500, 0.50, 29.0, 5.3852
22.92500, 0.50, 46.0, 6.7823
22.97500, 0.50, 30.0, 5.4772
23.02500, 0.50, 37.0, 6.0828
23.07500, 0.50, 43.0, 6.5574
23.12500, 0.50, 42.0, 6.4807
23.17500, 0.50, 28.0, 5.2915
23.22500, 0.50, 27.0, 5.1962
23.27500, 0.50, 43.0, 6.5574
23.32500, 0.50, 41.0, 6.4031
23.37500, 0.50, 28.0, 5.2915
23.42500, 0.50, 43.0, 6.5574
23.47500, 0.50, 28.0, 5.2915
23.52500, 0.50, 45.0, 6.7082
23.57500, 0.50, 38.0, 6.1644
23.62500, 0.50, 31.0, 5.5678
23.67500, 0.50, 28.0, 5.2915
23.72500, 0.50, 27.0, 5.1962
23.77500, 0.50, 50.0, 7.0711
23.82500, 0.50, 33.0, 5.7446
23.87500, 0.50, 38.0, 6.1644
23.92500, 0.50, 46.0, 6.7823
23.97500, 0.50, 35.0, 5.9161
24.02500, 0.50, 32.0, 5.6569
24.07500, 0.50, 19.0, 4.3589
24.12500, 0.50, 45.0, 6.7082
24.17500, 0.50, 50.0, 7.0711
24.22500, 0.50, 39.0, 6.2450
24.27500, 0.50, 35.0, 5.9161
24.32500, 0.50, 28.0, 5.2915
24.37500, 0.50, 46.0, 6.7823
24.42500, 0.50, 34.0, 5.8310
24.47500, 0.50, 38.0, 6.1644
24.52500, 0.50, 28.0, 5.2915
24.57500, 0.50, 36.0, 6.0000
24.62500, 0.50, 30.0, 5.4772
24.67500, 0.50, 41.0, 6.4031
24.72500, 0.50, 27.0, 5.1962
24.77500, 0.50, 32.0, 5.6569
24.82500, 0.50, 40.0, 6.3246
24.87500, 0.50, 35.0, 5.9161
24.92500, 0.50, 33.0, 5.7446
24.97500, 0.50, 32.0, 5.6569
25.02500, 0.50, 27.0, 5.1962
25.07500, 0.50, 29.0, 5.3852
25.12500, 0.50, 39.0, 6.2450
25.17500, 0.50, 35.0, 5.9161
25.22500, 0.50, 25.0, 5.0000
25.27500, 0.50, 33.0, 5.7446
25.32500, 0.50, 21.0, 4.5826
25.37500, 0.50, 26.0, 5.0990
25.42500, 0.50, 31.0, 5.5678
25.47500, 0.50, 26.0, 5.0990
25.52500, 0.50, 29.0, 5.3852
25.57500, 0.50, 37.0, 6.0828
25.62500, 0.50, 38.0, 6.1644
25.67500, 0.50, 25.0, 5.0000
25.72500, 0.50, 38.0, 6.1644
25.77500, 0.50, 24.0, 4.8990
25.82500, 0.50, 29.0, 5.3852
25.87500, 0.50, 34.0, 5.8310
25.92500, 0.50, 27.0, 5.1962
25.97500, 0.50, 24.0, 4.8990
26.02500, 0.50, 31.0, 5.5678
26.07500, 0.50, 40.0, 6.3246
26.12500, 0.50, 25.0, 5.0000
26.17500, 0.50, 30.0, 5.4772
26.22500, 0.50, 25.0, 5.0000
26.27500, 0.50, 30.0, 5.4772
26.32500, 0.50, 23.0, 4.7958
26.37500, 0.50, 28.0, 5.2915
26.42500, 0.50, 34.0, 5.8310
26.47500, 0.50, 23.0, 4.7958
26.52500, 0.50, 38.0, 6.1644
26.57500, 0.50, 30.0, 5.4772
26.62500, 0.50, 24.0, 4.8990
26.67500, 0.50, 26.0, 5.0990
26.72500, 0.50, 28.0, 5.2915
26.77500, 0.50, 36.0, 6.0000
26.82500, 0.50, 36.0, 6.0000
26.87500, 0.50, 27.0, 5.1962
26.92500, 0.50, 28.0, 5.2915
26.97500, 0.50, 29.0, 5.3852
27.02500, 0.50, 25.0, 5.0000
27.07500, 0.50, 31.0, 5.5678
27.12500, 0.50, 31.0, 5.5678
27.17500, 0.50, 34.0, 5.8310
27.22500, 0.50, 30.0, 5.4772
27.27500, 0.50, 21.0, 4.5826
27.32500, 0.50, 22.0, 4.6904
27.37500, 0.50, 23.0, 4.7958
27.42500, 0.50, 29.0, 5.3852
27.47500, 0.50, 30.0, 5.4772
27.52500, 0.50, 27.0, 5.1962
27.57500, 0.50, 30.0, 5.4772
27.62500, 0.50, 21.0, 4.5826
27.67500, 0.50, 22.0, 4.6904
27.72500, 0.50, 24.0, 4.8990
27.77500, 0.50, 21.0, 4.5826
27.82500, 0.50, 22.0, 4.6904
27.87500, 0.50, 21.0, 4.5826
27.92500, 0.50, 20.0, 4.4721
27.97500, 0.50, 23.0, 4.7958
28.02500, 0.50, 31.0, 5.5678
28.07500, 0.50, 28.0, 5.2915
28.12500, 0.50, 20.0, 4.4721
28.17500, 0.50, 25.0, 5.0000
28.22500, 0.50, 22.0, 4.6904
28.27500, 0.50, 20.0, 4.4721
28.32500, 0.50, 18.0, 4.2426
28.37500, 0.50, 22.0, 4.6904
28.42500, 0.50, 21.0, 4.5826
28.47500, 0.50, 21.0, 4.5826
28.52500, 0.50, 25.0, 5.0000
28.57500, 0.50, 28.0, 5.2915
28.62500, 0.50, 31.0, 5.5678
28.67500, 0.50, 24.0, 4.8990
28.72500, 0.50, 25.0, 5.0000
28.77500, 0.50, 22.0, 4.6904
28.82500, 0.50, 20.0, 4.4721
28.87500, 0.50, 31.0, 5.5678
28.92500, 0.50, 32.0, 5.6569
28.97500, 0.50, 24.0, 4.8990
29.02500, 0.50, 18.0, 4.2426
29.07500, 0.50, 19.0, 4.3589
29.12500, 0.50, 26.0, 5.0990
29.17500, 0.50, 26.0, 5.0990
29.22500, 0.50, 24.0, 4.8990
29.27500, 0.50, 43.0, 6.5574
29.32500, 0.50, 31.0, 5.5678
29.37500, 0.50, 37.0, 6.0828
29.42500, 0.50, 27.0, 5.1962
29.47500, 0.50, 24.0, 4.8990
29.52500, 0.50, 17.0, 4.1231
29.57500, 0.50, 22.0, 4.6904
29.62500, 0.50, 26.0, 5.0990
29.67500, 0.50, 24.0, 4.8990
29.72500, 0.50, 21.0, 4.5826
29.77500, 0.50, 24.0, 4.8990
29.82500, 0.50, 24.0, 4.8990
29.87500, 0.50, 20.0, 4.4721
29.92500, 0.50, 16.0, 4.0000
29.97500, 0.50, 29.0, 5.3852
30.02500, 0.50, 20.0, 4.4721
30.07500, 0.50, 16.0, 4.0000
30.12500, 0.50, 26.0, 5.0990
30.17500, 0.50, 29.0, 5.3852
30.22500, 0.50, 32.0, 5.6569
30.27500, 0.50, 30.0, 5.4772
30.32500, 0.50, 21.0, 4.5826
30.37500, 0.50, 21.0, 4.5826
30.42500, 0.50, 13.0, 3.6056
30.47500, 0.50, 23.0, 4.7958
30.52500, 0.50, 20.0, 4.4721
30.57500, 0.50, 19.0, 4.3589
30.62500, 0.50, 22.0, 4.6904
30.67500, 0.50, 21.0, 4.5826
30.72500, 0.50, 23.0, 4.7958
30.77500, 0.50, 23.0, 4.7958
30.82500, 0.50, 25.0, 5.0000
30.87500, 0.50, 20.0, 4.4721
30.92500, 0.50, 23.0, 4.7958
30.97500, 0.50, 23.0, 4.7958
31.02500, 0.50, 15.0, 3.8730
31.07500, 0.50, 20.0, 4.4721
31.12500, 0.50, 18.0, 4.2426
31.17500, 0.50, 17.0, 4.1231
31.22500, 0.50, 16.0, 4.0000
31.27500, 0.50, 22.0, 4.6904
31.32500, 0.50, 20.0, 4.4721
31.37500, 0.50, 18.0, 4.2426
31.42500, 0.50, 24.0, 4.8990
31.47500, 0.50, 16.0, 4.0000
31.52500, 0.50, 20.0, 4.4721
31.57500, 0.50, 18.0, 4.2426
31.62500, 0.50, 26.0, 5.0990
31.67500, 0.50, 23.0, 4.7958
31.72500, 0.50, 17.0, 4.1231
31.77500, 0.50, 32.0, 5.6569
31.82500, 0.50, 24.0, 4.8990
31.87500, 0.50, 24.0, 4.8990
31.92500, 0.50, 16.0, 4.0000
31.97500, 0.50, 19.0, 4.3589
32.02500, 0.50, 21.0, 4.5826
32.07500, 0.50, 19.0, 4.3589
32.12500, 0.50, 22.0, 4.6904
32.17500, 0.50, 13.0, 3.6056
32.22500, 0.50, 17.0, 4.1231
32.27500, 0.50, 16.0, 4.0000
32.32500, 0.50, 19.0, 4.3589
32.37500, 0.50, 25.0, 5.0000
32.42500, 0.50, 14.0, 3.7417
32.47500, 0.50, 15.0, 3.8730
32.52500, 0.50, 4.0, 2.0000
32.57500, 0.50, 21.0, 4.5826
32.62500, 0.50, 16.0, 4.0000
32.67500, 0.50, 16.0, 4.0000
32.72500, 0.50, 21.0, 4.5826
32.77500, 0.50, 18.0, 4.2426
32.82500, 0.50, 13.0, 3.6056
32.87500, 0.50, 23.0, 4.7958
32.92500, 0.50, 16.0, 4.0000
32.97500, 0.50, 11.0, 3.3166
33.02500, 0.50, 20.0, 4.4721
33.07500, 0.50, 14.0, 3.7417
33.12500, 0.50, 18.0, 4.2426
33.17500, 0.50, 24.0, 4.8990
33.22500, 0.50, 19.0, 4.3589
33.27500, 0.50, 16.0, 4.0000
33.32500, 0.50, 21.0, 4.5826
33.37500, 0.50, 16.0, 4.0000
33.42500, 0.50, 16.0, 4.0000
33.47500, 0.50, 19.0, 4.3589
33.52500, 0.50, 15.0, 3.8730
33.57500, 0.50, 13.0, 3.6056
33.62500, 0.50, 16.0, 4.0000
33.67500, 0.50, 21.0, 4.5826
33.72500, 0.50, 19.0, 4.3589
33.77500, 0.50, 16.0, 4.0000
33.82500, 0.50, 12.0, 3.4641
33.87500, 0.50, 16.0, 4.0000
33.92500, 0.50, 21.0, 4.5826
33.97500, 0.50, 16.0, 4.0000
34.02500, 0.50, 15.0, 3.8730
34.07500, 0.50, 16.0, 4.0000
34.12500, 0.50, 19.0, 4.3589
34.17500, 0.50, 14.0, 3.7417
34.22500, 0.50, 13.0, 3.6056
34.27500, 0.50, 15.0, 3.8730
34.32500, 0.50, 12.0, 3.4641
34.37500, 0.50, 13.0, 3.6056
34.42500, 0.50, 11.0, 3.3166
34.47500, 0.50, 15.0, 3.8730
34.52500, 0.50, 16.0, 4.0000
34.57500, 0.50, 13.0, 3.6056
34.62500, 0.50, 14.0, 3.7417
34.67500, 0.50, 12.0, 3.4641
34.72500, 0.50, 20.0, 4.4721
34.77500, 0.50, 10.0, 3.1623
34.82500, 0.50, 16.0, 4.0000
34.87500, 0.50, 22.0, 4.6904
34.92500, 0.50, 18.0, 4.2426
34.97500, 0.50, 13.0, 3.6056
35.02500, 0.50, 21.0, 4.5826
35.07500, 0.50, 16.0, 4.0000
35.12500, 0.50, 17.0, 4.1231
35.17500, 0.50, 17.0, 4.1231
35.22500, 0.50, 20.0, 4.4721
35.27500, 0.50, 13.0, 3.6056
35.32500, 0.50, 14.0, 3.7417
35.37500, 0.50, 15.0, 3.8730
35.42500, 0.50, 23.0, 4.7958
35.47500, 0.50, 7.0, 2.6458
35.52500, 0.50, 22.0, 4.6904
35.57500, 0.50, 19.0, 4.3589
35.62500, 0.50, 16.0, 4.0000
35.67500, 0.50, 15.0, 3.8730
35.72500, 0.50, 13.0, 3.6056
35.77500, 0.50, 12.0, 3.4641
35.82500, 0.50, 19.0, 4.3589
35.87500, 0.50, 12.0, 3.4641
35.92500, 0.50, 13.0, 3.6056
35.97500, 0.50, 17.0, 4.1231
36.02500, 0.50, 24.0, 4.8990
36.07500, 0.50, 19.0, 4.3589
36.12500, 0.50, 13.0, 3.6056
36.17500, 0.50, 17.0, 4.1231
36.22500, 0.50, 24.0, 4.8990
36.27500, 0.50, 24.0, 4.8990
36.32500, 0.50, 24.0, 4.8990
36.37500, 0.50, 22.0, 4.6904
36.42500, 0.50, 20.0, 4.4721
36.47500, 0.50, 25.0, 5.0000
36.52500, 0.50, 21.0, 4.5826
36.57500, 0.50, 24.0, 4.8990
36.62500, 0.50, 14.0, 3.7417
36.67500, 0.50, 16.0, 4.0000
36.72500, 0.50, 19.0, 4.3589
36.77500, 0.50, 20.0, 4.4721
36.82500, 0.50, 21.0, 4.5826
36.87500, 0.50, 13.0, 3.6056
36.92500, 0.50, 16.0, 4.0000
36.97500, 0.50, 17.0, 4.1231
37.02500, 0.50, 15.0, 3.8730
37.07500, 0.50, 16.0, 4.0000
37.12500, 0.50, 29.0, 5.3852
37.17500, 0.50, 29.0, 5.3852
37.22500, 0.50, 25.0, 5.0000
37.27500, 0.50, 21.0, 4.5826
37.32500, 0.50, 21.0, 4.5826
37.37500, 0.50, 17.0, 4.1231
37.42500, 0.50, 21.0, 4.5826
37.47500, 0.50, 30.0, 5.4772
37.52500, 0.50, 30.0, 5.4772
37.57500, 0.50, 36.0, 6.0000
37.62500, 0.50, 33.0, 5.7446
37.67500, 0.50, 37.0, 6.0828
37.72500, 0.50, 65.0, 8.0623
37.77500, 0.50, 114.0, 10.6771
37.82500, 0.50, 169.0, 13.0000
37.87500, 0.50, 231.0, 15.1987
37.92500, 0.50, 340.0, 18.4391
37.97500, 0.50, 541.0, 23.2594
38.02500, 0.50, 765.0, 27.6586
38.07500, 0.50, 855.0, 29.2404
38.12500, 0.50, 780.0, 27.9285
38.17500, 0.50, 622.0, 24.9399
38.22500, 0.50, 323.0, 17.9722
38.27500, 0.50, 187.0, 13.6748
38.32500, 0.50, 98.0, 9.8995
38.37500, 0.50, 63.0, 7.9373
38.42500, 0.50, 37.0, 6.0828
38.47500, 0.50, 35.0, 5.9161
38.52500, 0.50, 29.0, 5.3852
38.57500, 0.50, 25.0, 5.0000
38.62500, 0.50, 23.0, 4.7958
38.67500, 0.50, 18.0, 4.2426
38.72500, 0.50, 20.0, 4.4721
38.77500, 0.50, 16.0, 4.0000
38.82500, 0.50, 22.0, 4.6904
38.87500, 0.50, 14.0, 3.7417
38.92500, 0.50, 25.0, 5.0000
38.97500, 0.50, 18.0, 4.2426
39.02500, 0.50, 16.0, 4.0000
39.07500, 0.50, 19.0, 4.3589
39.12500, 0.50, 17.0, 4.1231
39.17500, 0.50, 17.0, 4.1231
39.22500, 0.50, 14.0, 3.7417
39.27500, 0.50, 16.0, 4.0000
39.32500, 0.50, 17.0, 4.1231
39.37500, 0.50, 13.0, 3.6056
39.42500, 0.50, 15.0, 3.8730
39.47500, 0.50, 16.0, 4.0000
39.52500, 0.50, 15.0, 3.8730
39.57500, 0.50, 14.0, 3.7417
39.62500, 0.50, 21.0, 4.5826
39.67500, 0.50, 16.0, 4.0000
39.72500, 0.50, 12.0, 3.4641
39.77500, 0.50, 14.0, 3.7417
39.82500, 0.50, 13.0, 3.6056
39.87500, 0.50, 19.0, 4.3589
39.92500, 0.50, 18.0, 4.2426
39.97500, 0.50, 9.0, 3.0000
40.02500, 0.50, 12.0, 3.4641
40.07500, 0.50, 16.0, 4.0000
40.12500, 0.50, 17.0, 4.1231
40.17500, 0.50, 13.0, 3.6056
40.22500, 0.50, 8.0, 2.8284
40.27500, 0.50, 11.0, 3.3166
40.32500, 0.50, 20.0, 4.4721
40.37500, 0.50, 12.0, 3.4641
40.42500, 0.50, 10.0, 3.1623
40.47500, 0.50, 14.0, 3.7417
40.52500, 0.50, 5.0, 2.2361
40.57500, 0.50, 17.0, 4.1231
40.62500, 0.50, 11.0, 3.3166
40.67500, 0.50, 15.0, 3.8730
40.72500, 0.50, 15.0, 3.8730
40.77500, 0.50, 6.0, 2.4495
40.82500, 0.50, 15.0, 3.8730
40.87500, 0.50, 10.0, 3.1623
40.92500, 0.50, 6.0, 2.4495
40.97500, 0.50, 9.0, 3.0000
41.02500, 0.50, 10.0, 3.1623
41.07500, 0.50, 10.0, 3.1623
41.12500, 0.50, 12.0, 3.4641
41.17500, 0.50, 11.0, 3.3166
41.22500, 0.50, 9.0, 3.0000
41.27500, 0.50, 14.0, 3.7417
41.32500, 0.50, 14.0, 3.7417
41.37500, 0.50, 10.0, 3.1623
41.42500, 0.50, 13.0, 3.6056
41.47500, 0.50, 9.0, 3.0000
41.52500, 0.50, 11.0, 3.3166
41.57500, 0.50, 12.0, 3.4641
41.62500, 0.50, 9.0, 3.0000
41.67500, 0.50, 10.0, 3.1623
41.72500, 0.50, 14.0, 3.7417
41.77500, 0.50, 11.0, 3.3166
41.82500, 0.50, 14.0, 3.7417
41.87500, 0.50, 14.0, 3.7417
41.92500, 0.50, 18.0, 4.2426
41.97500, 0.50, 9.0, 3.0000
42.02500, 0.50, 9.0, 3.0000
42.07500, 0.50, 15.0, 3.8730
42.12500, 0.50, 17.0, 4.1231
42.17500, 0.50, 11.0, 3.3166
42.22500, 0.50, 10.0, 3.1623
42.27500, 0.50, 15.0, 3.8730
42.32500, 0.50, 11.0, 3.3166
42.37500, 0.50, 11.0, 3.3166
42.42500, 0.50, 15.0, 3.8730
42.47500, 0.50, 14.0, 3.7417
42.52500, 0.50, 15.0, 3.8730
42.57500, 0.50, 11.0, 3.3166
42.62500, 0.50, 18.0, 4.2426
42.67500, 0.50, 11.0, 3.3166
42.72500, 0.50, 12.0, 3.4641
42.77500, 0.50, 9.0, 3.0000
42.82500, 0.50, 12.0, 3.4641
42.87500, 0.50, 14.0, 3.7417
42.92500, 0.50, 14.0, 3.7417
42.97500, 0.50, 26.0, 5.0990
43.02500, 0.50, 11.0, 3.3166
43.07500, 0.50, 26.0, 5.0990
43.12500, 0.50, 24.0, 4.8990
43.17500, 0.50, 26.0, 5.0990
43.22500, 0.50, 41.0, 6.4031
43.27500, 0.50, 47.0, 6.8557
43.32500, 0.50, 43.0, 6.5574
43.37500, 0.50, 43.0, 6.5574
43.42500, 0.50, 37.0, 6.0828
43.47500, 0.50, 29.0, 5.3852
43.52500, 0.50, 23.0, 4.7958
43.57500, 0.50, 24.0, 4.8990
43.62500, 0.50, 19.0, 4.3589
43.67500, 0.50, 17.0, 4.1231
43.72500, 0.50, 22.0, 4.6904
43.77500, 0.50, 27.0, 5.1962
43.82500, 0.50, 19.0, 4.3589
43.87500, 0.50, 28.0, 5.2915
43.92500, 0.50, 38.0, 6.1644
43.97500, 0.50, 58.0, 7.6158
44.02500, 0.50, 106.0, 10.2956
44.07500, 0.50, 129.0, 11.3578
44.12500, 0.50, 192.0, 13.8564
44.17500, 0.50, 280.0, 16.7332
44.22500, 0.50, 310.0, 17.6068
44.27500, 0.50, 343.0, 18.5203
44.32500, 0.50, 278.0, 16.6733
44.37500, 0.50, 246.0, 15.6844
44.42500, 0.50, 183.0, 13.5277
44.47500, 0.50, 90.0, 9.4868
44.52500, 0.50, 63.0, 7.9373
44.57500, 0.50, 46.0, 6.7823
44.62500, 0.50, 34.0, 5.8310
44.67500, 0.50, 23.0, 4.7958
44.72500, 0.50, 18.0, 4.2426
44.77500, 0.50, 21.0, 4.5826
44.82500, 0.50, 19.0, 4.3589
44.87500, 0.50, 13.0, 3.6056
44.92500, 0.50, 15.0, 3.8730
44.97500, 0.50, 12.0, 3.4641
45.02500, 0.50, 9.0, 3.0000
45.07500, 0.50, 14.0, 3.7417
45.12500, 0.50, 11.0, 3.3166
45.17500, 0.50, 11.0, 3.3166
45.22500, 0.50, 16.0, 4.0000
45.27500, 0.50, 8.0, 2.8284
45.32500, 0.50, 10.0, 3.1623
45.37500, 0.50, 8.0, 2.8284
45.42500, 0.50, 12.0, 3.4641
45.47500, 0.50, 4.0, 2.0000
45.52500, 0.50, 9.0, 3.0000
45.57500, 0.50, 17.0, 4.1231
45.62500, 0.50, 11.0, 3.3166
45.67500, 0.50, 10.0, 3.1623
45.72500, 0.50, 9.0, 3.0000
45.77500, 0.50, 11.0, 3.3166
45.82500, 0.50, 7.0, 2.6458
45.87500, 0.50, 13.0, 3.6056
45.92500, 0.50, 6.0, 2.4495
45.97500, 0.50, 11.0, 3.3166
46.02500, 0.50, 13.0, 3.6056
46.07500, 0.50, 11.0, 3.3166
46.12500, 0.50, 5.0, 2.2361
46.17500, 0.50, 7.0, 2.6458
46.22500, 0.50, 10.0, 3.1623
46.27500, 0.50, 5.0, 2.2361
46.32500, 0.50, 9.0, 3.0000
46.37500, 0.50, 6.0, 2.4495
46.42500, 0.50, 4.0, 2.0000
46.47500, 0.50, 12.0, 3.4641
46.52500, 0.50, 9.0, 3.0000
46.57500, 0.50, 5.0, 2.2361
46.62500, 0.50, 8.0, 2.8284
46.67500, 0.50, 14.0, 3.7417
46.72500, 0.50, 10.0, 3.1623
46.77500, 0.50, 4.0, 2.0000
46.82500, 0.50, 7.0, 2.6458
46.87500, 0.50, 10.0, 3.1623
46.92500, 0.50, 6.0, 2.4495
46.97500, 0.50, 11.0, 3.3166
47.02500, 0.50, 7.0, 2.6458
47.07500, 0.50, 10.0, 3.1623
47.12500, 0.50, 9.0, 3.0000
47.17500, 0.50, 6.0, 2.4495
47.22500, 0.50, 7.0, 2.6458
47.27500, 0.50, 2.0, 1.4142
47.32500, 0.50, 8.0, 2.8284
47.37500, 0.50, 1.0, 1.0000
47.42500, 0.50, 7.0, 2.6458
47.47500, 0.50, 7.0, 2.6458
47.52500, 0.50, 8.0, 2.8284
47.57500, 0.50, 5.0, 2.2361
47.62500, 0.50, 11.0, 3.3166
47.67500, 0.50, 11.0, 3.3166
47.72500, 0.50, 8.0, 2.8284
47.77500, 0.50, 8.0, 2.8284
47.82500, 0.50, 12.0, 3.4641
47.87500, 0.50, 13.0, 3.6056
47.92500, 0.50, 7.0, 2.6458
47.97500, 0.50, 6.0, 2.4495
48.02500, 0.50, 6.0, 2.4495
48.07500, 0.50, 4.0, 2.0000
48.12500, 0.50, 9.0, 3.0000
48.17500, 0.50, 12.0, 3.4641
48.22500, 0.50, 9.0, 3.0000
48.27500, 0.50, 6.0, 2.4495
48.32500, 0.50, 12.0, 3.4641
48.37500, 0.50, 7.0, 2.6458
48.42500, 0.50, 4.0, 2.0000
48.47500, 0.50, 4.0, 2.0000
48.52500, 0.50, 9.0, 3.0000
48.57500, 0.50, 8.0, 2.8284
48.62500, 0.50, 12.0, 3.4641
48.67500, 0.50, 5.0, 2.2361
48.72500, 0.50, 6.0, 2.4495
48.77500, 0.50, 4.0, 2.0000
48.82500, 0.50, 7.0, 2.6458
48.87500, 0.50, 5.0, 2.2361
48.92500, 0.50, 4.0, 2.0000
48.97500, 0.50, 5.0, 2.2361
49.02500, 0.50, 11.0, 3.3166
49.07500, 0.50, 7.0, 2.6458
49.12500, 0.50, 4.0, 2.0000
49.17500, 0.50, 7.0, 2.6458
49.22500, 0.50, 10.0, 3.1623
49.27500, 0.50, 7.0, 2.6458
49.32500, 0.50, 11.0, 3.3166
49.37500, 0.50, 12.0, 3.4641
49.42500, 0.50, 0.0, 0.0000
49.47500, 0.50, 6.0, 2.4495
49.52500, 0.50, 6.0, 2.4495
49.57500, 0.50, 9.0, 3.0000
49.62500, 0.50, 11.0, 3.3166
49.67500, 0.50, 8.0, 2.8284
49.72500, 0.50, 8.0, 2.8284
49.77500, 0.50, 7.0, 2.6458
49.82500, 0.50, 9.0, 3.0000
49.87500, 0.50, 5.0, 2.2361
49.92500, 0.50, 8.0, 2.8284
49.97500, 0.50, 6.0, 2.4495
50.02500, 0.50, 7.0, 2.6458
50.07500, 0.50, 11.0, 3.3166
50.12500, 0.50, 13.0, 3.6056
50.17500, 0.50, 9.0, 3.0000
50.22500, 0.50, 14.0, 3.7417
50.27500, 0.50, 14.0, 3.7417
50.32500, 0.50, 10.0, 3.1623
50.37500, 0.50, 16.0, 4.0000
50.42500, 0.50, 15.0, 3.8730
50.47500, 0.50, 17.0, 4.1231
50.52500, 0.50, 14.0, 3.7417
50.57500, 0.50, 14.0, 3.7417
50.62500, 0.50, 10.0, 3.1623
50.67500, 0.50, 8.0, 2.8284
50.72500, 0.50, 9.0, 3.0000
50.77500, 0.50, 13.0, 3.6056
50.82500, 0.50, 9.0, 3.0000
50.87500, 0.50, 11.0, 3.3166
50.92500, 0.50, 7.0, 2.6458
50.97500, 0.50, 11.0, 3.3166
51.02500, 0.50, 3.0, 1.7321
51.07500, 0.50, 5.0, 2.2361
51.12500, 0.50, 6.0, 2.4495
51.17500, 0.50, 4.0, 2.0000
51.22500, 0.50, 4.0, 2.0000
51.27500, 0.50, 2.0, 1.4142
51.32500, 0.50, 3.0, 1.7321
51.37500, 0.50, 1.0, 1.0000
51.42500, 0.50, 8.0, 2.8284
51.47500, 0.50, 3.0, 1.7321
51.52500, 0.50, 8.0, 2.8284
51.57500, 0.50, 5.0, 2.2361
51.62500, 0.50, 12.0, 3.4641
51.67500, 0.50, 11.0, 3.3166
51.72500, 0.50, 6.0, 2.4495
51.77500, 0.50, 2.0, 1.4142
51.82500, 0.50, 7.0, 2.6458
51.87500, 0.50, 6.0, 2.4495
51.92500, 0.50, 7.0, 2.6458
51.97500, 0.50, 5.0, 2.2361
52.02500, 0.50, 6.0, 2.4495
52.07500, 0.50, 4.0, 2.0000
52.12500, 0.50, 5.0, 2.2361
52.17500, 0.50, 6.0, 2.4495
52.22500, 0.50, 5.0, 2.2361
52.27500, 0.50, 10.0, 3.1623
52.32500, 0.50, 7.0, 2.6458
52.37500, 0.50, 7.0, 2.6458
52.42500, 0.50, 5.0, 2.2361
52.47500, 0.50, 5.0, 2.2361
52.52500, 0.50, 5.0, 2.2361
52.57500, 0.50, 4.0, 2.0000
52.62500, 0.50, 5.0, 2.2361
52.67500, 0.50, 5.0, 2.2361
52.72500, 0.50, 9.0, 3.0000
52.77500, 0.50, 7.0, 2.6458
52.82500, 0.50, 5.0, 2.2361
52.87500, 0.50, 8.0, 2.8284
52.92500, 0.50, 4.0, 2.0000
52.97500, 0.50, 8.0, 2.8284
53.02500, 0.50, 7.0, 2.6458
53.07500, 0.50, 3.0, 1.7321
53.12500, 0.50, 3.0, 1.7321
53.17500, 0.50, 7.0, 2.6458
53.22500, 0.50, 7.0, 2.6458
53.27500, 0.50, 5.0, 2.2361
53.32500, 0.50, 8.0, 2.8284
53.37500, 0.50, 7.0, 2.6458
53.42500, 0.50, 8.0, 2.8284
53.47500, 0.50, 7.0, 2.6458
53.52500, 0.50, 10.0, 3.1623
53.57500, 0.50, 4.0, 2.0000
53.62500, 0.50, 4.0, 2.0000
53.67500, 0.50, 5.0, 2.2361
53.72500, 0.50, 6.0, 2.4495
53.77500, 0.50, 5.0, 2.2361
53.82500, 0.50, 8.0, 2.8284
53.87500, 0.50, 3.0, 1.7321
53.92500, 0.50, 9.0, 3.0000
53.97500, 0.50, 8.0, 2.8284
54.02500, 0.50, 8.0, 2.8284
54.07500, 0.50, 9.0, 3.0000
54.12500, 0.50, 6.0, 2.4495
54.17500, 0.50, 6.0, 2.4495
54.22500, 0.50, 9.0, 3.0000
54.27500, 0.50, 5.0, 2.2361
54.32500, 0.50, 9.0, 3.0000
54.37500, 0.50, 12.0, 3.4641
54.42500, 0.50, 8.0, 2.8284
54.47500, 0.50, 6.0, 2.4495
54.52500, 0.50, 3.0, 1.7321
54.57500, 0.50, 9.0, 3.0000
54.62500, 0.50, 5.0, 2.2361
54.67500, 0.50, 7.0, 2.6458
54.72500, 0.50, 5.0, 2.2361
54.77500, 0.50, 6.0, 2.4495
54.82500, 0.50, 5.0, 2.2361
54.87500, 0.50, 8.0, 2.8284
54.92500, 0.50, 5.0, 2.2361
54.97500, 0.50, 3.0, 1.7321
55.02500, 0.50, 7.0, 2.6458
55.07500, 0.50, 8.0, 2.8284
55.12500, 0.50, 6.0, 2.4495
55.17500, 0.50, 5.0, 2.2361
55.22500, 0.50, 4.0, 2.0000
55.27500, 0.50, 9.0, 3.0000
55.32500, 0.50, 5.0, 2.2361
55.37500, 0.50, 9.0, 3.0000
55.42500, 0.50, 5.0, 2.2361
55.47500, 0.50, 7.0, 2.6458
55.52500, 0.50, 5.0, 2.2361
55.57500, 0.50, 4.0, 2.0000
55.62500, 0.50, 8.0, 2.8284
55.67500, 0.50, 6.0, 2.4495
55.72500, 0.50, 6.0, 2.4495
55.77500, 0.50, 4.0, 2.0000
55.82500, 0.50, 8.0, 2.8284
55.87500, 0.50, 7.0, 2.6458
55.92500, 0.50, 7.0, 2.6458
55.97500, 0.50, 7.0, 2.6458
56.02500, 0.50, 5.0, 2.2361
56.07500, 0.50, 4.0, 2.0000
56.12500, 0.50, 6.0, 2.4495
56.17500, 0.50, 7.0, 2.6458
56.22500, 0.50, 5.0, 2.2361
56.27500, 0.50, 9.0, 3.0000
56.32500, 0.50, 8.0, 2.8284
56.37500, 0.50, 8.0, 2.8284
56.42500, 0.50, 7.0, 2.6458
56.47500, 0.50, 7.0, 2.6458
56.52500, 0.50, 1.0, 1.0000
56.57500, 0.50, 2.0, 1.4142
56.62500, 0.50, 6.0, 2.4495
56.67500, 0.50, 6.0, 2.4495
56.72500, 0.50, 7.0, 2.6458
56.77500, 0.50, 5.0, 2.2361
56.82500, 0.50, 6.0, 2.4495
56.87500, 0.50, 4.0, 2.0000
56.92500, 0.50, 3.0, 1.7321
56.97500, 0.50, 4.0, 2.0000
57.02500, 0.50, 10.0, 3.1623
57.07500, 0.50, 7.0, 2.6458
57.12500, 0.50, 3.0, 1.7321
57.17500, 0.50, 9.0, 3.0000
57.22500, 0.50, 6.0, 2.4495
57.27500, 0.50, 5.0, 2.2361
57.32500, 0.50, 7.0, 2.6458
57.37500, 0.50, 9.0, 3.0000
57.42500, 0.50, 5.0, 2.2361
57.47500, 0.50, 8.0, 2.8284
57.52500, 0.50, 9.0, 3.0000
57.57500, 0.50, 4.0, 2.0000
57.62500, 0.50, 15.0, 3.8730
57.67500, 0.50, 11.0, 3.3166
57.72500, 0.50, 4.0, 2.0000
57.77500, 0.50, 8.0, 2.8284
57.82500, 0.50, 5.0, 2.2361
57.87500, 0.50, 5.0, 2.2361
57.92500, 0.50, 5.0, 2.2361
57.97500, 0.50, 6.0, 2.4495
58.02500, 0.50, 6.0, 2.4495
58.07500, 0.50, 2.0, 1.4142
58.12500, 0.50, 4.0, 2.0000
58.17500, 0.50, 4.0, 2.0000
58.22500, 0.50, 8.0, 2.8284
58.27500, 0.50, 9.0, 3.0000
58.32500, 0.50, 6.0, 2.4495
58.37500, 0.50, 8.0, 2.8284
58.42500, 0.50, 2.0, 1.4142
58.47500, 0.50, 6.0, 2.4495
58.52500, 0.50, 2.0, 1.4142
58.57500, 0.50, 5.0, 2.2361
58.62500, 0.50, 2.0, 1.4142
58.67500, 0.50, 8.0, 2.8284
58.72500, 0.50, 9.0, 3.0000
58.77500, 0.50, 4.0, 2.0000
58.82500, 0.50, 8.0, 2.8284
58.87500, 0.50, 9.0, 3.0000
58.92500, 0.50, 8.0, 2.8284
58.97500, 0.50, 7.0, 2.6458
59.02500, 0.50, 3.0, 1.7321
59.07500, 0.50, 4.0, 2.0000
59.12500, 0.50, 5.0, 2.2361
59.17500, 0.50, 5.0, 2.2361
59.22500, 0.50, 4.0, 2.0000
59.27500, 0.50, 3.0, 1.7321
59.32500, 0.50, 5.0, 2.2361
59.37500, 0.50, 5.0, 2.2361
59.42500, 0.50, 7.0, 2.6458
59.47500, 0.50, 3.0, 1.7321
59.52500, 0.50, 5.0, 2.2361
59.57500, 0.50, 9.0, 3.0000
59.62500, 0.50, 7.0, 2.6458
59.67500, 0.50, 4.0, 2.0000
59.72500, 0.50, 2.0, 1.4142
59.77500, 0.50, 9.0, 3.0000
59.82500, 0.50, 4.0, 2.0000
59.87500, 0.50, 10.0, 3.1623
59.92500, 0.50, 1.0, 1.0000
59.97500, 0.50, 4.0, 2.0000
60.02500, 0.50, 8.0, 2.8284
60.07500, 0.50, 1.0, 1.0000
60.12500, 0.50, 9.0, 3.0000
60.17500, 0.50, 6.0, 2.4495
60.22500, 0.50, 3.0, 1.7321
60.27500, 0.50, 7.0, 2.6458
60.32500, 0.50, 5.0, 2.2361
60.37500, 0.50, 5.0, 2.2361
60.42500, 0.50, 11.0, 3.3166
60.47500, 0.50, 7.0, 2.6458
60.52500, 0.50, 4.0, 2.0000
60.57500, 0.50, 7.0, 2.6458
60.62500, 0.50, 4.0, 2.0000
60.67500, 0.50, 4.0, 2.0000
60.72500, 0.50, 4.0, 2.0000
60.77500, 0.50, 8.0, 2.8284
60.82500, 0.50, 10.0, 3.1623
60.87500, 0.50, 8.0, 2.8284
60.92500, 0.50, 7.0, 2.6458
60.97500, 0.50, 8.0, 2.8284
61.02500, 0.50, 5.0, 2.2361
61.07500, 0.50, 3.0, 1.7321
61.12500, 0.50, 8.0, 2.8284
61.17500, 0.50, 9.0, 3.0000
61.22500, 0.50, 3.0, 1.7321
61.27500, 0.50, 5.0, 2.2361
61.32500, 0.50, 8.0, 2.8284
61.37500, 0.50, 4.0, 2.0000
61.42500, 0.50, 7.0, 2.6458
61.47500, 0.50, 6.0, 2.4495
61.52500, 0.50, 10.0, 3.1623
61.57500, 0.50, 7.0, 2.6458
61.62500, 0.50, 6.0, 2.4495
61.67500, 0.50, 4.0, 2.0000
61.72500, 0.50, 9.0, 3.0000
61.77500, 0.50, 6.0, 2.4495
61.82500, 0.50, 3.0, 1.7321
61.87500, 0.50, 7.0, 2.6458
61.92500, 0.50, 4.0, 2.0000
61.97500, 0.50, 4.0, 2.0000
62.02500, 0.50, 4.0, 2.0000
62.07500, 0.50, 6.0, 2.4495
62.12500, 0.50, 6.0, 2.4495
62.17500, 0.50, 5.0, 2.2361
62.22500, 0.50, 7.0, 2.6458
62.27500, 0.50, 11.0, 3.3166
62.32500, 0.50, 6.0, 2.4495
62.37500, 0.50, 7.0, 2.6458
62.42500, 0.50, 5.0, 2.2361
62.47500, 0.50, 3.0, 1.7321
62.52500, 0.50, 5.0, 2.2361
62.57500, 0.50, 6.0, 2.4495
62.62500, 0.50, 5.0, 2.2361
62.67500, 0.50, 5.0, 2.2361
62.72500, 0.50, 8.0, 2.8284
62.77500, 0.50, 7.0, 2.6458
62.82500, 0.50, 6.0, 2.4495
62.87500, 0.50, 7.0, 2.6458
62.92500, 0.50, 9.0, 3.0000
62.97500, 0.50, 10.0, 3.1623
63.02500, 0.50, 7.0, 2.6458
63.07500, 0.50, 10.0, 3.1623
63.12500, 0.50, 9.0, 3.0000
63.17500, 0.50, 8.0, 2.8284
63.22500, 0.50, 8.0, 2.8284
63.27500, 0.50, 3.0, 1.7321
63.32500, 0.50, 7.0, 2.6458
63.37500, 0.50, 7.0, 2.6458
63.42500, 0.50, 7.0, 2.6458
63.47500, 0.50, 9.0, 3.0000
63.52500, 0.50, 7.0, 2.6458
63.57500, 0.50, 6.0, 2.4495
63.62500, 0.50, 3.0, 1.7321
63.67500, 0.50, 10.0, 3.1623
63.72500, 0.50, 7.0, 2.6458
63.77500, 0.50, 6.0, 2.4495
63.82500, 0.50, 9.0, 3.0000
63.87500, 0.50, 11.0, 3.3166
63.92500, 0.50, 13.0, 3.6056
63.97500, 0.50, 9.0, 3.0000
64.02500, 0.50, 13.0, 3.6056
64.07500, 0.50, 18.0, 4.2426
64.12500, 0.50, 26.0, 5.0990
64.17500, 0.50, 34.0, 5.8310
64.22500, 0.50, 61.0, 7.8102
64.27500, 0.50, 93.0, 9.6437
64.32500, 0.50, 147.0, 12.1244
64.37500, 0.50, 154.0, 12.4097
64.42500, 0.50, 185.0, 13.6015
64.47500, 0.50, 150.0, 12.2474
64.52500, 0.50, 133.0, 11.5326
64.57500, 0.50, 117.0, 10.8167
64.62500, 0.50, 64.0, 8.0000
64.67500, 0.50, 75.0, 8.6603
64.72500, 0.50, 35.0, 5.9161
64.77500, 0.50, 26.0, 5.0990
64.82500, 0.50, 15.0, 3.8730
64.87500, 0.50, 7.0, 2.6458
64.92500, 0.50, 12.0, 3.4641
64.97500, 0.50, 13.0, 3.6056
65.02500, 0.50, 11.0, 3.3166
65.07500, 0.50, 8.0, 2.8284
65.12500, 0.50, 6.0, 2.4495
65.17500, 0.50, 9.0, 3.0000
65.22500, 0.50, 12.0, 3.4641
65.27500, 0.50, 3.0, 1.7321
65.32500, 0.50, 4.0, 2.0000
65.37500, 0.50, 11.0, 3.3166
65.42500, 0.50, 3.0, 1.7321
65.47500, 0.50, 4.0, 2.0000
65.52500, 0.50, 9.0, 3.0000
65.57500, 0.50, 6.0, 2.4495
65.62500, 0.50, 4.0, 2.0000
65.67500, 0.50, 2.0, 1.4142
65.72500, 0.50, 6.0, 2.4495
65.77500, 0.50, 6.0, 2.4495
65.82500, 0.50, 4.0, 2.0000
65.87500, 0.50, 7.0, 2.6458
65.92500, 0.50, 5.0, 2.2361
65.97500, 0.50, 5.0, 2.2361
66.02500, 0.50, 7.0, 2.6458
66.07500, 0.50, 3.0, 1.7321
66.12500, 0.50, 8.0, 2.8284
66.17500, 0.50, 4.0, 2.0000
66.22500, 0.50, 3.0, 1.7321
66.27500, 0.50, 4.0, 2.0000
66.32500, 0.50, 4.0, 2.0000
66.37500, 0.50, 3.0, 1.7321
66.42500, 0.50, 5.0, 2.2361
66.47500, 0.50, 1.0, 1.0000
66.52500, 0.50, 6.0, 2.4495
66.57500, 0.50, 8.0, 2.8284
66.62500, 0.50, 7.0, 2.6458
66.67500, 0.50, 4.0, 2.0000
66.72500, 0.50, 2.0, 1.4142
66.77500, 0.50, 7.0, 2.6458
66.82500, 0.50, 4.0, 2.0000
66.87500, 0.50, 7.0, 2.6458
66.92500, 0.50, 4.0, 2.0000
66.97500, 0.50, 7.0, 2.6458
67.02500, 0.50, 6.0, 2.4495
67.07500, 0.50, 8.0, 2.8284
67.12500, 0.50, 7.0, 2.6458
67.17500, 0.50, 8.0, 2.8284
67.22500, 0.50, 2.0, 1.4142
67.27500, 0.50, 10.0, 3.1623
67.32500, 0.50, 3.0, 1.7321
67.37500, 0.50, 5.0, 2.2361
67.42500, 0.50, 7.0, 2.6458
67.47500, 0.50, 8.0, 2.8284
67.52500, 0.50, 3.0, 1.7321
67.57500, 0.50, 7.0, 2.6458
67.62500, 0.50, 7.0, 2.6458
67.67500, 0.50, 2.0, 1.4142
67.72500, 0.50, 5.0, 2.2361
67.77500, 0.50, 4.0, 2.0000
67.82500, 0.50, 6.0, 2.4495
67.87500, 0.50, 4.0, 2.0000
67.92500, 0.50, 5.0, 2.2361
67.97500, 0.50, 5.0, 2.2361
68.02500, 0.50, 4.0, 2.0000
68.07500, 0.50, 5.0, 2.2361
68.12500, 0.50, 9.0, 3.0000
68.17500, 0.50, 5.0, 2.2361
68.22500, 0.50, 3.0, 1.7321
68.27500, 0.50, 5.0, 2.2361
68.32500, 0.50, 5.0, 2.2361
68.37500, 0.50, 4.0, 2.0000
68.42500, 0.50, 4.0, 2.0000
68.47500, 0.50, 3.0, 1.7321
68.52500, 0.50, 6.0, 2.4495
68.57500, 0.50, 8.0, 2.8284
68.62500, 0.50, 10.0, 3.1623
68.67500, 0.50, 9.0, 3.0000
68.72500, 0.50, 8.0, 2.8284
68.77500, 0.50, 4.0, 2.0000
68.82500, 0.50, 3.0, 1.7321
68.87500, 0.50, 3.0, 1.7321
68.92500, 0.50, 4.0, 2.0000
68.97500, 0.50, 5.0, 2.2361
69.02500, 0.50, 8.0, 2.8284
69.07500, 0.50, 5.0, 2.2361
69.12500, 0.50, 9.0, 3.0000
69.17500, 0.50, 1.0, 1.0000
69.22500, 0.50, 7.0, 2.6458
69.27500, 0.50, 6.0, 2.4495
69.32500, 0.50, 8.0, 2.8284
69.37500, 0.50, 5.0, 2.2361
69.42500, 0.50, 5.0, 2.2361
69.47500, 0.50, 4.0, 2.0000
69.52500, 0.50, 5.0, 2.2361
69.57500, 0.50, 4.0, 2.0000
69.62500, 0.50, 5.0, 2.2361
69.67500, 0.50, 6.0, 2.4495
69.72500, 0.50, 4.0, 2.0000
69.77500, 0.50, 4.0, 2.0000
69.82500, 0.50, 5.0, 2.2361
69.87500, 0.50, 3.0, 1.7321
69.92500, 0.50, 4.0, 2.0000
69.97500, 0.50, 9.0, 3.0000
70.02500, 0.50, 10.0, 3.1623
70.07500, 0.50, 12.0, 3.4641
70.12500, 0.50, 5.0, 2.2361
70.17500, 0.50, 3.0, 1.7321
70.22500, 0.50, 3.0, 1.7321
70.27500, 0.50, 2.0, 1.4142
70.32500, 0.50, 6.0, 2.4495
70.37500, 0.50, 9.0, 3.0000
70.42500, 0.50, 5.0, 2.2361
70.47500, 0.50, 5.0, 2.2361
70.52500, 0.50, 2.0, 1.4142
70.57500, 0.50, 5.0, 2.2361
70.62500, 0.50, 7.0, 2.6458
70.67500, 0.50, 3.0, 1.7321
70.72500, 0.50, 7.0, 2.6458
70.77500, 0.50, 10.0, 3.1623
70.82500, 0.50, 4.0, 2.0000
70.87500, 0.50, 5.0, 2.2361
70.92500, 0.50, 3.0, 1.7321
70.97500, 0.50, 4.0, 2.0000
71.02500, 0.50, 7.0, 2.6458
71.07500, 0.50, 3.0, 1.7321
71.12500, 0.50, 8.0, 2.8284
71.17500, 0.50, 8.0, 2.8284
71.22500, 0.50, 4.0, 2.0000
71.27500, 0.50, 8.0, 2.8284
71.32500, 0.50, 3.0, 1.7321
71.37500, 0.50, 3.0, 1.7321
71.42500, 0.50, 6.0, 2.4495
71.47500, 0.50, 2.0, 1.4142
71.52500, 0.50, 5.0, 2.2361
71.57500, 0.50, 6.0, 2.4495
71.62500, 0.50, 4.0, 2.0000
71.67500, 0.50, 4.0, 2.0000
71.72500, 0.50, 5.0, 2.2361
71.77500, 0.50, 4.0, 2.0000
71.82500, 0.50, 5.0, 2.2361
71.87500, 0.50, 4.0, 2.0000
71.92500, 0.50, 6.0, 2.4495
71.97500, 0.50, 3.0, 1.7321
72.02500, 0.50, 5.0, 2.2361
72.07500, 0.50, 6.0, 2.4495
72.12500, 0.50, 4.0, 2.0000
72.17500, 0.50, 8.0, 2.8284
72.22500, 0.50, 11.0, 3.3166
72.27500, 0.50, 4.0, 2.0000
72.32500, 0.50, 4.0, 2.0000
72.37500, 0.50, 9.0, 3.0000
72.42500, 0.50, 4.0, 2.0000
72.47500, 0.50, 4.0, 2.0000
72.52500, 0.50, 6.0, 2.4495
72.57500, 0.50, 5.0, 2.2361
72.62500, 0.50, 3.0, 1.7321
72.67500, 0.50, 6.0, 2.4495
72.72500, 0.50, 2.0, 1.4142
72.77500, 0.50, 8.0, 2.8284
72.82500, 0.50, 4.0, 2.0000
72.87500, 0.50, 7.0, 2.6458
72.92500, 0.50, 4.0, 2.0000
72.97500, 0.50, 6.0, 2.4495
73.02500, 0.50, 9.0, 3.0000
73.07500, 0.50, 2.0, 1.4142
73.12500, 0.50, 7.0, 2.6458
73.17500, 0.50, 0.0, 0.0000
73.22500, 0.50, 8.0, 2.8284
73.27500, 0.50, 3.0, 1.7321
73.32500, 0.50, 5.0, 2.2361
73.37500, 0.50, 6.0, 2.4495
73.42500, 0.50, 5.0, 2.2361
73.47500, 0.50, 8.0, 2.8284
73.52500, 0.50, 9.0, 3.0000
73.57500, 0.50, 5.0, 2.2361
73.62500, 0.50, 6.0, 2.4495
73.67500, 0.50, 4.0, 2.0000
73.72500, 0.50, 5.0, 2.2361
73.77500, 0.50, 5.0, 2.2361
73.82500, 0.50, 6.0, 2.4495
73.87500, 0.50, 7.0, 2.6458
73.92500, 0.50, 6.0, 2.4495
73.97500, 0.50, 5.0, 2.2361
74.02500, 0.50, 9.0, 3.0000
74.07500, 0.50, 10.0, 3.1623
74.12500, 0.50, 7.0, 2.6458
74.17500, 0.50, 7.0, 2.6458
74.22500, 0.50, 9.0, 3.0000
74.27500, 0.50, 10.0, 3.1623
74.32500, 0.50, 14.0, 3.7417
74.37500, 0.50, 3.0, 1.7321
74.42500, 0.50, 10.0, 3.1623
74.47500, 0.50, 8.0, 2.8284
74.52500, 0.50, 5.0, 2.2361
74.57500, 0.50, 7.0, 2.6458
74.62500, 0.50, 12.0, 3.4641
74.67500, 0.50, 3.0, 1.7321
74.72500, 0.50, 5.0, 2.2361
74.77500, 0.50, 7.0, 2.6458
74.82500, 0.50, 4.0, 2.0000
74.87500, 0.50, 6.0, 2.4495
74.92500, 0.50, 5.0, 2.2361
74.97500, 0.50, 4.0, 2.0000
75.02500, 0.50, 6.0, 2.4495
75.07500, 0.50, 5.0, 2.2361
75.12500, 0.50, 5.0, 2.2361
75.17500, 0.50, 8.0, 2.8284
75.22500, 0.50, 8.0, 2.8284
75.27500, 0.50, 5.0, 2.2361
75.32500, 0.50, 9.0, 3.0000
75.37500, 0.50, 6.0, 2.4495
75.42500, 0.50, 4.0, 2.0000
75.47500, 0.50, 3.0, 1.7321
75.52500, 0.50, 4.0, 2.0000
75.57500, 0.50, 4.0, 2.0000
75.62500, 0.50, 7.0, 2.6458
75.67500, 0.50, 7.0, 2.6458
75.72500, 0.50, 7.0, 2.6458
75.77500, 0.50, 2.0, 1.4142
75.82500, 0.50, 3.0, 1.7321
75.87500, 0.50, 10.0, 3.1623
75.92500, 0.50, 1.0, 1.0000
75.97500, 0.50, 9.0, 3.0000
76.02500, 0.50, 11.0, 3.3166
76.07500, 0.50, 8.0, 2.8284
76.12500, 0.50, 4.0, 2.0000
76.17500, 0.50, 6.0, 2.4495
76.22500, 0.50, 6.0, 2.4495
76.27500, 0.50, 4.0, 2.0000
76.32500, 0.50, 9.0, 3.0000
76.37500, 0.50, 3.0, 1.7321
76.42500, 0.50, 12.0, 3.4641
76.47500, 0.50, 6.0, 2.4495
76.52500, 0.50, 11.0, 3.3166
76.57500, 0.50, 8.0, 2.8284
76.62500, 0.50, 4.0, 2.0000
76.67500, 0.50, 7.0, 2.6458
76.72500, 0.50, 7.0, 2.6458
76.77500, 0.50, 5.0, 2.2361
76.82500, 0.50, 5.0, 2.2361
76.87500, 0.50, 11.0, 3.3166
76.92500, 0.50, 13.0, 3.6056
76.97500, 0.50, 18.0, 4.2426
77.02500, 0.50, 30.0, 5.4772
77.07500, 0.50, 29.0, 5.3852
77.12500, 0.50, 41.0, 6.4031
77.17500, 0.50, 42.0, 6.4807
77.22500, 0.50, 77.0, 8.7750
77.27500, 0.50, 105.0, 10.2470
77.32500, 0.50, 118.0, 10.8628
77.37500, 0.50, 140.0, 11.8322
77.42500, 0.50, 148.0, 12.1655
77.47500, 0.50, 114.0, 10.6771
77.52500, 0.50, 97.0, 9.8489
77.57500, 0.50, 97.0, 9.8489
77.62500, 0.50, 71.0, 8.4261
77.67500, 0.50, 57.0, 7.5498
77.72500, 0.50, 52.0, 7.2111
77.77500, 0.50, 29.0, 5.3852
77.82500, 0.50, 23.0, 4.7958
77.87500, 0.50, 17.0, 4.1231
77.92500, 0.50, 11.0, 3.3166
77.97500, 0.50, 15.0, 3.8730
78.02500, 0.50, 7.0, 2.6458
78.07500, 0.50, 7.0, 2.6458
78.12500, 0.50, 9.0, 3.0000
78.17500, 0.50, 11.0, 3.3166
78.22500, 0.50, 2.0, 1.4142
78.27500, 0.50, 10.0, 3.1623
78.32500, 0.50, 6.0, 2.4495
78.37500, 0.50, 2.0, 1.4142
78.42500, 0.50, 5.0, 2.2361
78.47500, 0.50, 3.0, 1.7321
78.52500, 0.50, 2.0, 1.4142
78.57500, 0.50, 12.0, 3.4641
78.62500, 0.50, 0.0, 0.0000
78.67500, 0.50, 11.0, 3.3166
78.72500, 0.50, 5.0, 2.2361
78.77500, 0.50, 4.0, 2.0000
78.82500, 0.50, 2.0, 1.4142
78.87500, 0.50, 8.0, 2.8284
78.92500, 0.50, 4.0, 2.0000
78.97500, 0.50, 5.0, 2.2361
79.02500, 0.50, 4.0, 2.0000
79.07500, 0.50, 6.0, 2.4495
79.12500, 0.50, 6.0, 2.4495
79.17500, 0.50, 2.0, 1.4142
79.22500, 0.50, 5.0, 2.2361
79.27500, 0.50, 1.0, 1.0000
79.32500, 0.50, 4.0, 2.0000
79.37500, 0.50, 2.0, 1.4142
79.42500, 0.50, 4.0, 2.0000
79.47500, 0.50, 6.0, 2.4495
79.52500, 0.50, 4.0, 2.0000
79.57500, 0.50, 5.0, 2.2361
79.62500, 0.50, 3.0, 1.7321
79.67500, 0.50, 4.0, 2.0000
79.72500, 0.50, 3.0, 1.7321
79.77500, 0.50, 6.0, 2.4495
79.82500, 0.50, 5.0, 2.2361
79.87500, 0.50, 4.0, 2.0000
79.92500, 0.50, 6.0, 2.4495
79.97500, 0.50, 3.0, 1.7321