File: G04007.csv
[Measurement conditions]
Sample identification,100%Ag-AP
Comment - 1,"Configuration=Programmable xy with programmable z platforms, Owner=User, Creation date=02/07/2021 13:22:25"
Comment - 2,"Goniometer=Theta/Theta; Minimum step size 2Theta:0.0001; Minimum step size Omega:0.0001"
Comment - 3,"Sample stage=Programmable xy-platform with programmable z-adjustment; Minimum step size X:0.01; Minimum step size Y:0.01; Minimum step size Z:0.001"
Comment - 4,"Diffractometer system=EMPYREAN"
Comment - 5,"Measurement program=C:\PANalytical\Data Collector\Programs\Knapp Group (CK)\Songming Liu\20-80°, 0.05° step, 0.5s-step.xrdmp, Created identifier={D6D0720B-9417-4404-86A5-80CEFF14CAE1}, Created by=User, Id=WL:EMPYREANGI:User, Creation date=20/06/2024 10:10:34"
Anode material,Cu
K-Alpha1 wavelength,1.5405980
K-Alpha2 wavelength,1.5444260
Ratio K-Alpha2/K-Alpha1,0.500
Divergence slit,Fixed,0.76mm
Monochromator used,NO
Generator voltage, 40
Tube current, 40
File date and time,15/Jul/2024 13:35
Unit cell,
h k l, 0 0 0
Scan axis,2Theta
Scan range,20.00000,80.00000
Scan step size,0.0500000
No. of points, 1200
Scan type,CONTINUOUS
Omega,1.0000
X,2.95
Y,3.80
Z,20.300
Time per step,0.50
[Scan points]
Angle, TimePerStep, Intensity, ESD
20.02500, 0.50, 71.0, 8.4261
20.07500, 0.50, 72.0, 8.4853
20.12500, 0.50, 88.0, 9.3808
20.17500, 0.50, 82.0, 9.0554
20.22500, 0.50, 83.0, 9.1104
20.27500, 0.50, 90.0, 9.4868
20.32500, 0.50, 84.0, 9.1652
20.37500, 0.50, 73.0, 8.5440
20.42500, 0.50, 90.0, 9.4868
20.47500, 0.50, 82.0, 9.0554
20.52500, 0.50, 82.0, 9.0554
20.57500, 0.50, 65.0, 8.0623
20.62500, 0.50, 64.0, 8.0000
20.67500, 0.50, 73.0, 8.5440
20.72500, 0.50, 76.0, 8.7178
20.77500, 0.50, 70.0, 8.3666
20.82500, 0.50, 69.0, 8.3066
20.87500, 0.50, 60.0, 7.7460
20.92500, 0.50, 74.0, 8.6023
20.97500, 0.50, 71.0, 8.4261
21.02500, 0.50, 79.0, 8.8882
21.07500, 0.50, 79.0, 8.8882
21.12500, 0.50, 59.0, 7.6811
21.17500, 0.50, 75.0, 8.6603
21.22500, 0.50, 79.0, 8.8882
21.27500, 0.50, 64.0, 8.0000
21.32500, 0.50, 49.0, 7.0000
21.37500, 0.50, 67.0, 8.1854
21.42500, 0.50, 69.0, 8.3066
21.47500, 0.50, 76.0, 8.7178
21.52500, 0.50, 70.0, 8.3666
21.57500, 0.50, 73.0, 8.5440
21.62500, 0.50, 82.0, 9.0554
21.67500, 0.50, 84.0, 9.1652
21.72500, 0.50, 78.0, 8.8318
21.77500, 0.50, 63.0, 7.9373
21.82500, 0.50, 88.0, 9.3808
21.87500, 0.50, 76.0, 8.7178
21.92500, 0.50, 58.0, 7.6158
21.97500, 0.50, 67.0, 8.1854
22.02500, 0.50, 76.0, 8.7178
22.07500, 0.50, 69.0, 8.3066
22.12500, 0.50, 74.0, 8.6023
22.17500, 0.50, 82.0, 9.0554
22.22500, 0.50, 82.0, 9.0554
22.27500, 0.50, 83.0, 9.1104
22.32500, 0.50, 71.0, 8.4261
22.37500, 0.50, 78.0, 8.8318
22.42500, 0.50, 75.0, 8.6603
22.47500, 0.50, 71.0, 8.4261
22.52500, 0.50, 54.0, 7.3485
22.57500, 0.50, 78.0, 8.8318
22.62500, 0.50, 72.0, 8.4853
22.67500, 0.50, 74.0, 8.6023
22.72500, 0.50, 66.0, 8.1240
22.77500, 0.50, 73.0, 8.5440
22.82500, 0.50, 68.0, 8.2462
22.87500, 0.50, 68.0, 8.2462
22.92500, 0.50, 70.0, 8.3666
22.97500, 0.50, 74.0, 8.6023
23.02500, 0.50, 64.0, 8.0000
23.07500, 0.50, 68.0, 8.2462
23.12500, 0.50, 75.0, 8.6603
23.17500, 0.50, 68.0, 8.2462
23.22500, 0.50, 54.0, 7.3485
23.27500, 0.50, 73.0, 8.5440
23.32500, 0.50, 56.0, 7.4833
23.37500, 0.50, 62.0, 7.8740
23.42500, 0.50, 66.0, 8.1240
23.47500, 0.50, 62.0, 7.8740
23.52500, 0.50, 58.0, 7.6158
23.57500, 0.50, 60.0, 7.7460
23.62500, 0.50, 56.0, 7.4833
23.67500, 0.50, 65.0, 8.0623
23.72500, 0.50, 63.0, 7.9373
23.77500, 0.50, 67.0, 8.1854
23.82500, 0.50, 66.0, 8.1240
23.87500, 0.50, 58.0, 7.6158
23.92500, 0.50, 67.0, 8.1854
23.97500, 0.50, 75.0, 8.6603
24.02500, 0.50, 63.0, 7.9373
24.07500, 0.50, 62.0, 7.8740
24.12500, 0.50, 53.0, 7.2801
24.17500, 0.50, 68.0, 8.2462
24.22500, 0.50, 61.0, 7.8102
24.27500, 0.50, 71.0, 8.4261
24.32500, 0.50, 79.0, 8.8882
24.37500, 0.50, 66.0, 8.1240
24.42500, 0.50, 69.0, 8.3066
24.47500, 0.50, 54.0, 7.3485
24.52500, 0.50, 79.0, 8.8882
24.57500, 0.50, 59.0, 7.6811
24.62500, 0.50, 54.0, 7.3485
24.67500, 0.50, 63.0, 7.9373
24.72500, 0.50, 60.0, 7.7460
24.77500, 0.50, 61.0, 7.8102
24.82500, 0.50, 68.0, 8.2462
24.87500, 0.50, 64.0, 8.0000
24.92500, 0.50, 73.0, 8.5440
24.97500, 0.50, 59.0, 7.6811
25.02500, 0.50, 59.0, 7.6811
25.07500, 0.50, 50.0, 7.0711
25.12500, 0.50, 66.0, 8.1240
25.17500, 0.50, 45.0, 6.7082
25.22500, 0.50, 62.0, 7.8740
25.27500, 0.50, 58.0, 7.6158
25.32500, 0.50, 50.0, 7.0711
25.37500, 0.50, 60.0, 7.7460
25.42500, 0.50, 58.0, 7.6158
25.47500, 0.50, 48.0, 6.9282
25.52500, 0.50, 51.0, 7.1414
25.57500, 0.50, 76.0, 8.7178
25.62500, 0.50, 72.0, 8.4853
25.67500, 0.50, 62.0, 7.8740
25.72500, 0.50, 47.0, 6.8557
25.77500, 0.50, 47.0, 6.8557
25.82500, 0.50, 48.0, 6.9282
25.87500, 0.50, 50.0, 7.0711
25.92500, 0.50, 43.0, 6.5574
25.97500, 0.50, 45.0, 6.7082
26.02500, 0.50, 58.0, 7.6158
26.07500, 0.50, 61.0, 7.8102
26.12500, 0.50, 48.0, 6.9282
26.17500, 0.50, 54.0, 7.3485
26.22500, 0.50, 43.0, 6.5574
26.27500, 0.50, 47.0, 6.8557
26.32500, 0.50, 52.0, 7.2111
26.37500, 0.50, 52.0, 7.2111
26.42500, 0.50, 54.0, 7.3485
26.47500, 0.50, 53.0, 7.2801
26.52500, 0.50, 46.0, 6.7823
26.57500, 0.50, 60.0, 7.7460
26.62500, 0.50, 55.0, 7.4162
26.67500, 0.50, 55.0, 7.4162
26.72500, 0.50, 58.0, 7.6158
26.77500, 0.50, 48.0, 6.9282
26.82500, 0.50, 57.0, 7.5498
26.87500, 0.50, 32.0, 5.6569
26.92500, 0.50, 64.0, 8.0000
26.97500, 0.50, 59.0, 7.6811
27.02500, 0.50, 56.0, 7.4833
27.07500, 0.50, 44.0, 6.6332
27.12500, 0.50, 54.0, 7.3485
27.17500, 0.50, 59.0, 7.6811
27.22500, 0.50, 52.0, 7.2111
27.27500, 0.50, 56.0, 7.4833
27.32500, 0.50, 39.0, 6.2450
27.37500, 0.50, 65.0, 8.0623
27.42500, 0.50, 39.0, 6.2450
27.47500, 0.50, 42.0, 6.4807
27.52500, 0.50, 50.0, 7.0711
27.57500, 0.50, 36.0, 6.0000
27.62500, 0.50, 47.0, 6.8557
27.67500, 0.50, 52.0, 7.2111
27.72500, 0.50, 59.0, 7.6811
27.77500, 0.50, 49.0, 7.0000
27.82500, 0.50, 47.0, 6.8557
27.87500, 0.50, 48.0, 6.9282
27.92500, 0.50, 51.0, 7.1414
27.97500, 0.50, 49.0, 7.0000
28.02500, 0.50, 43.0, 6.5574
28.07500, 0.50, 49.0, 7.0000
28.12500, 0.50, 50.0, 7.0711
28.17500, 0.50, 38.0, 6.1644
28.22500, 0.50, 40.0, 6.3246
28.27500, 0.50, 41.0, 6.4031
28.32500, 0.50, 38.0, 6.1644
28.37500, 0.50, 39.0, 6.2450
28.42500, 0.50, 47.0, 6.8557
28.47500, 0.50, 41.0, 6.4031
28.52500, 0.50, 42.0, 6.4807
28.57500, 0.50, 63.0, 7.9373
28.62500, 0.50, 40.0, 6.3246
28.67500, 0.50, 35.0, 5.9161
28.72500, 0.50, 47.0, 6.8557
28.77500, 0.50, 38.0, 6.1644
28.82500, 0.50, 47.0, 6.8557
28.87500, 0.50, 46.0, 6.7823
28.92500, 0.50, 36.0, 6.0000
28.97500, 0.50, 49.0, 7.0000
29.02500, 0.50, 45.0, 6.7082
29.07500, 0.50, 50.0, 7.0711
29.12500, 0.50, 49.0, 7.0000
29.17500, 0.50, 41.0, 6.4031
29.22500, 0.50, 51.0, 7.1414
29.27500, 0.50, 57.0, 7.5498
29.32500, 0.50, 49.0, 7.0000
29.37500, 0.50, 56.0, 7.4833
29.42500, 0.50, 60.0, 7.7460
29.47500, 0.50, 49.0, 7.0000
29.52500, 0.50, 37.0, 6.0828
29.57500, 0.50, 47.0, 6.8557
29.62500, 0.50, 30.0, 5.4772
29.67500, 0.50, 37.0, 6.0828
29.72500, 0.50, 38.0, 6.1644
29.77500, 0.50, 40.0, 6.3246
29.82500, 0.50, 44.0, 6.6332
29.87500, 0.50, 42.0, 6.4807
29.92500, 0.50, 29.0, 5.3852
29.97500, 0.50, 43.0, 6.5574
30.02500, 0.50, 43.0, 6.5574
30.07500, 0.50, 35.0, 5.9161
30.12500, 0.50, 25.0, 5.0000
30.17500, 0.50, 22.0, 4.6904
30.22500, 0.50, 33.0, 5.7446
30.27500, 0.50, 43.0, 6.5574
30.32500, 0.50, 27.0, 5.1962
30.37500, 0.50, 34.0, 5.8310
30.42500, 0.50, 38.0, 6.1644
30.47500, 0.50, 23.0, 4.7958
30.52500, 0.50, 42.0, 6.4807
30.57500, 0.50, 48.0, 6.9282
30.62500, 0.50, 33.0, 5.7446
30.67500, 0.50, 30.0, 5.4772
30.72500, 0.50, 38.0, 6.1644
30.77500, 0.50, 34.0, 5.8310
30.82500, 0.50, 39.0, 6.2450
30.87500, 0.50, 39.0, 6.2450
30.92500, 0.50, 23.0, 4.7958
30.97500, 0.50, 30.0, 5.4772
31.02500, 0.50, 33.0, 5.7446
31.07500, 0.50, 25.0, 5.0000
31.12500, 0.50, 33.0, 5.7446
31.17500, 0.50, 39.0, 6.2450
31.22500, 0.50, 39.0, 6.2450
31.27500, 0.50, 37.0, 6.0828
31.32500, 0.50, 29.0, 5.3852
31.37500, 0.50, 34.0, 5.8310
31.42500, 0.50, 34.0, 5.8310
31.47500, 0.50, 40.0, 6.3246
31.52500, 0.50, 28.0, 5.2915
31.57500, 0.50, 25.0, 5.0000
31.62500, 0.50, 34.0, 5.8310
31.67500, 0.50, 33.0, 5.7446
31.72500, 0.50, 41.0, 6.4031
31.77500, 0.50, 30.0, 5.4772
31.82500, 0.50, 35.0, 5.9161
31.87500, 0.50, 41.0, 6.4031
31.92500, 0.50, 45.0, 6.7082
31.97500, 0.50, 31.0, 5.5678
32.02500, 0.50, 28.0, 5.2915
32.07500, 0.50, 31.0, 5.5678
32.12500, 0.50, 28.0, 5.2915
32.17500, 0.50, 35.0, 5.9161
32.22500, 0.50, 37.0, 6.0828
32.27500, 0.50, 27.0, 5.1962
32.32500, 0.50, 34.0, 5.8310
32.37500, 0.50, 25.0, 5.0000
32.42500, 0.50, 24.0, 4.8990
32.47500, 0.50, 28.0, 5.2915
32.52500, 0.50, 34.0, 5.8310
32.57500, 0.50, 27.0, 5.1962
32.62500, 0.50, 24.0, 4.8990
32.67500, 0.50, 20.0, 4.4721
32.72500, 0.50, 25.0, 5.0000
32.77500, 0.50, 14.0, 3.7417
32.82500, 0.50, 24.0, 4.8990
32.87500, 0.50, 24.0, 4.8990
32.92500, 0.50, 24.0, 4.8990
32.97500, 0.50, 27.0, 5.1962
33.02500, 0.50, 35.0, 5.9161
33.07500, 0.50, 20.0, 4.4721
33.12500, 0.50, 30.0, 5.4772
33.17500, 0.50, 27.0, 5.1962
33.22500, 0.50, 31.0, 5.5678
33.27500, 0.50, 29.0, 5.3852
33.32500, 0.50, 27.0, 5.1962
33.37500, 0.50, 35.0, 5.9161
33.42500, 0.50, 22.0, 4.6904
33.47500, 0.50, 24.0, 4.8990
33.52500, 0.50, 33.0, 5.7446
33.57500, 0.50, 21.0, 4.5826
33.62500, 0.50, 33.0, 5.7446
33.67500, 0.50, 39.0, 6.2450
33.72500, 0.50, 29.0, 5.3852
33.77500, 0.50, 33.0, 5.7446
33.82500, 0.50, 34.0, 5.8310
33.87500, 0.50, 26.0, 5.0990
33.92500, 0.50, 39.0, 6.2450
33.97500, 0.50, 32.0, 5.6569
34.02500, 0.50, 25.0, 5.0000
34.07500, 0.50, 28.0, 5.2915
34.12500, 0.50, 30.0, 5.4772
34.17500, 0.50, 32.0, 5.6569
34.22500, 0.50, 37.0, 6.0828
34.27500, 0.50, 35.0, 5.9161
34.32500, 0.50, 33.0, 5.7446
34.37500, 0.50, 32.0, 5.6569
34.42500, 0.50, 27.0, 5.1962
34.47500, 0.50, 27.0, 5.1962
34.52500, 0.50, 20.0, 4.4721
34.57500, 0.50, 27.0, 5.1962
34.62500, 0.50, 29.0, 5.3852
34.67500, 0.50, 18.0, 4.2426
34.72500, 0.50, 19.0, 4.3589
34.77500, 0.50, 22.0, 4.6904
34.82500, 0.50, 27.0, 5.1962
34.87500, 0.50, 30.0, 5.4772
34.92500, 0.50, 17.0, 4.1231
34.97500, 0.50, 24.0, 4.8990
35.02500, 0.50, 23.0, 4.7958
35.07500, 0.50, 27.0, 5.1962
35.12500, 0.50, 15.0, 3.8730
35.17500, 0.50, 24.0, 4.8990
35.22500, 0.50, 37.0, 6.0828
35.27500, 0.50, 31.0, 5.5678
35.32500, 0.50, 29.0, 5.3852
35.37500, 0.50, 28.0, 5.2915
35.42500, 0.50, 25.0, 5.0000
35.47500, 0.50, 26.0, 5.0990
35.52500, 0.50, 34.0, 5.8310
35.57500, 0.50, 28.0, 5.2915
35.62500, 0.50, 26.0, 5.0990
35.67500, 0.50, 30.0, 5.4772
35.72500, 0.50, 28.0, 5.2915
35.77500, 0.50, 25.0, 5.0000
35.82500, 0.50, 24.0, 4.8990
35.87500, 0.50, 26.0, 5.0990
35.92500, 0.50, 24.0, 4.8990
35.97500, 0.50, 30.0, 5.4772
36.02500, 0.50, 19.0, 4.3589
36.07500, 0.50, 24.0, 4.8990
36.12500, 0.50, 31.0, 5.5678
36.17500, 0.50, 24.0, 4.8990
36.22500, 0.50, 27.0, 5.1962
36.27500, 0.50, 27.0, 5.1962
36.32500, 0.50, 36.0, 6.0000
36.37500, 0.50, 24.0, 4.8990
36.42500, 0.50, 24.0, 4.8990
36.47500, 0.50, 32.0, 5.6569
36.52500, 0.50, 21.0, 4.5826
36.57500, 0.50, 23.0, 4.7958
36.62500, 0.50, 34.0, 5.8310
36.67500, 0.50, 25.0, 5.0000
36.72500, 0.50, 23.0, 4.7958
36.77500, 0.50, 26.0, 5.0990
36.82500, 0.50, 24.0, 4.8990
36.87500, 0.50, 26.0, 5.0990
36.92500, 0.50, 21.0, 4.5826
36.97500, 0.50, 33.0, 5.7446
37.02500, 0.50, 34.0, 5.8310
37.07500, 0.50, 27.0, 5.1962
37.12500, 0.50, 23.0, 4.7958
37.17500, 0.50, 29.0, 5.3852
37.22500, 0.50, 25.0, 5.0000
37.27500, 0.50, 32.0, 5.6569
37.32500, 0.50, 37.0, 6.0828
37.37500, 0.50, 33.0, 5.7446
37.42500, 0.50, 34.0, 5.8310
37.47500, 0.50, 22.0, 4.6904
37.52500, 0.50, 38.0, 6.1644
37.57500, 0.50, 45.0, 6.7082
37.62500, 0.50, 47.0, 6.8557
37.67500, 0.50, 57.0, 7.5498
37.72500, 0.50, 76.0, 8.7178
37.77500, 0.50, 116.0, 10.7703
37.82500, 0.50, 170.0, 13.0384
37.87500, 0.50, 277.0, 16.6433
37.92500, 0.50, 415.0, 20.3715
37.97500, 0.50, 726.0, 26.9444
38.02500, 0.50, 1114.0, 33.3766
38.07500, 0.50, 1400.0, 37.4166
38.12500, 0.50, 1354.0, 36.7967
38.17500, 0.50, 1016.0, 31.8748
38.22500, 0.50, 655.0, 25.5930
38.27500, 0.50, 348.0, 18.6548
38.32500, 0.50, 185.0, 13.6015
38.37500, 0.50, 105.0, 10.2470
38.42500, 0.50, 86.0, 9.2736
38.47500, 0.50, 63.0, 7.9373
38.52500, 0.50, 43.0, 6.5574
38.57500, 0.50, 44.0, 6.6332
38.62500, 0.50, 39.0, 6.2450
38.67500, 0.50, 31.0, 5.5678
38.72500, 0.50, 34.0, 5.8310
38.77500, 0.50, 23.0, 4.7958
38.82500, 0.50, 26.0, 5.0990
38.87500, 0.50, 30.0, 5.4772
38.92500, 0.50, 26.0, 5.0990
38.97500, 0.50, 28.0, 5.2915
39.02500, 0.50, 29.0, 5.3852
39.07500, 0.50, 27.0, 5.1962
39.12500, 0.50, 23.0, 4.7958
39.17500, 0.50, 22.0, 4.6904
39.22500, 0.50, 28.0, 5.2915
39.27500, 0.50, 28.0, 5.2915
39.32500, 0.50, 20.0, 4.4721
39.37500, 0.50, 23.0, 4.7958
39.42500, 0.50, 29.0, 5.3852
39.47500, 0.50, 18.0, 4.2426
39.52500, 0.50, 24.0, 4.8990
39.57500, 0.50, 19.0, 4.3589
39.62500, 0.50, 20.0, 4.4721
39.67500, 0.50, 23.0, 4.7958
39.72500, 0.50, 24.0, 4.8990
39.77500, 0.50, 22.0, 4.6904
39.82500, 0.50, 16.0, 4.0000
39.87500, 0.50, 17.0, 4.1231
39.92500, 0.50, 16.0, 4.0000
39.97500, 0.50, 19.0, 4.3589
40.02500, 0.50, 16.0, 4.0000
40.07500, 0.50, 29.0, 5.3852
40.12500, 0.50, 16.0, 4.0000
40.17500, 0.50, 19.0, 4.3589
40.22500, 0.50, 20.0, 4.4721
40.27500, 0.50, 17.0, 4.1231
40.32500, 0.50, 16.0, 4.0000
40.37500, 0.50, 22.0, 4.6904
40.42500, 0.50, 13.0, 3.6056
40.47500, 0.50, 18.0, 4.2426
40.52500, 0.50, 11.0, 3.3166
40.57500, 0.50, 15.0, 3.8730
40.62500, 0.50, 20.0, 4.4721
40.67500, 0.50, 13.0, 3.6056
40.72500, 0.50, 19.0, 4.3589
40.77500, 0.50, 21.0, 4.5826
40.82500, 0.50, 16.0, 4.0000
40.87500, 0.50, 29.0, 5.3852
40.92500, 0.50, 18.0, 4.2426
40.97500, 0.50, 9.0, 3.0000
41.02500, 0.50, 21.0, 4.5826
41.07500, 0.50, 19.0, 4.3589
41.12500, 0.50, 12.0, 3.4641
41.17500, 0.50, 14.0, 3.7417
41.22500, 0.50, 19.0, 4.3589
41.27500, 0.50, 17.0, 4.1231
41.32500, 0.50, 23.0, 4.7958
41.37500, 0.50, 13.0, 3.6056
41.42500, 0.50, 13.0, 3.6056
41.47500, 0.50, 19.0, 4.3589
41.52500, 0.50, 21.0, 4.5826
41.57500, 0.50, 18.0, 4.2426
41.62500, 0.50, 24.0, 4.8990
41.67500, 0.50, 18.0, 4.2426
41.72500, 0.50, 14.0, 3.7417
41.77500, 0.50, 19.0, 4.3589
41.82500, 0.50, 17.0, 4.1231
41.87500, 0.50, 23.0, 4.7958
41.92500, 0.50, 15.0, 3.8730
41.97500, 0.50, 24.0, 4.8990
42.02500, 0.50, 18.0, 4.2426
42.07500, 0.50, 15.0, 3.8730
42.12500, 0.50, 23.0, 4.7958
42.17500, 0.50, 21.0, 4.5826
42.22500, 0.50, 24.0, 4.8990
42.27500, 0.50, 25.0, 5.0000
42.32500, 0.50, 27.0, 5.1962
42.37500, 0.50, 22.0, 4.6904
42.42500, 0.50, 21.0, 4.5826
42.47500, 0.50, 15.0, 3.8730
42.52500, 0.50, 17.0, 4.1231
42.57500, 0.50, 20.0, 4.4721
42.62500, 0.50, 14.0, 3.7417
42.67500, 0.50, 18.0, 4.2426
42.72500, 0.50, 24.0, 4.8990
42.77500, 0.50, 22.0, 4.6904
42.82500, 0.50, 24.0, 4.8990
42.87500, 0.50, 20.0, 4.4721
42.92500, 0.50, 12.0, 3.4641
42.97500, 0.50, 20.0, 4.4721
43.02500, 0.50, 23.0, 4.7958
43.07500, 0.50, 24.0, 4.8990
43.12500, 0.50, 25.0, 5.0000
43.17500, 0.50, 27.0, 5.1962
43.22500, 0.50, 15.0, 3.8730
43.27500, 0.50, 24.0, 4.8990
43.32500, 0.50, 17.0, 4.1231
43.37500, 0.50, 24.0, 4.8990
43.42500, 0.50, 28.0, 5.2915
43.47500, 0.50, 21.0, 4.5826
43.52500, 0.50, 25.0, 5.0000
43.57500, 0.50, 22.0, 4.6904
43.62500, 0.50, 25.0, 5.0000
43.67500, 0.50, 27.0, 5.1962
43.72500, 0.50, 32.0, 5.6569
43.77500, 0.50, 31.0, 5.5678
43.82500, 0.50, 27.0, 5.1962
43.87500, 0.50, 50.0, 7.0711
43.92500, 0.50, 48.0, 6.9282
43.97500, 0.50, 73.0, 8.5440
44.02500, 0.50, 118.0, 10.8628
44.07500, 0.50, 168.0, 12.9615
44.12500, 0.50, 275.0, 16.5831
44.17500, 0.50, 378.0, 19.4422
44.22500, 0.50, 498.0, 22.3159
44.27500, 0.50, 543.0, 23.3024
44.32500, 0.50, 537.0, 23.1733
44.37500, 0.50, 424.0, 20.5913
44.42500, 0.50, 313.0, 17.6918
44.47500, 0.50, 190.0, 13.7840
44.52500, 0.50, 115.0, 10.7238
44.57500, 0.50, 75.0, 8.6603
44.62500, 0.50, 43.0, 6.5574
44.67500, 0.50, 31.0, 5.5678
44.72500, 0.50, 30.0, 5.4772
44.77500, 0.50, 24.0, 4.8990
44.82500, 0.50, 26.0, 5.0990
44.87500, 0.50, 32.0, 5.6569
44.92500, 0.50, 20.0, 4.4721
44.97500, 0.50, 22.0, 4.6904
45.02500, 0.50, 21.0, 4.5826
45.07500, 0.50, 15.0, 3.8730
45.12500, 0.50, 20.0, 4.4721
45.17500, 0.50, 18.0, 4.2426
45.22500, 0.50, 11.0, 3.3166
45.27500, 0.50, 23.0, 4.7958
45.32500, 0.50, 14.0, 3.7417
45.37500, 0.50, 18.0, 4.2426
45.42500, 0.50, 17.0, 4.1231
45.47500, 0.50, 19.0, 4.3589
45.52500, 0.50, 14.0, 3.7417
45.57500, 0.50, 19.0, 4.3589
45.62500, 0.50, 12.0, 3.4641
45.67500, 0.50, 7.0, 2.6458
45.72500, 0.50, 25.0, 5.0000
45.77500, 0.50, 9.0, 3.0000
45.82500, 0.50, 9.0, 3.0000
45.87500, 0.50, 13.0, 3.6056
45.92500, 0.50, 16.0, 4.0000
45.97500, 0.50, 15.0, 3.8730
46.02500, 0.50, 13.0, 3.6056
46.07500, 0.50, 10.0, 3.1623
46.12500, 0.50, 17.0, 4.1231
46.17500, 0.50, 12.0, 3.4641
46.22500, 0.50, 18.0, 4.2426
46.27500, 0.50, 8.0, 2.8284
46.32500, 0.50, 15.0, 3.8730
46.37500, 0.50, 14.0, 3.7417
46.42500, 0.50, 19.0, 4.3589
46.47500, 0.50, 12.0, 3.4641
46.52500, 0.50, 13.0, 3.6056
46.57500, 0.50, 15.0, 3.8730
46.62500, 0.50, 16.0, 4.0000
46.67500, 0.50, 15.0, 3.8730
46.72500, 0.50, 13.0, 3.6056
46.77500, 0.50, 15.0, 3.8730
46.82500, 0.50, 12.0, 3.4641
46.87500, 0.50, 7.0, 2.6458
46.92500, 0.50, 9.0, 3.0000
46.97500, 0.50, 16.0, 4.0000
47.02500, 0.50, 15.0, 3.8730
47.07500, 0.50, 10.0, 3.1623
47.12500, 0.50, 16.0, 4.0000
47.17500, 0.50, 19.0, 4.3589
47.22500, 0.50, 15.0, 3.8730
47.27500, 0.50, 12.0, 3.4641
47.32500, 0.50, 11.0, 3.3166
47.37500, 0.50, 13.0, 3.6056
47.42500, 0.50, 12.0, 3.4641
47.47500, 0.50, 10.0, 3.1623
47.52500, 0.50, 11.0, 3.3166
47.57500, 0.50, 14.0, 3.7417
47.62500, 0.50, 7.0, 2.6458
47.67500, 0.50, 12.0, 3.4641
47.72500, 0.50, 13.0, 3.6056
47.77500, 0.50, 16.0, 4.0000
47.82500, 0.50, 23.0, 4.7958
47.87500, 0.50, 9.0, 3.0000
47.92500, 0.50, 9.0, 3.0000
47.97500, 0.50, 18.0, 4.2426
48.02500, 0.50, 13.0, 3.6056
48.07500, 0.50, 18.0, 4.2426
48.12500, 0.50, 15.0, 3.8730
48.17500, 0.50, 10.0, 3.1623
48.22500, 0.50, 14.0, 3.7417
48.27500, 0.50, 9.0, 3.0000
48.32500, 0.50, 12.0, 3.4641
48.37500, 0.50, 9.0, 3.0000
48.42500, 0.50, 16.0, 4.0000
48.47500, 0.50, 7.0, 2.6458
48.52500, 0.50, 14.0, 3.7417
48.57500, 0.50, 13.0, 3.6056
48.62500, 0.50, 19.0, 4.3589
48.67500, 0.50, 16.0, 4.0000
48.72500, 0.50, 15.0, 3.8730
48.77500, 0.50, 11.0, 3.3166
48.82500, 0.50, 11.0, 3.3166
48.87500, 0.50, 17.0, 4.1231
48.92500, 0.50, 13.0, 3.6056
48.97500, 0.50, 11.0, 3.3166
49.02500, 0.50, 6.0, 2.4495
49.07500, 0.50, 8.0, 2.8284
49.12500, 0.50, 14.0, 3.7417
49.17500, 0.50, 10.0, 3.1623
49.22500, 0.50, 5.0, 2.2361
49.27500, 0.50, 14.0, 3.7417
49.32500, 0.50, 12.0, 3.4641
49.37500, 0.50, 10.0, 3.1623
49.42500, 0.50, 11.0, 3.3166
49.47500, 0.50, 8.0, 2.8284
49.52500, 0.50, 15.0, 3.8730
49.57500, 0.50, 14.0, 3.7417
49.62500, 0.50, 10.0, 3.1623
49.67500, 0.50, 15.0, 3.8730
49.72500, 0.50, 17.0, 4.1231
49.77500, 0.50, 7.0, 2.6458
49.82500, 0.50, 13.0, 3.6056
49.87500, 0.50, 7.0, 2.6458
49.92500, 0.50, 11.0, 3.3166
49.97500, 0.50, 15.0, 3.8730
50.02500, 0.50, 21.0, 4.5826
50.07500, 0.50, 12.0, 3.4641
50.12500, 0.50, 8.0, 2.8284
50.17500, 0.50, 15.0, 3.8730
50.22500, 0.50, 6.0, 2.4495
50.27500, 0.50, 10.0, 3.1623
50.32500, 0.50, 11.0, 3.3166
50.37500, 0.50, 3.0, 1.7321
50.42500, 0.50, 10.0, 3.1623
50.47500, 0.50, 16.0, 4.0000
50.52500, 0.50, 18.0, 4.2426
50.57500, 0.50, 9.0, 3.0000
50.62500, 0.50, 9.0, 3.0000
50.67500, 0.50, 16.0, 4.0000
50.72500, 0.50, 11.0, 3.3166
50.77500, 0.50, 11.0, 3.3166
50.82500, 0.50, 9.0, 3.0000
50.87500, 0.50, 11.0, 3.3166
50.92500, 0.50, 12.0, 3.4641
50.97500, 0.50, 5.0, 2.2361
51.02500, 0.50, 12.0, 3.4641
51.07500, 0.50, 8.0, 2.8284
51.12500, 0.50, 11.0, 3.3166
51.17500, 0.50, 10.0, 3.1623
51.22500, 0.50, 14.0, 3.7417
51.27500, 0.50, 11.0, 3.3166
51.32500, 0.50, 14.0, 3.7417
51.37500, 0.50, 9.0, 3.0000
51.42500, 0.50, 9.0, 3.0000
51.47500, 0.50, 6.0, 2.4495
51.52500, 0.50, 13.0, 3.6056
51.57500, 0.50, 10.0, 3.1623
51.62500, 0.50, 15.0, 3.8730
51.67500, 0.50, 14.0, 3.7417
51.72500, 0.50, 11.0, 3.3166
51.77500, 0.50, 8.0, 2.8284
51.82500, 0.50, 5.0, 2.2361
51.87500, 0.50, 11.0, 3.3166
51.92500, 0.50, 5.0, 2.2361
51.97500, 0.50, 7.0, 2.6458
52.02500, 0.50, 12.0, 3.4641
52.07500, 0.50, 5.0, 2.2361
52.12500, 0.50, 10.0, 3.1623
52.17500, 0.50, 10.0, 3.1623
52.22500, 0.50, 6.0, 2.4495
52.27500, 0.50, 9.0, 3.0000
52.32500, 0.50, 8.0, 2.8284
52.37500, 0.50, 5.0, 2.2361
52.42500, 0.50, 13.0, 3.6056
52.47500, 0.50, 13.0, 3.6056
52.52500, 0.50, 9.0, 3.0000
52.57500, 0.50, 9.0, 3.0000
52.62500, 0.50, 10.0, 3.1623
52.67500, 0.50, 9.0, 3.0000
52.72500, 0.50, 9.0, 3.0000
52.77500, 0.50, 9.0, 3.0000
52.82500, 0.50, 6.0, 2.4495
52.87500, 0.50, 8.0, 2.8284
52.92500, 0.50, 13.0, 3.6056
52.97500, 0.50, 8.0, 2.8284
53.02500, 0.50, 16.0, 4.0000
53.07500, 0.50, 13.0, 3.6056
53.12500, 0.50, 10.0, 3.1623
53.17500, 0.50, 16.0, 4.0000
53.22500, 0.50, 9.0, 3.0000
53.27500, 0.50, 10.0, 3.1623
53.32500, 0.50, 9.0, 3.0000
53.37500, 0.50, 9.0, 3.0000
53.42500, 0.50, 11.0, 3.3166
53.47500, 0.50, 6.0, 2.4495
53.52500, 0.50, 19.0, 4.3589
53.57500, 0.50, 8.0, 2.8284
53.62500, 0.50, 7.0, 2.6458
53.67500, 0.50, 11.0, 3.3166
53.72500, 0.50, 10.0, 3.1623
53.77500, 0.50, 5.0, 2.2361
53.82500, 0.50, 4.0, 2.0000
53.87500, 0.50, 7.0, 2.6458
53.92500, 0.50, 8.0, 2.8284
53.97500, 0.50, 2.0, 1.4142
54.02500, 0.50, 13.0, 3.6056
54.07500, 0.50, 8.0, 2.8284
54.12500, 0.50, 20.0, 4.4721
54.17500, 0.50, 7.0, 2.6458
54.22500, 0.50, 11.0, 3.3166
54.27500, 0.50, 5.0, 2.2361
54.32500, 0.50, 10.0, 3.1623
54.37500, 0.50, 11.0, 3.3166
54.42500, 0.50, 6.0, 2.4495
54.47500, 0.50, 11.0, 3.3166
54.52500, 0.50, 12.0, 3.4641
54.57500, 0.50, 5.0, 2.2361
54.62500, 0.50, 11.0, 3.3166
54.67500, 0.50, 10.0, 3.1623
54.72500, 0.50, 12.0, 3.4641
54.77500, 0.50, 14.0, 3.7417
54.82500, 0.50, 7.0, 2.6458
54.87500, 0.50, 5.0, 2.2361
54.92500, 0.50, 8.0, 2.8284
54.97500, 0.50, 8.0, 2.8284
55.02500, 0.50, 12.0, 3.4641
55.07500, 0.50, 14.0, 3.7417
55.12500, 0.50, 12.0, 3.4641
55.17500, 0.50, 13.0, 3.6056
55.22500, 0.50, 5.0, 2.2361
55.27500, 0.50, 13.0, 3.6056
55.32500, 0.50, 6.0, 2.4495
55.37500, 0.50, 10.0, 3.1623
55.42500, 0.50, 6.0, 2.4495
55.47500, 0.50, 10.0, 3.1623
55.52500, 0.50, 12.0, 3.4641
55.57500, 0.50, 9.0, 3.0000
55.62500, 0.50, 10.0, 3.1623
55.67500, 0.50, 6.0, 2.4495
55.72500, 0.50, 12.0, 3.4641
55.77500, 0.50, 9.0, 3.0000
55.82500, 0.50, 14.0, 3.7417
55.87500, 0.50, 8.0, 2.8284
55.92500, 0.50, 13.0, 3.6056
55.97500, 0.50, 10.0, 3.1623
56.02500, 0.50, 11.0, 3.3166
56.07500, 0.50, 7.0, 2.6458
56.12500, 0.50, 9.0, 3.0000
56.17500, 0.50, 10.0, 3.1623
56.22500, 0.50, 10.0, 3.1623
56.27500, 0.50, 4.0, 2.0000
56.32500, 0.50, 9.0, 3.0000
56.37500, 0.50, 12.0, 3.4641
56.42500, 0.50, 11.0, 3.3166
56.47500, 0.50, 6.0, 2.4495
56.52500, 0.50, 10.0, 3.1623
56.57500, 0.50, 8.0, 2.8284
56.62500, 0.50, 8.0, 2.8284
56.67500, 0.50, 10.0, 3.1623
56.72500, 0.50, 10.0, 3.1623
56.77500, 0.50, 13.0, 3.6056
56.82500, 0.50, 7.0, 2.6458
56.87500, 0.50, 9.0, 3.0000
56.92500, 0.50, 8.0, 2.8284
56.97500, 0.50, 13.0, 3.6056
57.02500, 0.50, 7.0, 2.6458
57.07500, 0.50, 8.0, 2.8284
57.12500, 0.50, 6.0, 2.4495
57.17500, 0.50, 8.0, 2.8284
57.22500, 0.50, 11.0, 3.3166
57.27500, 0.50, 11.0, 3.3166
57.32500, 0.50, 8.0, 2.8284
57.37500, 0.50, 14.0, 3.7417
57.42500, 0.50, 7.0, 2.6458
57.47500, 0.50, 10.0, 3.1623
57.52500, 0.50, 12.0, 3.4641
57.57500, 0.50, 6.0, 2.4495
57.62500, 0.50, 11.0, 3.3166
57.67500, 0.50, 9.0, 3.0000
57.72500, 0.50, 10.0, 3.1623
57.77500, 0.50, 15.0, 3.8730
57.82500, 0.50, 8.0, 2.8284
57.87500, 0.50, 4.0, 2.0000
57.92500, 0.50, 7.0, 2.6458
57.97500, 0.50, 5.0, 2.2361
58.02500, 0.50, 10.0, 3.1623
58.07500, 0.50, 9.0, 3.0000
58.12500, 0.50, 11.0, 3.3166
58.17500, 0.50, 15.0, 3.8730
58.22500, 0.50, 14.0, 3.7417
58.27500, 0.50, 3.0, 1.7321
58.32500, 0.50, 5.0, 2.2361
58.37500, 0.50, 12.0, 3.4641
58.42500, 0.50, 9.0, 3.0000
58.47500, 0.50, 9.0, 3.0000
58.52500, 0.50, 5.0, 2.2361
58.57500, 0.50, 6.0, 2.4495
58.62500, 0.50, 11.0, 3.3166
58.67500, 0.50, 6.0, 2.4495
58.72500, 0.50, 11.0, 3.3166
58.77500, 0.50, 3.0, 1.7321
58.82500, 0.50, 7.0, 2.6458
58.87500, 0.50, 6.0, 2.4495
58.92500, 0.50, 8.0, 2.8284
58.97500, 0.50, 6.0, 2.4495
59.02500, 0.50, 6.0, 2.4495
59.07500, 0.50, 8.0, 2.8284
59.12500, 0.50, 10.0, 3.1623
59.17500, 0.50, 8.0, 2.8284
59.22500, 0.50, 13.0, 3.6056
59.27500, 0.50, 10.0, 3.1623
59.32500, 0.50, 6.0, 2.4495
59.37500, 0.50, 10.0, 3.1623
59.42500, 0.50, 6.0, 2.4495
59.47500, 0.50, 5.0, 2.2361
59.52500, 0.50, 8.0, 2.8284
59.57500, 0.50, 16.0, 4.0000
59.62500, 0.50, 8.0, 2.8284
59.67500, 0.50, 12.0, 3.4641
59.72500, 0.50, 9.0, 3.0000
59.77500, 0.50, 11.0, 3.3166
59.82500, 0.50, 7.0, 2.6458
59.87500, 0.50, 13.0, 3.6056
59.92500, 0.50, 11.0, 3.3166
59.97500, 0.50, 9.0, 3.0000
60.02500, 0.50, 12.0, 3.4641
60.07500, 0.50, 15.0, 3.8730
60.12500, 0.50, 14.0, 3.7417
60.17500, 0.50, 10.0, 3.1623
60.22500, 0.50, 12.0, 3.4641
60.27500, 0.50, 9.0, 3.0000
60.32500, 0.50, 5.0, 2.2361
60.37500, 0.50, 4.0, 2.0000
60.42500, 0.50, 7.0, 2.6458
60.47500, 0.50, 8.0, 2.8284
60.52500, 0.50, 12.0, 3.4641
60.57500, 0.50, 6.0, 2.4495
60.62500, 0.50, 12.0, 3.4641
60.67500, 0.50, 6.0, 2.4495
60.72500, 0.50, 6.0, 2.4495
60.77500, 0.50, 5.0, 2.2361
60.82500, 0.50, 9.0, 3.0000
60.87500, 0.50, 10.0, 3.1623
60.92500, 0.50, 6.0, 2.4495
60.97500, 0.50, 11.0, 3.3166
61.02500, 0.50, 10.0, 3.1623
61.07500, 0.50, 6.0, 2.4495
61.12500, 0.50, 11.0, 3.3166
61.17500, 0.50, 11.0, 3.3166
61.22500, 0.50, 7.0, 2.6458
61.27500, 0.50, 5.0, 2.2361
61.32500, 0.50, 10.0, 3.1623
61.37500, 0.50, 12.0, 3.4641
61.42500, 0.50, 10.0, 3.1623
61.47500, 0.50, 11.0, 3.3166
61.52500, 0.50, 5.0, 2.2361
61.57500, 0.50, 6.0, 2.4495
61.62500, 0.50, 16.0, 4.0000
61.67500, 0.50, 11.0, 3.3166
61.72500, 0.50, 6.0, 2.4495
61.77500, 0.50, 15.0, 3.8730
61.82500, 0.50, 11.0, 3.3166
61.87500, 0.50, 8.0, 2.8284
61.92500, 0.50, 7.0, 2.6458
61.97500, 0.50, 17.0, 4.1231
62.02500, 0.50, 11.0, 3.3166
62.07500, 0.50, 14.0, 3.7417
62.12500, 0.50, 8.0, 2.8284
62.17500, 0.50, 9.0, 3.0000
62.22500, 0.50, 10.0, 3.1623
62.27500, 0.50, 9.0, 3.0000
62.32500, 0.50, 11.0, 3.3166
62.37500, 0.50, 13.0, 3.6056
62.42500, 0.50, 9.0, 3.0000
62.47500, 0.50, 10.0, 3.1623
62.52500, 0.50, 11.0, 3.3166
62.57500, 0.50, 8.0, 2.8284
62.62500, 0.50, 4.0, 2.0000
62.67500, 0.50, 6.0, 2.4495
62.72500, 0.50, 12.0, 3.4641
62.77500, 0.50, 11.0, 3.3166
62.82500, 0.50, 7.0, 2.6458
62.87500, 0.50, 10.0, 3.1623
62.92500, 0.50, 9.0, 3.0000
62.97500, 0.50, 6.0, 2.4495
63.02500, 0.50, 9.0, 3.0000
63.07500, 0.50, 10.0, 3.1623
63.12500, 0.50, 12.0, 3.4641
63.17500, 0.50, 6.0, 2.4495
63.22500, 0.50, 10.0, 3.1623
63.27500, 0.50, 11.0, 3.3166
63.32500, 0.50, 4.0, 2.0000
63.37500, 0.50, 12.0, 3.4641
63.42500, 0.50, 12.0, 3.4641
63.47500, 0.50, 12.0, 3.4641
63.52500, 0.50, 15.0, 3.8730
63.57500, 0.50, 15.0, 3.8730
63.62500, 0.50, 14.0, 3.7417
63.67500, 0.50, 12.0, 3.4641
63.72500, 0.50, 17.0, 4.1231
63.77500, 0.50, 11.0, 3.3166
63.82500, 0.50, 13.0, 3.6056
63.87500, 0.50, 10.0, 3.1623
63.92500, 0.50, 10.0, 3.1623
63.97500, 0.50, 17.0, 4.1231
64.02500, 0.50, 22.0, 4.6904
64.07500, 0.50, 23.0, 4.7958
64.12500, 0.50, 31.0, 5.5678
64.17500, 0.50, 41.0, 6.4031
64.22500, 0.50, 49.0, 7.0000
64.27500, 0.50, 107.0, 10.3441
64.32500, 0.50, 154.0, 12.4097
64.37500, 0.50, 229.0, 15.1327
64.42500, 0.50, 270.0, 16.4317
64.47500, 0.50, 213.0, 14.5945
64.52500, 0.50, 191.0, 13.8203
64.57500, 0.50, 188.0, 13.7113
64.62500, 0.50, 136.0, 11.6619
64.67500, 0.50, 108.0, 10.3923
64.72500, 0.50, 63.0, 7.9373
64.77500, 0.50, 35.0, 5.9161
64.82500, 0.50, 35.0, 5.9161
64.87500, 0.50, 23.0, 4.7958
64.92500, 0.50, 24.0, 4.8990
64.97500, 0.50, 12.0, 3.4641
65.02500, 0.50, 20.0, 4.4721
65.07500, 0.50, 13.0, 3.6056
65.12500, 0.50, 11.0, 3.3166
65.17500, 0.50, 14.0, 3.7417
65.22500, 0.50, 17.0, 4.1231
65.27500, 0.50, 11.0, 3.3166
65.32500, 0.50, 10.0, 3.1623
65.37500, 0.50, 13.0, 3.6056
65.42500, 0.50, 11.0, 3.3166
65.47500, 0.50, 8.0, 2.8284
65.52500, 0.50, 6.0, 2.4495
65.57500, 0.50, 14.0, 3.7417
65.62500, 0.50, 6.0, 2.4495
65.67500, 0.50, 12.0, 3.4641
65.72500, 0.50, 7.0, 2.6458
65.77500, 0.50, 11.0, 3.3166
65.82500, 0.50, 11.0, 3.3166
65.87500, 0.50, 10.0, 3.1623
65.92500, 0.50, 15.0, 3.8730
65.97500, 0.50, 8.0, 2.8284
66.02500, 0.50, 11.0, 3.3166
66.07500, 0.50, 10.0, 3.1623
66.12500, 0.50, 9.0, 3.0000
66.17500, 0.50, 5.0, 2.2361
66.22500, 0.50, 12.0, 3.4641
66.27500, 0.50, 12.0, 3.4641
66.32500, 0.50, 11.0, 3.3166
66.37500, 0.50, 7.0, 2.6458
66.42500, 0.50, 16.0, 4.0000
66.47500, 0.50, 12.0, 3.4641
66.52500, 0.50, 7.0, 2.6458
66.57500, 0.50, 6.0, 2.4495
66.62500, 0.50, 13.0, 3.6056
66.67500, 0.50, 12.0, 3.4641
66.72500, 0.50, 12.0, 3.4641
66.77500, 0.50, 13.0, 3.6056
66.82500, 0.50, 10.0, 3.1623
66.87500, 0.50, 10.0, 3.1623
66.92500, 0.50, 7.0, 2.6458
66.97500, 0.50, 12.0, 3.4641
67.02500, 0.50, 7.0, 2.6458
67.07500, 0.50, 8.0, 2.8284
67.12500, 0.50, 7.0, 2.6458
67.17500, 0.50, 8.0, 2.8284
67.22500, 0.50, 11.0, 3.3166
67.27500, 0.50, 6.0, 2.4495
67.32500, 0.50, 10.0, 3.1623
67.37500, 0.50, 9.0, 3.0000
67.42500, 0.50, 9.0, 3.0000
67.47500, 0.50, 10.0, 3.1623
67.52500, 0.50, 7.0, 2.6458
67.57500, 0.50, 10.0, 3.1623
67.62500, 0.50, 14.0, 3.7417
67.67500, 0.50, 6.0, 2.4495
67.72500, 0.50, 8.0, 2.8284
67.77500, 0.50, 9.0, 3.0000
67.82500, 0.50, 6.0, 2.4495
67.87500, 0.50, 11.0, 3.3166
67.92500, 0.50, 6.0, 2.4495
67.97500, 0.50, 10.0, 3.1623
68.02500, 0.50, 11.0, 3.3166
68.07500, 0.50, 7.0, 2.6458
68.12500, 0.50, 7.0, 2.6458
68.17500, 0.50, 15.0, 3.8730
68.22500, 0.50, 5.0, 2.2361
68.27500, 0.50, 8.0, 2.8284
68.32500, 0.50, 9.0, 3.0000
68.37500, 0.50, 9.0, 3.0000
68.42500, 0.50, 6.0, 2.4495
68.47500, 0.50, 11.0, 3.3166
68.52500, 0.50, 11.0, 3.3166
68.57500, 0.50, 12.0, 3.4641
68.62500, 0.50, 9.0, 3.0000
68.67500, 0.50, 17.0, 4.1231
68.72500, 0.50, 3.0, 1.7321
68.77500, 0.50, 9.0, 3.0000
68.82500, 0.50, 10.0, 3.1623
68.87500, 0.50, 6.0, 2.4495
68.92500, 0.50, 4.0, 2.0000
68.97500, 0.50, 8.0, 2.8284
69.02500, 0.50, 9.0, 3.0000
69.07500, 0.50, 10.0, 3.1623
69.12500, 0.50, 10.0, 3.1623
69.17500, 0.50, 5.0, 2.2361
69.22500, 0.50, 13.0, 3.6056
69.27500, 0.50, 4.0, 2.0000
69.32500, 0.50, 10.0, 3.1623
69.37500, 0.50, 9.0, 3.0000
69.42500, 0.50, 5.0, 2.2361
69.47500, 0.50, 3.0, 1.7321
69.52500, 0.50, 13.0, 3.6056
69.57500, 0.50, 14.0, 3.7417
69.62500, 0.50, 10.0, 3.1623
69.67500, 0.50, 5.0, 2.2361
69.72500, 0.50, 8.0, 2.8284
69.77500, 0.50, 5.0, 2.2361
69.82500, 0.50, 9.0, 3.0000
69.87500, 0.50, 6.0, 2.4495
69.92500, 0.50, 6.0, 2.4495
69.97500, 0.50, 9.0, 3.0000
70.02500, 0.50, 6.0, 2.4495
70.07500, 0.50, 2.0, 1.4142
70.12500, 0.50, 13.0, 3.6056
70.17500, 0.50, 7.0, 2.6458
70.22500, 0.50, 12.0, 3.4641
70.27500, 0.50, 6.0, 2.4495
70.32500, 0.50, 9.0, 3.0000
70.37500, 0.50, 6.0, 2.4495
70.42500, 0.50, 4.0, 2.0000
70.47500, 0.50, 3.0, 1.7321
70.52500, 0.50, 3.0, 1.7321
70.57500, 0.50, 8.0, 2.8284
70.62500, 0.50, 9.0, 3.0000
70.67500, 0.50, 7.0, 2.6458
70.72500, 0.50, 11.0, 3.3166
70.77500, 0.50, 6.0, 2.4495
70.82500, 0.50, 7.0, 2.6458
70.87500, 0.50, 7.0, 2.6458
70.92500, 0.50, 4.0, 2.0000
70.97500, 0.50, 4.0, 2.0000
71.02500, 0.50, 9.0, 3.0000
71.07500, 0.50, 6.0, 2.4495
71.12500, 0.50, 10.0, 3.1623
71.17500, 0.50, 8.0, 2.8284
71.22500, 0.50, 11.0, 3.3166
71.27500, 0.50, 3.0, 1.7321
71.32500, 0.50, 8.0, 2.8284
71.37500, 0.50, 6.0, 2.4495
71.42500, 0.50, 9.0, 3.0000
71.47500, 0.50, 9.0, 3.0000
71.52500, 0.50, 8.0, 2.8284
71.57500, 0.50, 5.0, 2.2361
71.62500, 0.50, 5.0, 2.2361
71.67500, 0.50, 8.0, 2.8284
71.72500, 0.50, 12.0, 3.4641
71.77500, 0.50, 8.0, 2.8284
71.82500, 0.50, 2.0, 1.4142
71.87500, 0.50, 7.0, 2.6458
71.92500, 0.50, 8.0, 2.8284
71.97500, 0.50, 7.0, 2.6458
72.02500, 0.50, 8.0, 2.8284
72.07500, 0.50, 12.0, 3.4641
72.12500, 0.50, 9.0, 3.0000
72.17500, 0.50, 6.0, 2.4495
72.22500, 0.50, 7.0, 2.6458
72.27500, 0.50, 4.0, 2.0000
72.32500, 0.50, 9.0, 3.0000
72.37500, 0.50, 7.0, 2.6458
72.42500, 0.50, 8.0, 2.8284
72.47500, 0.50, 6.0, 2.4495
72.52500, 0.50, 5.0, 2.2361
72.57500, 0.50, 7.0, 2.6458
72.62500, 0.50, 6.0, 2.4495
72.67500, 0.50, 8.0, 2.8284
72.72500, 0.50, 2.0, 1.4142
72.77500, 0.50, 11.0, 3.3166
72.82500, 0.50, 4.0, 2.0000
72.87500, 0.50, 5.0, 2.2361
72.92500, 0.50, 6.0, 2.4495
72.97500, 0.50, 7.0, 2.6458
73.02500, 0.50, 6.0, 2.4495
73.07500, 0.50, 6.0, 2.4495
73.12500, 0.50, 8.0, 2.8284
73.17500, 0.50, 6.0, 2.4495
73.22500, 0.50, 9.0, 3.0000
73.27500, 0.50, 7.0, 2.6458
73.32500, 0.50, 7.0, 2.6458
73.37500, 0.50, 8.0, 2.8284
73.42500, 0.50, 7.0, 2.6458
73.47500, 0.50, 8.0, 2.8284
73.52500, 0.50, 6.0, 2.4495
73.57500, 0.50, 6.0, 2.4495
73.62500, 0.50, 6.0, 2.4495
73.67500, 0.50, 6.0, 2.4495
73.72500, 0.50, 5.0, 2.2361
73.77500, 0.50, 10.0, 3.1623
73.82500, 0.50, 7.0, 2.6458
73.87500, 0.50, 9.0, 3.0000
73.92500, 0.50, 12.0, 3.4641
73.97500, 0.50, 12.0, 3.4641
74.02500, 0.50, 10.0, 3.1623
74.07500, 0.50, 6.0, 2.4495
74.12500, 0.50, 10.0, 3.1623
74.17500, 0.50, 7.0, 2.6458
74.22500, 0.50, 6.0, 2.4495
74.27500, 0.50, 11.0, 3.3166
74.32500, 0.50, 10.0, 3.1623
74.37500, 0.50, 12.0, 3.4641
74.42500, 0.50, 6.0, 2.4495
74.47500, 0.50, 3.0, 1.7321
74.52500, 0.50, 8.0, 2.8284
74.57500, 0.50, 8.0, 2.8284
74.62500, 0.50, 3.0, 1.7321
74.67500, 0.50, 5.0, 2.2361
74.72500, 0.50, 8.0, 2.8284
74.77500, 0.50, 5.0, 2.2361
74.82500, 0.50, 8.0, 2.8284
74.87500, 0.50, 4.0, 2.0000
74.92500, 0.50, 8.0, 2.8284
74.97500, 0.50, 11.0, 3.3166
75.02500, 0.50, 8.0, 2.8284
75.07500, 0.50, 10.0, 3.1623
75.12500, 0.50, 8.0, 2.8284
75.17500, 0.50, 10.0, 3.1623
75.22500, 0.50, 4.0, 2.0000
75.27500, 0.50, 7.0, 2.6458
75.32500, 0.50, 6.0, 2.4495
75.37500, 0.50, 2.0, 1.4142
75.42500, 0.50, 13.0, 3.6056
75.47500, 0.50, 5.0, 2.2361
75.52500, 0.50, 14.0, 3.7417
75.57500, 0.50, 12.0, 3.4641
75.62500, 0.50, 7.0, 2.6458
75.67500, 0.50, 9.0, 3.0000
75.72500, 0.50, 11.0, 3.3166
75.77500, 0.50, 17.0, 4.1231
75.82500, 0.50, 6.0, 2.4495
75.87500, 0.50, 9.0, 3.0000
75.92500, 0.50, 12.0, 3.4641
75.97500, 0.50, 7.0, 2.6458
76.02500, 0.50, 6.0, 2.4495
76.07500, 0.50, 6.0, 2.4495
76.12500, 0.50, 6.0, 2.4495
76.17500, 0.50, 8.0, 2.8284
76.22500, 0.50, 7.0, 2.6458
76.27500, 0.50, 15.0, 3.8730
76.32500, 0.50, 11.0, 3.3166
76.37500, 0.50, 6.0, 2.4495
76.42500, 0.50, 11.0, 3.3166
76.47500, 0.50, 11.0, 3.3166
76.52500, 0.50, 6.0, 2.4495
76.57500, 0.50, 18.0, 4.2426
76.62500, 0.50, 6.0, 2.4495
76.67500, 0.50, 19.0, 4.3589
76.72500, 0.50, 9.0, 3.0000
76.77500, 0.50, 12.0, 3.4641
76.82500, 0.50, 10.0, 3.1623
76.87500, 0.50, 13.0, 3.6056
76.92500, 0.50, 20.0, 4.4721
76.97500, 0.50, 26.0, 5.0990
77.02500, 0.50, 23.0, 4.7958
77.07500, 0.50, 43.0, 6.5574
77.12500, 0.50, 30.0, 5.4772
77.17500, 0.50, 76.0, 8.7178
77.22500, 0.50, 92.0, 9.5917
77.27500, 0.50, 165.0, 12.8452
77.32500, 0.50, 213.0, 14.5945
77.37500, 0.50, 226.0, 15.0333
77.42500, 0.50, 199.0, 14.1067
77.47500, 0.50, 170.0, 13.0384
77.52500, 0.50, 139.0, 11.7898
77.57500, 0.50, 128.0, 11.3137
77.62500, 0.50, 136.0, 11.6619
77.67500, 0.50, 88.0, 9.3808
77.72500, 0.50, 62.0, 7.8740
77.77500, 0.50, 36.0, 6.0000
77.82500, 0.50, 36.0, 6.0000
77.87500, 0.50, 25.0, 5.0000
77.92500, 0.50, 16.0, 4.0000
77.97500, 0.50, 11.0, 3.3166
78.02500, 0.50, 25.0, 5.0000
78.07500, 0.50, 11.0, 3.3166
78.12500, 0.50, 9.0, 3.0000
78.17500, 0.50, 13.0, 3.6056
78.22500, 0.50, 10.0, 3.1623
78.27500, 0.50, 11.0, 3.3166
78.32500, 0.50, 11.0, 3.3166
78.37500, 0.50, 10.0, 3.1623
78.42500, 0.50, 12.0, 3.4641
78.47500, 0.50, 6.0, 2.4495
78.52500, 0.50, 6.0, 2.4495
78.57500, 0.50, 8.0, 2.8284
78.62500, 0.50, 11.0, 3.3166
78.67500, 0.50, 6.0, 2.4495
78.72500, 0.50, 15.0, 3.8730
78.77500, 0.50, 8.0, 2.8284
78.82500, 0.50, 14.0, 3.7417
78.87500, 0.50, 4.0, 2.0000
78.92500, 0.50, 12.0, 3.4641
78.97500, 0.50, 6.0, 2.4495
79.02500, 0.50, 5.0, 2.2361
79.07500, 0.50, 5.0, 2.2361
79.12500, 0.50, 6.0, 2.4495
79.17500, 0.50, 10.0, 3.1623
79.22500, 0.50, 14.0, 3.7417
79.27500, 0.50, 9.0, 3.0000
79.32500, 0.50, 7.0, 2.6458
79.37500, 0.50, 9.0, 3.0000
79.42500, 0.50, 8.0, 2.8284
79.47500, 0.50, 6.0, 2.4495
79.52500, 0.50, 8.0, 2.8284
79.57500, 0.50, 4.0, 2.0000
79.62500, 0.50, 5.0, 2.2361
79.67500, 0.50, 5.0, 2.2361
79.72500, 0.50, 8.0, 2.8284
79.77500, 0.50, 9.0, 3.0000
79.82500, 0.50, 8.0, 2.8284
79.87500, 0.50, 3.0, 1.7321
79.92500, 0.50, 9.0, 3.0000
79.97500, 0.50, 11.0, 3.3166