File: G04004.csv
[Measurement conditions]
Sample identification,25%Ag-AP
Comment - 1,"Configuration=Programmable xy with programmable z platforms, Owner=User, Creation date=02/07/2021 13:22:25"
Comment - 2,"Goniometer=Theta/Theta; Minimum step size 2Theta:0.0001; Minimum step size Omega:0.0001"
Comment - 3,"Sample stage=Programmable xy-platform with programmable z-adjustment; Minimum step size X:0.01; Minimum step size Y:0.01; Minimum step size Z:0.001"
Comment - 4,"Diffractometer system=EMPYREAN"
Comment - 5,"Measurement program=C:\PANalytical\Data Collector\Programs\Knapp Group (CK)\Songming Liu\20-80°, 0.05° step, 0.5s-step.xrdmp, Created identifier={D6D0720B-9417-4404-86A5-80CEFF14CAE1}, Created by=User, Id=WL:EMPYREANGI:User, Creation date=20/06/2024 10:10:34"
Anode material,Cu
K-Alpha1 wavelength,1.5405980
K-Alpha2 wavelength,1.5444260
Ratio K-Alpha2/K-Alpha1,0.500
Divergence slit,Fixed,0.76mm
Monochromator used,NO
Generator voltage, 40
Tube current, 40
File date and time,15/Jul/2024 12:51
Unit cell,
h k l, 0 0 0
Scan axis,2Theta
Scan range,20.00000,80.00000
Scan step size,0.0500000
No. of points, 1200
Scan type,CONTINUOUS
Omega,1.0000
X,-0.72
Y,-1.07
Z,20.290
Time per step,0.50
[Scan points]
Angle, TimePerStep, Intensity, ESD
20.02500, 0.50, 68.0, 8.2462
20.07500, 0.50, 64.0, 8.0000
20.12500, 0.50, 62.0, 7.8740
20.17500, 0.50, 74.0, 8.6023
20.22500, 0.50, 59.0, 7.6811
20.27500, 0.50, 52.0, 7.2111
20.32500, 0.50, 46.0, 6.7823
20.37500, 0.50, 53.0, 7.2801
20.42500, 0.50, 55.0, 7.4162
20.47500, 0.50, 50.0, 7.0711
20.52500, 0.50, 51.0, 7.1414
20.57500, 0.50, 62.0, 7.8740
20.62500, 0.50, 67.0, 8.1854
20.67500, 0.50, 50.0, 7.0711
20.72500, 0.50, 63.0, 7.9373
20.77500, 0.50, 74.0, 8.6023
20.82500, 0.50, 56.0, 7.4833
20.87500, 0.50, 45.0, 6.7082
20.92500, 0.50, 68.0, 8.2462
20.97500, 0.50, 64.0, 8.0000
21.02500, 0.50, 67.0, 8.1854
21.07500, 0.50, 70.0, 8.3666
21.12500, 0.50, 53.0, 7.2801
21.17500, 0.50, 57.0, 7.5498
21.22500, 0.50, 74.0, 8.6023
21.27500, 0.50, 62.0, 7.8740
21.32500, 0.50, 70.0, 8.3666
21.37500, 0.50, 77.0, 8.7750
21.42500, 0.50, 63.0, 7.9373
21.47500, 0.50, 61.0, 7.8102
21.52500, 0.50, 50.0, 7.0711
21.57500, 0.50, 51.0, 7.1414
21.62500, 0.50, 66.0, 8.1240
21.67500, 0.50, 62.0, 7.8740
21.72500, 0.50, 44.0, 6.6332
21.77500, 0.50, 61.0, 7.8102
21.82500, 0.50, 60.0, 7.7460
21.87500, 0.50, 59.0, 7.6811
21.92500, 0.50, 49.0, 7.0000
21.97500, 0.50, 50.0, 7.0711
22.02500, 0.50, 63.0, 7.9373
22.07500, 0.50, 60.0, 7.7460
22.12500, 0.50, 45.0, 6.7082
22.17500, 0.50, 56.0, 7.4833
22.22500, 0.50, 41.0, 6.4031
22.27500, 0.50, 52.0, 7.2111
22.32500, 0.50, 62.0, 7.8740
22.37500, 0.50, 64.0, 8.0000
22.42500, 0.50, 57.0, 7.5498
22.47500, 0.50, 53.0, 7.2801
22.52500, 0.50, 56.0, 7.4833
22.57500, 0.50, 55.0, 7.4162
22.62500, 0.50, 50.0, 7.0711
22.67500, 0.50, 53.0, 7.2801
22.72500, 0.50, 44.0, 6.6332
22.77500, 0.50, 46.0, 6.7823
22.82500, 0.50, 48.0, 6.9282
22.87500, 0.50, 52.0, 7.2111
22.92500, 0.50, 48.0, 6.9282
22.97500, 0.50, 49.0, 7.0000
23.02500, 0.50, 43.0, 6.5574
23.07500, 0.50, 50.0, 7.0711
23.12500, 0.50, 47.0, 6.8557
23.17500, 0.50, 69.0, 8.3066
23.22500, 0.50, 36.0, 6.0000
23.27500, 0.50, 47.0, 6.8557
23.32500, 0.50, 52.0, 7.2111
23.37500, 0.50, 40.0, 6.3246
23.42500, 0.50, 47.0, 6.8557
23.47500, 0.50, 62.0, 7.8740
23.52500, 0.50, 46.0, 6.7823
23.57500, 0.50, 54.0, 7.3485
23.62500, 0.50, 46.0, 6.7823
23.67500, 0.50, 49.0, 7.0000
23.72500, 0.50, 54.0, 7.3485
23.77500, 0.50, 37.0, 6.0828
23.82500, 0.50, 52.0, 7.2111
23.87500, 0.50, 45.0, 6.7082
23.92500, 0.50, 46.0, 6.7823
23.97500, 0.50, 49.0, 7.0000
24.02500, 0.50, 45.0, 6.7082
24.07500, 0.50, 55.0, 7.4162
24.12500, 0.50, 43.0, 6.5574
24.17500, 0.50, 51.0, 7.1414
24.22500, 0.50, 60.0, 7.7460
24.27500, 0.50, 45.0, 6.7082
24.32500, 0.50, 45.0, 6.7082
24.37500, 0.50, 44.0, 6.6332
24.42500, 0.50, 35.0, 5.9161
24.47500, 0.50, 42.0, 6.4807
24.52500, 0.50, 56.0, 7.4833
24.57500, 0.50, 35.0, 5.9161
24.62500, 0.50, 42.0, 6.4807
24.67500, 0.50, 42.0, 6.4807
24.72500, 0.50, 44.0, 6.6332
24.77500, 0.50, 36.0, 6.0000
24.82500, 0.50, 47.0, 6.8557
24.87500, 0.50, 53.0, 7.2801
24.92500, 0.50, 52.0, 7.2111
24.97500, 0.50, 52.0, 7.2111
25.02500, 0.50, 40.0, 6.3246
25.07500, 0.50, 43.0, 6.5574
25.12500, 0.50, 48.0, 6.9282
25.17500, 0.50, 49.0, 7.0000
25.22500, 0.50, 40.0, 6.3246
25.27500, 0.50, 34.0, 5.8310
25.32500, 0.50, 26.0, 5.0990
25.37500, 0.50, 45.0, 6.7082
25.42500, 0.50, 50.0, 7.0711
25.47500, 0.50, 48.0, 6.9282
25.52500, 0.50, 57.0, 7.5498
25.57500, 0.50, 48.0, 6.9282
25.62500, 0.50, 38.0, 6.1644
25.67500, 0.50, 54.0, 7.3485
25.72500, 0.50, 46.0, 6.7823
25.77500, 0.50, 55.0, 7.4162
25.82500, 0.50, 50.0, 7.0711
25.87500, 0.50, 36.0, 6.0000
25.92500, 0.50, 44.0, 6.6332
25.97500, 0.50, 33.0, 5.7446
26.02500, 0.50, 39.0, 6.2450
26.07500, 0.50, 41.0, 6.4031
26.12500, 0.50, 43.0, 6.5574
26.17500, 0.50, 37.0, 6.0828
26.22500, 0.50, 40.0, 6.3246
26.27500, 0.50, 39.0, 6.2450
26.32500, 0.50, 43.0, 6.5574
26.37500, 0.50, 42.0, 6.4807
26.42500, 0.50, 32.0, 5.6569
26.47500, 0.50, 25.0, 5.0000
26.52500, 0.50, 37.0, 6.0828
26.57500, 0.50, 50.0, 7.0711
26.62500, 0.50, 37.0, 6.0828
26.67500, 0.50, 37.0, 6.0828
26.72500, 0.50, 42.0, 6.4807
26.77500, 0.50, 29.0, 5.3852
26.82500, 0.50, 29.0, 5.3852
26.87500, 0.50, 43.0, 6.5574
26.92500, 0.50, 30.0, 5.4772
26.97500, 0.50, 38.0, 6.1644
27.02500, 0.50, 29.0, 5.3852
27.07500, 0.50, 34.0, 5.8310
27.12500, 0.50, 36.0, 6.0000
27.17500, 0.50, 31.0, 5.5678
27.22500, 0.50, 33.0, 5.7446
27.27500, 0.50, 35.0, 5.9161
27.32500, 0.50, 31.0, 5.5678
27.37500, 0.50, 26.0, 5.0990
27.42500, 0.50, 33.0, 5.7446
27.47500, 0.50, 36.0, 6.0000
27.52500, 0.50, 37.0, 6.0828
27.57500, 0.50, 35.0, 5.9161
27.62500, 0.50, 36.0, 6.0000
27.67500, 0.50, 45.0, 6.7082
27.72500, 0.50, 34.0, 5.8310
27.77500, 0.50, 35.0, 5.9161
27.82500, 0.50, 21.0, 4.5826
27.87500, 0.50, 35.0, 5.9161
27.92500, 0.50, 23.0, 4.7958
27.97500, 0.50, 39.0, 6.2450
28.02500, 0.50, 24.0, 4.8990
28.07500, 0.50, 24.0, 4.8990
28.12500, 0.50, 37.0, 6.0828
28.17500, 0.50, 36.0, 6.0000
28.22500, 0.50, 34.0, 5.8310
28.27500, 0.50, 30.0, 5.4772
28.32500, 0.50, 35.0, 5.9161
28.37500, 0.50, 38.0, 6.1644
28.42500, 0.50, 34.0, 5.8310
28.47500, 0.50, 35.0, 5.9161
28.52500, 0.50, 30.0, 5.4772
28.57500, 0.50, 36.0, 6.0000
28.62500, 0.50, 26.0, 5.0990
28.67500, 0.50, 34.0, 5.8310
28.72500, 0.50, 24.0, 4.8990
28.77500, 0.50, 19.0, 4.3589
28.82500, 0.50, 32.0, 5.6569
28.87500, 0.50, 32.0, 5.6569
28.92500, 0.50, 35.0, 5.9161
28.97500, 0.50, 16.0, 4.0000
29.02500, 0.50, 20.0, 4.4721
29.07500, 0.50, 31.0, 5.5678
29.12500, 0.50, 28.0, 5.2915
29.17500, 0.50, 23.0, 4.7958
29.22500, 0.50, 36.0, 6.0000
29.27500, 0.50, 32.0, 5.6569
29.32500, 0.50, 31.0, 5.5678
29.37500, 0.50, 31.0, 5.5678
29.42500, 0.50, 24.0, 4.8990
29.47500, 0.50, 24.0, 4.8990
29.52500, 0.50, 36.0, 6.0000
29.57500, 0.50, 30.0, 5.4772
29.62500, 0.50, 24.0, 4.8990
29.67500, 0.50, 27.0, 5.1962
29.72500, 0.50, 34.0, 5.8310
29.77500, 0.50, 31.0, 5.5678
29.82500, 0.50, 31.0, 5.5678
29.87500, 0.50, 36.0, 6.0000
29.92500, 0.50, 31.0, 5.5678
29.97500, 0.50, 29.0, 5.3852
30.02500, 0.50, 36.0, 6.0000
30.07500, 0.50, 22.0, 4.6904
30.12500, 0.50, 21.0, 4.5826
30.17500, 0.50, 20.0, 4.4721
30.22500, 0.50, 33.0, 5.7446
30.27500, 0.50, 21.0, 4.5826
30.32500, 0.50, 22.0, 4.6904
30.37500, 0.50, 35.0, 5.9161
30.42500, 0.50, 23.0, 4.7958
30.47500, 0.50, 35.0, 5.9161
30.52500, 0.50, 24.0, 4.8990
30.57500, 0.50, 21.0, 4.5826
30.62500, 0.50, 15.0, 3.8730
30.67500, 0.50, 28.0, 5.2915
30.72500, 0.50, 27.0, 5.1962
30.77500, 0.50, 29.0, 5.3852
30.82500, 0.50, 32.0, 5.6569
30.87500, 0.50, 24.0, 4.8990
30.92500, 0.50, 13.0, 3.6056
30.97500, 0.50, 22.0, 4.6904
31.02500, 0.50, 21.0, 4.5826
31.07500, 0.50, 26.0, 5.0990
31.12500, 0.50, 23.0, 4.7958
31.17500, 0.50, 21.0, 4.5826
31.22500, 0.50, 21.0, 4.5826
31.27500, 0.50, 21.0, 4.5826
31.32500, 0.50, 33.0, 5.7446
31.37500, 0.50, 24.0, 4.8990
31.42500, 0.50, 27.0, 5.1962
31.47500, 0.50, 18.0, 4.2426
31.52500, 0.50, 22.0, 4.6904
31.57500, 0.50, 21.0, 4.5826
31.62500, 0.50, 32.0, 5.6569
31.67500, 0.50, 15.0, 3.8730
31.72500, 0.50, 28.0, 5.2915
31.77500, 0.50, 33.0, 5.7446
31.82500, 0.50, 25.0, 5.0000
31.87500, 0.50, 21.0, 4.5826
31.92500, 0.50, 23.0, 4.7958
31.97500, 0.50, 21.0, 4.5826
32.02500, 0.50, 23.0, 4.7958
32.07500, 0.50, 25.0, 5.0000
32.12500, 0.50, 22.0, 4.6904
32.17500, 0.50, 19.0, 4.3589
32.22500, 0.50, 24.0, 4.8990
32.27500, 0.50, 17.0, 4.1231
32.32500, 0.50, 22.0, 4.6904
32.37500, 0.50, 19.0, 4.3589
32.42500, 0.50, 21.0, 4.5826
32.47500, 0.50, 10.0, 3.1623
32.52500, 0.50, 16.0, 4.0000
32.57500, 0.50, 19.0, 4.3589
32.62500, 0.50, 22.0, 4.6904
32.67500, 0.50, 20.0, 4.4721
32.72500, 0.50, 22.0, 4.6904
32.77500, 0.50, 18.0, 4.2426
32.82500, 0.50, 22.0, 4.6904
32.87500, 0.50, 24.0, 4.8990
32.92500, 0.50, 18.0, 4.2426
32.97500, 0.50, 20.0, 4.4721
33.02500, 0.50, 20.0, 4.4721
33.07500, 0.50, 28.0, 5.2915
33.12500, 0.50, 18.0, 4.2426
33.17500, 0.50, 19.0, 4.3589
33.22500, 0.50, 26.0, 5.0990
33.27500, 0.50, 25.0, 5.0000
33.32500, 0.50, 13.0, 3.6056
33.37500, 0.50, 18.0, 4.2426
33.42500, 0.50, 17.0, 4.1231
33.47500, 0.50, 15.0, 3.8730
33.52500, 0.50, 22.0, 4.6904
33.57500, 0.50, 22.0, 4.6904
33.62500, 0.50, 26.0, 5.0990
33.67500, 0.50, 26.0, 5.0990
33.72500, 0.50, 20.0, 4.4721
33.77500, 0.50, 12.0, 3.4641
33.82500, 0.50, 21.0, 4.5826
33.87500, 0.50, 21.0, 4.5826
33.92500, 0.50, 11.0, 3.3166
33.97500, 0.50, 20.0, 4.4721
34.02500, 0.50, 20.0, 4.4721
34.07500, 0.50, 24.0, 4.8990
34.12500, 0.50, 22.0, 4.6904
34.17500, 0.50, 21.0, 4.5826
34.22500, 0.50, 26.0, 5.0990
34.27500, 0.50, 28.0, 5.2915
34.32500, 0.50, 27.0, 5.1962
34.37500, 0.50, 22.0, 4.6904
34.42500, 0.50, 20.0, 4.4721
34.47500, 0.50, 20.0, 4.4721
34.52500, 0.50, 19.0, 4.3589
34.57500, 0.50, 16.0, 4.0000
34.62500, 0.50, 18.0, 4.2426
34.67500, 0.50, 22.0, 4.6904
34.72500, 0.50, 18.0, 4.2426
34.77500, 0.50, 13.0, 3.6056
34.82500, 0.50, 16.0, 4.0000
34.87500, 0.50, 17.0, 4.1231
34.92500, 0.50, 17.0, 4.1231
34.97500, 0.50, 15.0, 3.8730
35.02500, 0.50, 18.0, 4.2426
35.07500, 0.50, 35.0, 5.9161
35.12500, 0.50, 18.0, 4.2426
35.17500, 0.50, 24.0, 4.8990
35.22500, 0.50, 16.0, 4.0000
35.27500, 0.50, 21.0, 4.5826
35.32500, 0.50, 26.0, 5.0990
35.37500, 0.50, 20.0, 4.4721
35.42500, 0.50, 28.0, 5.2915
35.47500, 0.50, 16.0, 4.0000
35.52500, 0.50, 24.0, 4.8990
35.57500, 0.50, 23.0, 4.7958
35.62500, 0.50, 27.0, 5.1962
35.67500, 0.50, 18.0, 4.2426
35.72500, 0.50, 27.0, 5.1962
35.77500, 0.50, 23.0, 4.7958
35.82500, 0.50, 16.0, 4.0000
35.87500, 0.50, 24.0, 4.8990
35.92500, 0.50, 19.0, 4.3589
35.97500, 0.50, 28.0, 5.2915
36.02500, 0.50, 29.0, 5.3852
36.07500, 0.50, 29.0, 5.3852
36.12500, 0.50, 19.0, 4.3589
36.17500, 0.50, 20.0, 4.4721
36.22500, 0.50, 34.0, 5.8310
36.27500, 0.50, 43.0, 6.5574
36.32500, 0.50, 25.0, 5.0000
36.37500, 0.50, 27.0, 5.1962
36.42500, 0.50, 38.0, 6.1644
36.47500, 0.50, 31.0, 5.5678
36.52500, 0.50, 28.0, 5.2915
36.57500, 0.50, 22.0, 4.6904
36.62500, 0.50, 40.0, 6.3246
36.67500, 0.50, 32.0, 5.6569
36.72500, 0.50, 24.0, 4.8990
36.77500, 0.50, 29.0, 5.3852
36.82500, 0.50, 35.0, 5.9161
36.87500, 0.50, 27.0, 5.1962
36.92500, 0.50, 27.0, 5.1962
36.97500, 0.50, 35.0, 5.9161
37.02500, 0.50, 27.0, 5.1962
37.07500, 0.50, 38.0, 6.1644
37.12500, 0.50, 39.0, 6.2450
37.17500, 0.50, 34.0, 5.8310
37.22500, 0.50, 23.0, 4.7958
37.27500, 0.50, 38.0, 6.1644
37.32500, 0.50, 37.0, 6.0828
37.37500, 0.50, 46.0, 6.7823
37.42500, 0.50, 51.0, 7.1414
37.47500, 0.50, 41.0, 6.4031
37.52500, 0.50, 57.0, 7.5498
37.57500, 0.50, 68.0, 8.2462
37.62500, 0.50, 68.0, 8.2462
37.67500, 0.50, 83.0, 9.1104
37.72500, 0.50, 106.0, 10.2956
37.77500, 0.50, 136.0, 11.6619
37.82500, 0.50, 208.0, 14.4222
37.87500, 0.50, 230.0, 15.1658
37.92500, 0.50, 364.0, 19.0788
37.97500, 0.50, 470.0, 21.6795
38.02500, 0.50, 505.0, 22.4722
38.07500, 0.50, 618.0, 24.8596
38.12500, 0.50, 550.0, 23.4521
38.17500, 0.50, 477.0, 21.8403
38.22500, 0.50, 353.0, 18.7883
38.27500, 0.50, 238.0, 15.4272
38.32500, 0.50, 189.0, 13.7477
38.37500, 0.50, 129.0, 11.3578
38.42500, 0.50, 100.0, 10.0000
38.47500, 0.50, 97.0, 9.8489
38.52500, 0.50, 65.0, 8.0623
38.57500, 0.50, 70.0, 8.3666
38.62500, 0.50, 51.0, 7.1414
38.67500, 0.50, 43.0, 6.5574
38.72500, 0.50, 54.0, 7.3485
38.77500, 0.50, 52.0, 7.2111
38.82500, 0.50, 38.0, 6.1644
38.87500, 0.50, 43.0, 6.5574
38.92500, 0.50, 30.0, 5.4772
38.97500, 0.50, 28.0, 5.2915
39.02500, 0.50, 38.0, 6.1644
39.07500, 0.50, 34.0, 5.8310
39.12500, 0.50, 34.0, 5.8310
39.17500, 0.50, 33.0, 5.7446
39.22500, 0.50, 32.0, 5.6569
39.27500, 0.50, 24.0, 4.8990
39.32500, 0.50, 36.0, 6.0000
39.37500, 0.50, 31.0, 5.5678
39.42500, 0.50, 34.0, 5.8310
39.47500, 0.50, 38.0, 6.1644
39.52500, 0.50, 22.0, 4.6904
39.57500, 0.50, 17.0, 4.1231
39.62500, 0.50, 29.0, 5.3852
39.67500, 0.50, 22.0, 4.6904
39.72500, 0.50, 22.0, 4.6904
39.77500, 0.50, 20.0, 4.4721
39.82500, 0.50, 19.0, 4.3589
39.87500, 0.50, 23.0, 4.7958
39.92500, 0.50, 27.0, 5.1962
39.97500, 0.50, 17.0, 4.1231
40.02500, 0.50, 15.0, 3.8730
40.07500, 0.50, 25.0, 5.0000
40.12500, 0.50, 19.0, 4.3589
40.17500, 0.50, 18.0, 4.2426
40.22500, 0.50, 20.0, 4.4721
40.27500, 0.50, 18.0, 4.2426
40.32500, 0.50, 20.0, 4.4721
40.37500, 0.50, 21.0, 4.5826
40.42500, 0.50, 21.0, 4.5826
40.47500, 0.50, 15.0, 3.8730
40.52500, 0.50, 29.0, 5.3852
40.57500, 0.50, 21.0, 4.5826
40.62500, 0.50, 27.0, 5.1962
40.67500, 0.50, 23.0, 4.7958
40.72500, 0.50, 18.0, 4.2426
40.77500, 0.50, 22.0, 4.6904
40.82500, 0.50, 24.0, 4.8990
40.87500, 0.50, 25.0, 5.0000
40.92500, 0.50, 25.0, 5.0000
40.97500, 0.50, 23.0, 4.7958
41.02500, 0.50, 20.0, 4.4721
41.07500, 0.50, 23.0, 4.7958
41.12500, 0.50, 26.0, 5.0990
41.17500, 0.50, 26.0, 5.0990
41.22500, 0.50, 22.0, 4.6904
41.27500, 0.50, 19.0, 4.3589
41.32500, 0.50, 18.0, 4.2426
41.37500, 0.50, 34.0, 5.8310
41.42500, 0.50, 36.0, 6.0000
41.47500, 0.50, 27.0, 5.1962
41.52500, 0.50, 30.0, 5.4772
41.57500, 0.50, 27.0, 5.1962
41.62500, 0.50, 22.0, 4.6904
41.67500, 0.50, 24.0, 4.8990
41.72500, 0.50, 19.0, 4.3589
41.77500, 0.50, 33.0, 5.7446
41.82500, 0.50, 16.0, 4.0000
41.87500, 0.50, 24.0, 4.8990
41.92500, 0.50, 20.0, 4.4721
41.97500, 0.50, 26.0, 5.0990
42.02500, 0.50, 23.0, 4.7958
42.07500, 0.50, 23.0, 4.7958
42.12500, 0.50, 28.0, 5.2915
42.17500, 0.50, 28.0, 5.2915
42.22500, 0.50, 29.0, 5.3852
42.27500, 0.50, 28.0, 5.2915
42.32500, 0.50, 34.0, 5.8310
42.37500, 0.50, 30.0, 5.4772
42.42500, 0.50, 38.0, 6.1644
42.47500, 0.50, 33.0, 5.7446
42.52500, 0.50, 31.0, 5.5678
42.57500, 0.50, 34.0, 5.8310
42.62500, 0.50, 41.0, 6.4031
42.67500, 0.50, 44.0, 6.6332
42.72500, 0.50, 34.0, 5.8310
42.77500, 0.50, 45.0, 6.7082
42.82500, 0.50, 57.0, 7.5498
42.87500, 0.50, 70.0, 8.3666
42.92500, 0.50, 68.0, 8.2462
42.97500, 0.50, 107.0, 10.3441
43.02500, 0.50, 148.0, 12.1655
43.07500, 0.50, 263.0, 16.2173
43.12500, 0.50, 387.0, 19.6723
43.17500, 0.50, 537.0, 23.1733
43.22500, 0.50, 749.0, 27.3679
43.27500, 0.50, 861.0, 29.3428
43.32500, 0.50, 773.0, 27.8029
43.37500, 0.50, 670.0, 25.8844
43.42500, 0.50, 493.0, 22.2036
43.47500, 0.50, 303.0, 17.4069
43.52500, 0.50, 204.0, 14.2829
43.57500, 0.50, 129.0, 11.3578
43.62500, 0.50, 76.0, 8.7178
43.67500, 0.50, 84.0, 9.1652
43.72500, 0.50, 84.0, 9.1652
43.77500, 0.50, 82.0, 9.0554
43.82500, 0.50, 75.0, 8.6603
43.87500, 0.50, 81.0, 9.0000
43.92500, 0.50, 101.0, 10.0499
43.97500, 0.50, 96.0, 9.7980
44.02500, 0.50, 153.0, 12.3693
44.07500, 0.50, 129.0, 11.3578
44.12500, 0.50, 162.0, 12.7279
44.17500, 0.50, 160.0, 12.6491
44.22500, 0.50, 183.0, 13.5277
44.27500, 0.50, 184.0, 13.5647
44.32500, 0.50, 185.0, 13.6015
44.37500, 0.50, 165.0, 12.8452
44.42500, 0.50, 143.0, 11.9583
44.47500, 0.50, 105.0, 10.2470
44.52500, 0.50, 98.0, 9.8995
44.57500, 0.50, 70.0, 8.3666
44.62500, 0.50, 73.0, 8.5440
44.67500, 0.50, 58.0, 7.6158
44.72500, 0.50, 44.0, 6.6332
44.77500, 0.50, 47.0, 6.8557
44.82500, 0.50, 34.0, 5.8310
44.87500, 0.50, 28.0, 5.2915
44.92500, 0.50, 37.0, 6.0828
44.97500, 0.50, 30.0, 5.4772
45.02500, 0.50, 35.0, 5.9161
45.07500, 0.50, 29.0, 5.3852
45.12500, 0.50, 24.0, 4.8990
45.17500, 0.50, 18.0, 4.2426
45.22500, 0.50, 29.0, 5.3852
45.27500, 0.50, 26.0, 5.0990
45.32500, 0.50, 14.0, 3.7417
45.37500, 0.50, 14.0, 3.7417
45.42500, 0.50, 19.0, 4.3589
45.47500, 0.50, 14.0, 3.7417
45.52500, 0.50, 14.0, 3.7417
45.57500, 0.50, 15.0, 3.8730
45.62500, 0.50, 15.0, 3.8730
45.67500, 0.50, 17.0, 4.1231
45.72500, 0.50, 15.0, 3.8730
45.77500, 0.50, 13.0, 3.6056
45.82500, 0.50, 16.0, 4.0000
45.87500, 0.50, 15.0, 3.8730
45.92500, 0.50, 20.0, 4.4721
45.97500, 0.50, 11.0, 3.3166
46.02500, 0.50, 9.0, 3.0000
46.07500, 0.50, 21.0, 4.5826
46.12500, 0.50, 15.0, 3.8730
46.17500, 0.50, 9.0, 3.0000
46.22500, 0.50, 12.0, 3.4641
46.27500, 0.50, 9.0, 3.0000
46.32500, 0.50, 12.0, 3.4641
46.37500, 0.50, 17.0, 4.1231
46.42500, 0.50, 18.0, 4.2426
46.47500, 0.50, 16.0, 4.0000
46.52500, 0.50, 19.0, 4.3589
46.57500, 0.50, 17.0, 4.1231
46.62500, 0.50, 10.0, 3.1623
46.67500, 0.50, 8.0, 2.8284
46.72500, 0.50, 16.0, 4.0000
46.77500, 0.50, 10.0, 3.1623
46.82500, 0.50, 10.0, 3.1623
46.87500, 0.50, 13.0, 3.6056
46.92500, 0.50, 11.0, 3.3166
46.97500, 0.50, 10.0, 3.1623
47.02500, 0.50, 15.0, 3.8730
47.07500, 0.50, 14.0, 3.7417
47.12500, 0.50, 15.0, 3.8730
47.17500, 0.50, 15.0, 3.8730
47.22500, 0.50, 10.0, 3.1623
47.27500, 0.50, 9.0, 3.0000
47.32500, 0.50, 12.0, 3.4641
47.37500, 0.50, 16.0, 4.0000
47.42500, 0.50, 12.0, 3.4641
47.47500, 0.50, 17.0, 4.1231
47.52500, 0.50, 7.0, 2.6458
47.57500, 0.50, 13.0, 3.6056
47.62500, 0.50, 13.0, 3.6056
47.67500, 0.50, 10.0, 3.1623
47.72500, 0.50, 12.0, 3.4641
47.77500, 0.50, 14.0, 3.7417
47.82500, 0.50, 11.0, 3.3166
47.87500, 0.50, 7.0, 2.6458
47.92500, 0.50, 12.0, 3.4641
47.97500, 0.50, 10.0, 3.1623
48.02500, 0.50, 11.0, 3.3166
48.07500, 0.50, 13.0, 3.6056
48.12500, 0.50, 13.0, 3.6056
48.17500, 0.50, 23.0, 4.7958
48.22500, 0.50, 16.0, 4.0000
48.27500, 0.50, 12.0, 3.4641
48.32500, 0.50, 11.0, 3.3166
48.37500, 0.50, 15.0, 3.8730
48.42500, 0.50, 11.0, 3.3166
48.47500, 0.50, 18.0, 4.2426
48.52500, 0.50, 10.0, 3.1623
48.57500, 0.50, 14.0, 3.7417
48.62500, 0.50, 10.0, 3.1623
48.67500, 0.50, 13.0, 3.6056
48.72500, 0.50, 12.0, 3.4641
48.77500, 0.50, 19.0, 4.3589
48.82500, 0.50, 8.0, 2.8284
48.87500, 0.50, 12.0, 3.4641
48.92500, 0.50, 15.0, 3.8730
48.97500, 0.50, 14.0, 3.7417
49.02500, 0.50, 15.0, 3.8730
49.07500, 0.50, 15.0, 3.8730
49.12500, 0.50, 13.0, 3.6056
49.17500, 0.50, 11.0, 3.3166
49.22500, 0.50, 24.0, 4.8990
49.27500, 0.50, 7.0, 2.6458
49.32500, 0.50, 10.0, 3.1623
49.37500, 0.50, 11.0, 3.3166
49.42500, 0.50, 10.0, 3.1623
49.47500, 0.50, 17.0, 4.1231
49.52500, 0.50, 18.0, 4.2426
49.57500, 0.50, 16.0, 4.0000
49.62500, 0.50, 19.0, 4.3589
49.67500, 0.50, 21.0, 4.5826
49.72500, 0.50, 23.0, 4.7958
49.77500, 0.50, 15.0, 3.8730
49.82500, 0.50, 27.0, 5.1962
49.87500, 0.50, 25.0, 5.0000
49.92500, 0.50, 42.0, 6.4807
49.97500, 0.50, 38.0, 6.1644
50.02500, 0.50, 65.0, 8.0623
50.07500, 0.50, 57.0, 7.5498
50.12500, 0.50, 77.0, 8.7750
50.17500, 0.50, 109.0, 10.4403
50.22500, 0.50, 137.0, 11.7047
50.27500, 0.50, 165.0, 12.8452
50.32500, 0.50, 202.0, 14.2127
50.37500, 0.50, 252.0, 15.8745
50.42500, 0.50, 254.0, 15.9374
50.47500, 0.50, 236.0, 15.3623
50.52500, 0.50, 218.0, 14.7648
50.57500, 0.50, 161.0, 12.6886
50.62500, 0.50, 119.0, 10.9087
50.67500, 0.50, 96.0, 9.7980
50.72500, 0.50, 81.0, 9.0000
50.77500, 0.50, 49.0, 7.0000
50.82500, 0.50, 39.0, 6.2450
50.87500, 0.50, 30.0, 5.4772
50.92500, 0.50, 30.0, 5.4772
50.97500, 0.50, 37.0, 6.0828
51.02500, 0.50, 20.0, 4.4721
51.07500, 0.50, 15.0, 3.8730
51.12500, 0.50, 22.0, 4.6904
51.17500, 0.50, 13.0, 3.6056
51.22500, 0.50, 17.0, 4.1231
51.27500, 0.50, 14.0, 3.7417
51.32500, 0.50, 11.0, 3.3166
51.37500, 0.50, 9.0, 3.0000
51.42500, 0.50, 13.0, 3.6056
51.47500, 0.50, 12.0, 3.4641
51.52500, 0.50, 14.0, 3.7417
51.57500, 0.50, 11.0, 3.3166
51.62500, 0.50, 14.0, 3.7417
51.67500, 0.50, 11.0, 3.3166
51.72500, 0.50, 13.0, 3.6056
51.77500, 0.50, 8.0, 2.8284
51.82500, 0.50, 8.0, 2.8284
51.87500, 0.50, 9.0, 3.0000
51.92500, 0.50, 12.0, 3.4641
51.97500, 0.50, 8.0, 2.8284
52.02500, 0.50, 12.0, 3.4641
52.07500, 0.50, 11.0, 3.3166
52.12500, 0.50, 14.0, 3.7417
52.17500, 0.50, 12.0, 3.4641
52.22500, 0.50, 6.0, 2.4495
52.27500, 0.50, 12.0, 3.4641
52.32500, 0.50, 10.0, 3.1623
52.37500, 0.50, 10.0, 3.1623
52.42500, 0.50, 12.0, 3.4641
52.47500, 0.50, 13.0, 3.6056
52.52500, 0.50, 9.0, 3.0000
52.57500, 0.50, 10.0, 3.1623
52.62500, 0.50, 7.0, 2.6458
52.67500, 0.50, 6.0, 2.4495
52.72500, 0.50, 7.0, 2.6458
52.77500, 0.50, 11.0, 3.3166
52.82500, 0.50, 8.0, 2.8284
52.87500, 0.50, 5.0, 2.2361
52.92500, 0.50, 8.0, 2.8284
52.97500, 0.50, 6.0, 2.4495
53.02500, 0.50, 11.0, 3.3166
53.07500, 0.50, 12.0, 3.4641
53.12500, 0.50, 7.0, 2.6458
53.17500, 0.50, 9.0, 3.0000
53.22500, 0.50, 5.0, 2.2361
53.27500, 0.50, 10.0, 3.1623
53.32500, 0.50, 8.0, 2.8284
53.37500, 0.50, 13.0, 3.6056
53.42500, 0.50, 12.0, 3.4641
53.47500, 0.50, 10.0, 3.1623
53.52500, 0.50, 5.0, 2.2361
53.57500, 0.50, 9.0, 3.0000
53.62500, 0.50, 7.0, 2.6458
53.67500, 0.50, 9.0, 3.0000
53.72500, 0.50, 3.0, 1.7321
53.77500, 0.50, 13.0, 3.6056
53.82500, 0.50, 4.0, 2.0000
53.87500, 0.50, 5.0, 2.2361
53.92500, 0.50, 7.0, 2.6458
53.97500, 0.50, 9.0, 3.0000
54.02500, 0.50, 9.0, 3.0000
54.07500, 0.50, 2.0, 1.4142
54.12500, 0.50, 6.0, 2.4495
54.17500, 0.50, 8.0, 2.8284
54.22500, 0.50, 8.0, 2.8284
54.27500, 0.50, 6.0, 2.4495
54.32500, 0.50, 8.0, 2.8284
54.37500, 0.50, 6.0, 2.4495
54.42500, 0.50, 6.0, 2.4495
54.47500, 0.50, 7.0, 2.6458
54.52500, 0.50, 6.0, 2.4495
54.57500, 0.50, 11.0, 3.3166
54.62500, 0.50, 11.0, 3.3166
54.67500, 0.50, 4.0, 2.0000
54.72500, 0.50, 8.0, 2.8284
54.77500, 0.50, 7.0, 2.6458
54.82500, 0.50, 6.0, 2.4495
54.87500, 0.50, 7.0, 2.6458
54.92500, 0.50, 6.0, 2.4495
54.97500, 0.50, 5.0, 2.2361
55.02500, 0.50, 7.0, 2.6458
55.07500, 0.50, 8.0, 2.8284
55.12500, 0.50, 5.0, 2.2361
55.17500, 0.50, 5.0, 2.2361
55.22500, 0.50, 11.0, 3.3166
55.27500, 0.50, 10.0, 3.1623
55.32500, 0.50, 10.0, 3.1623
55.37500, 0.50, 3.0, 1.7321
55.42500, 0.50, 6.0, 2.4495
55.47500, 0.50, 9.0, 3.0000
55.52500, 0.50, 11.0, 3.3166
55.57500, 0.50, 13.0, 3.6056
55.62500, 0.50, 8.0, 2.8284
55.67500, 0.50, 6.0, 2.4495
55.72500, 0.50, 5.0, 2.2361
55.77500, 0.50, 9.0, 3.0000
55.82500, 0.50, 3.0, 1.7321
55.87500, 0.50, 11.0, 3.3166
55.92500, 0.50, 3.0, 1.7321
55.97500, 0.50, 8.0, 2.8284
56.02500, 0.50, 4.0, 2.0000
56.07500, 0.50, 9.0, 3.0000
56.12500, 0.50, 6.0, 2.4495
56.17500, 0.50, 8.0, 2.8284
56.22500, 0.50, 8.0, 2.8284
56.27500, 0.50, 8.0, 2.8284
56.32500, 0.50, 10.0, 3.1623
56.37500, 0.50, 3.0, 1.7321
56.42500, 0.50, 7.0, 2.6458
56.47500, 0.50, 5.0, 2.2361
56.52500, 0.50, 11.0, 3.3166
56.57500, 0.50, 4.0, 2.0000
56.62500, 0.50, 10.0, 3.1623
56.67500, 0.50, 7.0, 2.6458
56.72500, 0.50, 7.0, 2.6458
56.77500, 0.50, 2.0, 1.4142
56.82500, 0.50, 8.0, 2.8284
56.87500, 0.50, 8.0, 2.8284
56.92500, 0.50, 3.0, 1.7321
56.97500, 0.50, 4.0, 2.0000
57.02500, 0.50, 8.0, 2.8284
57.07500, 0.50, 9.0, 3.0000
57.12500, 0.50, 10.0, 3.1623
57.17500, 0.50, 5.0, 2.2361
57.22500, 0.50, 10.0, 3.1623
57.27500, 0.50, 12.0, 3.4641
57.32500, 0.50, 4.0, 2.0000
57.37500, 0.50, 9.0, 3.0000
57.42500, 0.50, 12.0, 3.4641
57.47500, 0.50, 7.0, 2.6458
57.52500, 0.50, 4.0, 2.0000
57.57500, 0.50, 7.0, 2.6458
57.62500, 0.50, 9.0, 3.0000
57.67500, 0.50, 6.0, 2.4495
57.72500, 0.50, 7.0, 2.6458
57.77500, 0.50, 10.0, 3.1623
57.82500, 0.50, 9.0, 3.0000
57.87500, 0.50, 8.0, 2.8284
57.92500, 0.50, 8.0, 2.8284
57.97500, 0.50, 13.0, 3.6056
58.02500, 0.50, 6.0, 2.4495
58.07500, 0.50, 6.0, 2.4495
58.12500, 0.50, 9.0, 3.0000
58.17500, 0.50, 5.0, 2.2361
58.22500, 0.50, 8.0, 2.8284
58.27500, 0.50, 7.0, 2.6458
58.32500, 0.50, 7.0, 2.6458
58.37500, 0.50, 6.0, 2.4495
58.42500, 0.50, 3.0, 1.7321
58.47500, 0.50, 10.0, 3.1623
58.52500, 0.50, 7.0, 2.6458
58.57500, 0.50, 5.0, 2.2361
58.62500, 0.50, 14.0, 3.7417
58.67500, 0.50, 7.0, 2.6458
58.72500, 0.50, 4.0, 2.0000
58.77500, 0.50, 10.0, 3.1623
58.82500, 0.50, 7.0, 2.6458
58.87500, 0.50, 6.0, 2.4495
58.92500, 0.50, 8.0, 2.8284
58.97500, 0.50, 10.0, 3.1623
59.02500, 0.50, 8.0, 2.8284
59.07500, 0.50, 9.0, 3.0000
59.12500, 0.50, 7.0, 2.6458
59.17500, 0.50, 9.0, 3.0000
59.22500, 0.50, 12.0, 3.4641
59.27500, 0.50, 9.0, 3.0000
59.32500, 0.50, 3.0, 1.7321
59.37500, 0.50, 7.0, 2.6458
59.42500, 0.50, 2.0, 1.4142
59.47500, 0.50, 8.0, 2.8284
59.52500, 0.50, 2.0, 1.4142
59.57500, 0.50, 6.0, 2.4495
59.62500, 0.50, 10.0, 3.1623
59.67500, 0.50, 5.0, 2.2361
59.72500, 0.50, 6.0, 2.4495
59.77500, 0.50, 3.0, 1.7321
59.82500, 0.50, 11.0, 3.3166
59.87500, 0.50, 4.0, 2.0000
59.92500, 0.50, 6.0, 2.4495
59.97500, 0.50, 15.0, 3.8730
60.02500, 0.50, 8.0, 2.8284
60.07500, 0.50, 9.0, 3.0000
60.12500, 0.50, 8.0, 2.8284
60.17500, 0.50, 5.0, 2.2361
60.22500, 0.50, 7.0, 2.6458
60.27500, 0.50, 5.0, 2.2361
60.32500, 0.50, 8.0, 2.8284
60.37500, 0.50, 5.0, 2.2361
60.42500, 0.50, 3.0, 1.7321
60.47500, 0.50, 9.0, 3.0000
60.52500, 0.50, 8.0, 2.8284
60.57500, 0.50, 9.0, 3.0000
60.62500, 0.50, 6.0, 2.4495
60.67500, 0.50, 3.0, 1.7321
60.72500, 0.50, 9.0, 3.0000
60.77500, 0.50, 6.0, 2.4495
60.82500, 0.50, 6.0, 2.4495
60.87500, 0.50, 4.0, 2.0000
60.92500, 0.50, 9.0, 3.0000
60.97500, 0.50, 6.0, 2.4495
61.02500, 0.50, 7.0, 2.6458
61.07500, 0.50, 11.0, 3.3166
61.12500, 0.50, 5.0, 2.2361
61.17500, 0.50, 4.0, 2.0000
61.22500, 0.50, 6.0, 2.4495
61.27500, 0.50, 7.0, 2.6458
61.32500, 0.50, 4.0, 2.0000
61.37500, 0.50, 4.0, 2.0000
61.42500, 0.50, 10.0, 3.1623
61.47500, 0.50, 7.0, 2.6458
61.52500, 0.50, 10.0, 3.1623
61.57500, 0.50, 4.0, 2.0000
61.62500, 0.50, 13.0, 3.6056
61.67500, 0.50, 6.0, 2.4495
61.72500, 0.50, 5.0, 2.2361
61.77500, 0.50, 16.0, 4.0000
61.82500, 0.50, 3.0, 1.7321
61.87500, 0.50, 7.0, 2.6458
61.92500, 0.50, 5.0, 2.2361
61.97500, 0.50, 8.0, 2.8284
62.02500, 0.50, 8.0, 2.8284
62.07500, 0.50, 7.0, 2.6458
62.12500, 0.50, 2.0, 1.4142
62.17500, 0.50, 11.0, 3.3166
62.22500, 0.50, 11.0, 3.3166
62.27500, 0.50, 16.0, 4.0000
62.32500, 0.50, 10.0, 3.1623
62.37500, 0.50, 4.0, 2.0000
62.42500, 0.50, 3.0, 1.7321
62.47500, 0.50, 4.0, 2.0000
62.52500, 0.50, 7.0, 2.6458
62.57500, 0.50, 9.0, 3.0000
62.62500, 0.50, 5.0, 2.2361
62.67500, 0.50, 5.0, 2.2361
62.72500, 0.50, 7.0, 2.6458
62.77500, 0.50, 7.0, 2.6458
62.82500, 0.50, 4.0, 2.0000
62.87500, 0.50, 5.0, 2.2361
62.92500, 0.50, 4.0, 2.0000
62.97500, 0.50, 12.0, 3.4641
63.02500, 0.50, 10.0, 3.1623
63.07500, 0.50, 10.0, 3.1623
63.12500, 0.50, 12.0, 3.4641
63.17500, 0.50, 11.0, 3.3166
63.22500, 0.50, 7.0, 2.6458
63.27500, 0.50, 9.0, 3.0000
63.32500, 0.50, 15.0, 3.8730
63.37500, 0.50, 11.0, 3.3166
63.42500, 0.50, 9.0, 3.0000
63.47500, 0.50, 9.0, 3.0000
63.52500, 0.50, 10.0, 3.1623
63.57500, 0.50, 9.0, 3.0000
63.62500, 0.50, 17.0, 4.1231
63.67500, 0.50, 11.0, 3.3166
63.72500, 0.50, 13.0, 3.6056
63.77500, 0.50, 21.0, 4.5826
63.82500, 0.50, 12.0, 3.4641
63.87500, 0.50, 15.0, 3.8730
63.92500, 0.50, 25.0, 5.0000
63.97500, 0.50, 30.0, 5.4772
64.02500, 0.50, 30.0, 5.4772
64.07500, 0.50, 33.0, 5.7446
64.12500, 0.50, 39.0, 6.2450
64.17500, 0.50, 43.0, 6.5574
64.22500, 0.50, 53.0, 7.2801
64.27500, 0.50, 71.0, 8.4261
64.32500, 0.50, 82.0, 9.0554
64.37500, 0.50, 80.0, 8.9443
64.42500, 0.50, 93.0, 9.6437
64.47500, 0.50, 86.0, 9.2736
64.52500, 0.50, 93.0, 9.6437
64.57500, 0.50, 83.0, 9.1104
64.62500, 0.50, 83.0, 9.1104
64.67500, 0.50, 57.0, 7.5498
64.72500, 0.50, 48.0, 6.9282
64.77500, 0.50, 42.0, 6.4807
64.82500, 0.50, 32.0, 5.6569
64.87500, 0.50, 34.0, 5.8310
64.92500, 0.50, 24.0, 4.8990
64.97500, 0.50, 29.0, 5.3852
65.02500, 0.50, 22.0, 4.6904
65.07500, 0.50, 14.0, 3.7417
65.12500, 0.50, 13.0, 3.6056
65.17500, 0.50, 23.0, 4.7958
65.22500, 0.50, 10.0, 3.1623
65.27500, 0.50, 15.0, 3.8730
65.32500, 0.50, 14.0, 3.7417
65.37500, 0.50, 8.0, 2.8284
65.42500, 0.50, 11.0, 3.3166
65.47500, 0.50, 11.0, 3.3166
65.52500, 0.50, 12.0, 3.4641
65.57500, 0.50, 13.0, 3.6056
65.62500, 0.50, 13.0, 3.6056
65.67500, 0.50, 9.0, 3.0000
65.72500, 0.50, 10.0, 3.1623
65.77500, 0.50, 12.0, 3.4641
65.82500, 0.50, 11.0, 3.3166
65.87500, 0.50, 11.0, 3.3166
65.92500, 0.50, 8.0, 2.8284
65.97500, 0.50, 6.0, 2.4495
66.02500, 0.50, 8.0, 2.8284
66.07500, 0.50, 14.0, 3.7417
66.12500, 0.50, 7.0, 2.6458
66.17500, 0.50, 7.0, 2.6458
66.22500, 0.50, 7.0, 2.6458
66.27500, 0.50, 9.0, 3.0000
66.32500, 0.50, 6.0, 2.4495
66.37500, 0.50, 6.0, 2.4495
66.42500, 0.50, 7.0, 2.6458
66.47500, 0.50, 11.0, 3.3166
66.52500, 0.50, 12.0, 3.4641
66.57500, 0.50, 6.0, 2.4495
66.62500, 0.50, 7.0, 2.6458
66.67500, 0.50, 7.0, 2.6458
66.72500, 0.50, 9.0, 3.0000
66.77500, 0.50, 6.0, 2.4495
66.82500, 0.50, 8.0, 2.8284
66.87500, 0.50, 8.0, 2.8284
66.92500, 0.50, 12.0, 3.4641
66.97500, 0.50, 7.0, 2.6458
67.02500, 0.50, 11.0, 3.3166
67.07500, 0.50, 6.0, 2.4495
67.12500, 0.50, 7.0, 2.6458
67.17500, 0.50, 14.0, 3.7417
67.22500, 0.50, 5.0, 2.2361
67.27500, 0.50, 5.0, 2.2361
67.32500, 0.50, 4.0, 2.0000
67.37500, 0.50, 6.0, 2.4495
67.42500, 0.50, 3.0, 1.7321
67.47500, 0.50, 7.0, 2.6458
67.52500, 0.50, 6.0, 2.4495
67.57500, 0.50, 7.0, 2.6458
67.62500, 0.50, 6.0, 2.4495
67.67500, 0.50, 4.0, 2.0000
67.72500, 0.50, 8.0, 2.8284
67.77500, 0.50, 12.0, 3.4641
67.82500, 0.50, 10.0, 3.1623
67.87500, 0.50, 7.0, 2.6458
67.92500, 0.50, 8.0, 2.8284
67.97500, 0.50, 5.0, 2.2361
68.02500, 0.50, 4.0, 2.0000
68.07500, 0.50, 4.0, 2.0000
68.12500, 0.50, 8.0, 2.8284
68.17500, 0.50, 9.0, 3.0000
68.22500, 0.50, 4.0, 2.0000
68.27500, 0.50, 6.0, 2.4495
68.32500, 0.50, 5.0, 2.2361
68.37500, 0.50, 3.0, 1.7321
68.42500, 0.50, 14.0, 3.7417
68.47500, 0.50, 9.0, 3.0000
68.52500, 0.50, 4.0, 2.0000
68.57500, 0.50, 10.0, 3.1623
68.62500, 0.50, 14.0, 3.7417
68.67500, 0.50, 6.0, 2.4495
68.72500, 0.50, 9.0, 3.0000
68.77500, 0.50, 3.0, 1.7321
68.82500, 0.50, 6.0, 2.4495
68.87500, 0.50, 6.0, 2.4495
68.92500, 0.50, 6.0, 2.4495
68.97500, 0.50, 8.0, 2.8284
69.02500, 0.50, 6.0, 2.4495
69.07500, 0.50, 7.0, 2.6458
69.12500, 0.50, 11.0, 3.3166
69.17500, 0.50, 4.0, 2.0000
69.22500, 0.50, 9.0, 3.0000
69.27500, 0.50, 2.0, 1.4142
69.32500, 0.50, 4.0, 2.0000
69.37500, 0.50, 5.0, 2.2361
69.42500, 0.50, 12.0, 3.4641
69.47500, 0.50, 3.0, 1.7321
69.52500, 0.50, 8.0, 2.8284
69.57500, 0.50, 8.0, 2.8284
69.62500, 0.50, 11.0, 3.3166
69.67500, 0.50, 1.0, 1.0000
69.72500, 0.50, 4.0, 2.0000
69.77500, 0.50, 4.0, 2.0000
69.82500, 0.50, 2.0, 1.4142
69.87500, 0.50, 8.0, 2.8284
69.92500, 0.50, 9.0, 3.0000
69.97500, 0.50, 8.0, 2.8284
70.02500, 0.50, 8.0, 2.8284
70.07500, 0.50, 8.0, 2.8284
70.12500, 0.50, 5.0, 2.2361
70.17500, 0.50, 5.0, 2.2361
70.22500, 0.50, 7.0, 2.6458
70.27500, 0.50, 3.0, 1.7321
70.32500, 0.50, 4.0, 2.0000
70.37500, 0.50, 2.0, 1.4142
70.42500, 0.50, 4.0, 2.0000
70.47500, 0.50, 10.0, 3.1623
70.52500, 0.50, 6.0, 2.4495
70.57500, 0.50, 3.0, 1.7321
70.62500, 0.50, 5.0, 2.2361
70.67500, 0.50, 4.0, 2.0000
70.72500, 0.50, 5.0, 2.2361
70.77500, 0.50, 6.0, 2.4495
70.82500, 0.50, 8.0, 2.8284
70.87500, 0.50, 6.0, 2.4495
70.92500, 0.50, 4.0, 2.0000
70.97500, 0.50, 5.0, 2.2361
71.02500, 0.50, 4.0, 2.0000
71.07500, 0.50, 7.0, 2.6458
71.12500, 0.50, 10.0, 3.1623
71.17500, 0.50, 3.0, 1.7321
71.22500, 0.50, 10.0, 3.1623
71.27500, 0.50, 6.0, 2.4495
71.32500, 0.50, 6.0, 2.4495
71.37500, 0.50, 11.0, 3.3166
71.42500, 0.50, 2.0, 1.4142
71.47500, 0.50, 7.0, 2.6458
71.52500, 0.50, 6.0, 2.4495
71.57500, 0.50, 4.0, 2.0000
71.62500, 0.50, 5.0, 2.2361
71.67500, 0.50, 9.0, 3.0000
71.72500, 0.50, 5.0, 2.2361
71.77500, 0.50, 3.0, 1.7321
71.82500, 0.50, 4.0, 2.0000
71.87500, 0.50, 3.0, 1.7321
71.92500, 0.50, 5.0, 2.2361
71.97500, 0.50, 7.0, 2.6458
72.02500, 0.50, 6.0, 2.4495
72.07500, 0.50, 6.0, 2.4495
72.12500, 0.50, 8.0, 2.8284
72.17500, 0.50, 5.0, 2.2361
72.22500, 0.50, 6.0, 2.4495
72.27500, 0.50, 9.0, 3.0000
72.32500, 0.50, 12.0, 3.4641
72.37500, 0.50, 10.0, 3.1623
72.42500, 0.50, 5.0, 2.2361
72.47500, 0.50, 7.0, 2.6458
72.52500, 0.50, 7.0, 2.6458
72.57500, 0.50, 8.0, 2.8284
72.62500, 0.50, 8.0, 2.8284
72.67500, 0.50, 5.0, 2.2361
72.72500, 0.50, 5.0, 2.2361
72.77500, 0.50, 12.0, 3.4641
72.82500, 0.50, 6.0, 2.4495
72.87500, 0.50, 11.0, 3.3166
72.92500, 0.50, 14.0, 3.7417
72.97500, 0.50, 7.0, 2.6458
73.02500, 0.50, 10.0, 3.1623
73.07500, 0.50, 8.0, 2.8284
73.12500, 0.50, 8.0, 2.8284
73.17500, 0.50, 7.0, 2.6458
73.22500, 0.50, 8.0, 2.8284
73.27500, 0.50, 9.0, 3.0000
73.32500, 0.50, 10.0, 3.1623
73.37500, 0.50, 10.0, 3.1623
73.42500, 0.50, 13.0, 3.6056
73.47500, 0.50, 15.0, 3.8730
73.52500, 0.50, 16.0, 4.0000
73.57500, 0.50, 22.0, 4.6904
73.62500, 0.50, 8.0, 2.8284
73.67500, 0.50, 23.0, 4.7958
73.72500, 0.50, 19.0, 4.3589
73.77500, 0.50, 33.0, 5.7446
73.82500, 0.50, 37.0, 6.0828
73.87500, 0.50, 46.0, 6.7823
73.92500, 0.50, 49.0, 7.0000
73.97500, 0.50, 82.0, 9.0554
74.02500, 0.50, 92.0, 9.5917
74.07500, 0.50, 106.0, 10.2956
74.12500, 0.50, 98.0, 9.8995
74.17500, 0.50, 113.0, 10.6301
74.22500, 0.50, 94.0, 9.6954
74.27500, 0.50, 54.0, 7.3485
74.32500, 0.50, 69.0, 8.3066
74.37500, 0.50, 53.0, 7.2801
74.42500, 0.50, 33.0, 5.7446
74.47500, 0.50, 26.0, 5.0990
74.52500, 0.50, 19.0, 4.3589
74.57500, 0.50, 27.0, 5.1962
74.62500, 0.50, 20.0, 4.4721
74.67500, 0.50, 16.0, 4.0000
74.72500, 0.50, 10.0, 3.1623
74.77500, 0.50, 15.0, 3.8730
74.82500, 0.50, 14.0, 3.7417
74.87500, 0.50, 12.0, 3.4641
74.92500, 0.50, 14.0, 3.7417
74.97500, 0.50, 11.0, 3.3166
75.02500, 0.50, 17.0, 4.1231
75.07500, 0.50, 12.0, 3.4641
75.12500, 0.50, 5.0, 2.2361
75.17500, 0.50, 8.0, 2.8284
75.22500, 0.50, 9.0, 3.0000
75.27500, 0.50, 10.0, 3.1623
75.32500, 0.50, 7.0, 2.6458
75.37500, 0.50, 13.0, 3.6056
75.42500, 0.50, 9.0, 3.0000
75.47500, 0.50, 7.0, 2.6458
75.52500, 0.50, 6.0, 2.4495
75.57500, 0.50, 12.0, 3.4641
75.62500, 0.50, 10.0, 3.1623
75.67500, 0.50, 12.0, 3.4641
75.72500, 0.50, 16.0, 4.0000
75.77500, 0.50, 12.0, 3.4641
75.82500, 0.50, 16.0, 4.0000
75.87500, 0.50, 7.0, 2.6458
75.92500, 0.50, 9.0, 3.0000
75.97500, 0.50, 7.0, 2.6458
76.02500, 0.50, 9.0, 3.0000
76.07500, 0.50, 9.0, 3.0000
76.12500, 0.50, 10.0, 3.1623
76.17500, 0.50, 11.0, 3.3166
76.22500, 0.50, 7.0, 2.6458
76.27500, 0.50, 16.0, 4.0000
76.32500, 0.50, 7.0, 2.6458
76.37500, 0.50, 12.0, 3.4641
76.42500, 0.50, 12.0, 3.4641
76.47500, 0.50, 10.0, 3.1623
76.52500, 0.50, 17.0, 4.1231
76.57500, 0.50, 22.0, 4.6904
76.62500, 0.50, 15.0, 3.8730
76.67500, 0.50, 13.0, 3.6056
76.72500, 0.50, 19.0, 4.3589
76.77500, 0.50, 21.0, 4.5826
76.82500, 0.50, 24.0, 4.8990
76.87500, 0.50, 21.0, 4.5826
76.92500, 0.50, 27.0, 5.1962
76.97500, 0.50, 37.0, 6.0828
77.02500, 0.50, 38.0, 6.1644
77.07500, 0.50, 41.0, 6.4031
77.12500, 0.50, 51.0, 7.1414
77.17500, 0.50, 61.0, 7.8102
77.22500, 0.50, 66.0, 8.1240
77.27500, 0.50, 72.0, 8.4853
77.32500, 0.50, 91.0, 9.5394
77.37500, 0.50, 83.0, 9.1104
77.42500, 0.50, 79.0, 8.8882
77.47500, 0.50, 92.0, 9.5917
77.52500, 0.50, 67.0, 8.1854
77.57500, 0.50, 75.0, 8.6603
77.62500, 0.50, 61.0, 7.8102
77.67500, 0.50, 57.0, 7.5498
77.72500, 0.50, 40.0, 6.3246
77.77500, 0.50, 48.0, 6.9282
77.82500, 0.50, 40.0, 6.3246
77.87500, 0.50, 40.0, 6.3246
77.92500, 0.50, 27.0, 5.1962
77.97500, 0.50, 28.0, 5.2915
78.02500, 0.50, 18.0, 4.2426
78.07500, 0.50, 24.0, 4.8990
78.12500, 0.50, 15.0, 3.8730
78.17500, 0.50, 15.0, 3.8730
78.22500, 0.50, 16.0, 4.0000
78.27500, 0.50, 16.0, 4.0000
78.32500, 0.50, 11.0, 3.3166
78.37500, 0.50, 12.0, 3.4641
78.42500, 0.50, 8.0, 2.8284
78.47500, 0.50, 12.0, 3.4641
78.52500, 0.50, 9.0, 3.0000
78.57500, 0.50, 10.0, 3.1623
78.62500, 0.50, 10.0, 3.1623
78.67500, 0.50, 11.0, 3.3166
78.72500, 0.50, 8.0, 2.8284
78.77500, 0.50, 8.0, 2.8284
78.82500, 0.50, 10.0, 3.1623
78.87500, 0.50, 9.0, 3.0000
78.92500, 0.50, 10.0, 3.1623
78.97500, 0.50, 9.0, 3.0000
79.02500, 0.50, 5.0, 2.2361
79.07500, 0.50, 8.0, 2.8284
79.12500, 0.50, 2.0, 1.4142
79.17500, 0.50, 9.0, 3.0000
79.22500, 0.50, 5.0, 2.2361
79.27500, 0.50, 6.0, 2.4495
79.32500, 0.50, 7.0, 2.6458
79.37500, 0.50, 10.0, 3.1623
79.42500, 0.50, 5.0, 2.2361
79.47500, 0.50, 5.0, 2.2361
79.52500, 0.50, 6.0, 2.4495
79.57500, 0.50, 6.0, 2.4495
79.62500, 0.50, 10.0, 3.1623
79.67500, 0.50, 3.0, 1.7321
79.72500, 0.50, 13.0, 3.6056
79.77500, 0.50, 6.0, 2.4495
79.82500, 0.50, 5.0, 2.2361
79.87500, 0.50, 6.0, 2.4495
79.92500, 0.50, 5.0, 2.2361
79.97500, 0.50, 11.0, 3.3166