File: G04006.csv
[Measurement conditions]
Sample identification,75%Ag-AP
Comment - 1,"Configuration=Programmable xy with programmable z platforms, Owner=User, Creation date=02/07/2021 13:22:25"
Comment - 2,"Goniometer=Theta/Theta; Minimum step size 2Theta:0.0001; Minimum step size Omega:0.0001"
Comment - 3,"Sample stage=Programmable xy-platform with programmable z-adjustment; Minimum step size X:0.01; Minimum step size Y:0.01; Minimum step size Z:0.001"
Comment - 4,"Diffractometer system=EMPYREAN"
Comment - 5,"Measurement program=C:\PANalytical\Data Collector\Programs\Knapp Group (CK)\Songming Liu\20-80°, 0.05° step, 0.5s-step.xrdmp, Created identifier={D6D0720B-9417-4404-86A5-80CEFF14CAE1}, Created by=User, Id=WL:EMPYREANGI:User, Creation date=20/06/2024 10:10:34"
Anode material,Cu
K-Alpha1 wavelength,1.5405980
K-Alpha2 wavelength,1.5444260
Ratio K-Alpha2/K-Alpha1,0.500
Divergence slit,Fixed,0.76mm
Monochromator used,NO
Generator voltage, 40
Tube current, 40
File date and time,15/Jul/2024 13:21
Unit cell,
h k l, 0 0 0
Scan axis,2Theta
Scan range,20.00000,80.00000
Scan step size,0.0500000
No. of points, 1200
Scan type,CONTINUOUS
Omega,1.0000
X,-0.44
Y,2.60
Z,19.974
Time per step,0.50
[Scan points]
Angle, TimePerStep, Intensity, ESD
20.02500, 0.50, 61.0, 7.8102
20.07500, 0.50, 77.0, 8.7750
20.12500, 0.50, 52.0, 7.2111
20.17500, 0.50, 62.0, 7.8740
20.22500, 0.50, 60.0, 7.7460
20.27500, 0.50, 62.0, 7.8740
20.32500, 0.50, 66.0, 8.1240
20.37500, 0.50, 56.0, 7.4833
20.42500, 0.50, 50.0, 7.0711
20.47500, 0.50, 74.0, 8.6023
20.52500, 0.50, 52.0, 7.2111
20.57500, 0.50, 53.0, 7.2801
20.62500, 0.50, 60.0, 7.7460
20.67500, 0.50, 48.0, 6.9282
20.72500, 0.50, 47.0, 6.8557
20.77500, 0.50, 64.0, 8.0000
20.82500, 0.50, 51.0, 7.1414
20.87500, 0.50, 75.0, 8.6603
20.92500, 0.50, 57.0, 7.5498
20.97500, 0.50, 59.0, 7.6811
21.02500, 0.50, 52.0, 7.2111
21.07500, 0.50, 50.0, 7.0711
21.12500, 0.50, 52.0, 7.2111
21.17500, 0.50, 66.0, 8.1240
21.22500, 0.50, 55.0, 7.4162
21.27500, 0.50, 51.0, 7.1414
21.32500, 0.50, 68.0, 8.2462
21.37500, 0.50, 57.0, 7.5498
21.42500, 0.50, 65.0, 8.0623
21.47500, 0.50, 52.0, 7.2111
21.52500, 0.50, 71.0, 8.4261
21.57500, 0.50, 63.0, 7.9373
21.62500, 0.50, 61.0, 7.8102
21.67500, 0.50, 67.0, 8.1854
21.72500, 0.50, 56.0, 7.4833
21.77500, 0.50, 54.0, 7.3485
21.82500, 0.50, 50.0, 7.0711
21.87500, 0.50, 55.0, 7.4162
21.92500, 0.50, 62.0, 7.8740
21.97500, 0.50, 60.0, 7.7460
22.02500, 0.50, 57.0, 7.5498
22.07500, 0.50, 66.0, 8.1240
22.12500, 0.50, 54.0, 7.3485
22.17500, 0.50, 59.0, 7.6811
22.22500, 0.50, 57.0, 7.5498
22.27500, 0.50, 52.0, 7.2111
22.32500, 0.50, 47.0, 6.8557
22.37500, 0.50, 44.0, 6.6332
22.42500, 0.50, 53.0, 7.2801
22.47500, 0.50, 56.0, 7.4833
22.52500, 0.50, 54.0, 7.3485
22.57500, 0.50, 52.0, 7.2111
22.62500, 0.50, 60.0, 7.7460
22.67500, 0.50, 53.0, 7.2801
22.72500, 0.50, 44.0, 6.6332
22.77500, 0.50, 55.0, 7.4162
22.82500, 0.50, 41.0, 6.4031
22.87500, 0.50, 64.0, 8.0000
22.92500, 0.50, 54.0, 7.3485
22.97500, 0.50, 49.0, 7.0000
23.02500, 0.50, 42.0, 6.4807
23.07500, 0.50, 47.0, 6.8557
23.12500, 0.50, 47.0, 6.8557
23.17500, 0.50, 43.0, 6.5574
23.22500, 0.50, 58.0, 7.6158
23.27500, 0.50, 51.0, 7.1414
23.32500, 0.50, 48.0, 6.9282
23.37500, 0.50, 52.0, 7.2111
23.42500, 0.50, 39.0, 6.2450
23.47500, 0.50, 43.0, 6.5574
23.52500, 0.50, 50.0, 7.0711
23.57500, 0.50, 45.0, 6.7082
23.62500, 0.50, 43.0, 6.5574
23.67500, 0.50, 57.0, 7.5498
23.72500, 0.50, 50.0, 7.0711
23.77500, 0.50, 36.0, 6.0000
23.82500, 0.50, 37.0, 6.0828
23.87500, 0.50, 51.0, 7.1414
23.92500, 0.50, 44.0, 6.6332
23.97500, 0.50, 40.0, 6.3246
24.02500, 0.50, 47.0, 6.8557
24.07500, 0.50, 47.0, 6.8557
24.12500, 0.50, 65.0, 8.0623
24.17500, 0.50, 53.0, 7.2801
24.22500, 0.50, 54.0, 7.3485
24.27500, 0.50, 46.0, 6.7823
24.32500, 0.50, 53.0, 7.2801
24.37500, 0.50, 55.0, 7.4162
24.42500, 0.50, 39.0, 6.2450
24.47500, 0.50, 43.0, 6.5574
24.52500, 0.50, 45.0, 6.7082
24.57500, 0.50, 30.0, 5.4772
24.62500, 0.50, 38.0, 6.1644
24.67500, 0.50, 41.0, 6.4031
24.72500, 0.50, 36.0, 6.0000
24.77500, 0.50, 46.0, 6.7823
24.82500, 0.50, 33.0, 5.7446
24.87500, 0.50, 40.0, 6.3246
24.92500, 0.50, 45.0, 6.7082
24.97500, 0.50, 57.0, 7.5498
25.02500, 0.50, 48.0, 6.9282
25.07500, 0.50, 43.0, 6.5574
25.12500, 0.50, 34.0, 5.8310
25.17500, 0.50, 52.0, 7.2111
25.22500, 0.50, 45.0, 6.7082
25.27500, 0.50, 32.0, 5.6569
25.32500, 0.50, 42.0, 6.4807
25.37500, 0.50, 26.0, 5.0990
25.42500, 0.50, 44.0, 6.6332
25.47500, 0.50, 43.0, 6.5574
25.52500, 0.50, 40.0, 6.3246
25.57500, 0.50, 36.0, 6.0000
25.62500, 0.50, 45.0, 6.7082
25.67500, 0.50, 49.0, 7.0000
25.72500, 0.50, 44.0, 6.6332
25.77500, 0.50, 38.0, 6.1644
25.82500, 0.50, 37.0, 6.0828
25.87500, 0.50, 53.0, 7.2801
25.92500, 0.50, 42.0, 6.4807
25.97500, 0.50, 52.0, 7.2111
26.02500, 0.50, 45.0, 6.7082
26.07500, 0.50, 34.0, 5.8310
26.12500, 0.50, 35.0, 5.9161
26.17500, 0.50, 32.0, 5.6569
26.22500, 0.50, 48.0, 6.9282
26.27500, 0.50, 42.0, 6.4807
26.32500, 0.50, 45.0, 6.7082
26.37500, 0.50, 34.0, 5.8310
26.42500, 0.50, 35.0, 5.9161
26.47500, 0.50, 35.0, 5.9161
26.52500, 0.50, 46.0, 6.7823
26.57500, 0.50, 30.0, 5.4772
26.62500, 0.50, 51.0, 7.1414
26.67500, 0.50, 31.0, 5.5678
26.72500, 0.50, 39.0, 6.2450
26.77500, 0.50, 44.0, 6.6332
26.82500, 0.50, 33.0, 5.7446
26.87500, 0.50, 32.0, 5.6569
26.92500, 0.50, 37.0, 6.0828
26.97500, 0.50, 37.0, 6.0828
27.02500, 0.50, 34.0, 5.8310
27.07500, 0.50, 32.0, 5.6569
27.12500, 0.50, 35.0, 5.9161
27.17500, 0.50, 42.0, 6.4807
27.22500, 0.50, 36.0, 6.0000
27.27500, 0.50, 32.0, 5.6569
27.32500, 0.50, 28.0, 5.2915
27.37500, 0.50, 29.0, 5.3852
27.42500, 0.50, 33.0, 5.7446
27.47500, 0.50, 28.0, 5.2915
27.52500, 0.50, 34.0, 5.8310
27.57500, 0.50, 37.0, 6.0828
27.62500, 0.50, 44.0, 6.6332
27.67500, 0.50, 28.0, 5.2915
27.72500, 0.50, 40.0, 6.3246
27.77500, 0.50, 30.0, 5.4772
27.82500, 0.50, 27.0, 5.1962
27.87500, 0.50, 29.0, 5.3852
27.92500, 0.50, 29.0, 5.3852
27.97500, 0.50, 21.0, 4.5826
28.02500, 0.50, 27.0, 5.1962
28.07500, 0.50, 30.0, 5.4772
28.12500, 0.50, 33.0, 5.7446
28.17500, 0.50, 32.0, 5.6569
28.22500, 0.50, 33.0, 5.7446
28.27500, 0.50, 32.0, 5.6569
28.32500, 0.50, 28.0, 5.2915
28.37500, 0.50, 33.0, 5.7446
28.42500, 0.50, 26.0, 5.0990
28.47500, 0.50, 30.0, 5.4772
28.52500, 0.50, 27.0, 5.1962
28.57500, 0.50, 31.0, 5.5678
28.62500, 0.50, 29.0, 5.3852
28.67500, 0.50, 30.0, 5.4772
28.72500, 0.50, 30.0, 5.4772
28.77500, 0.50, 35.0, 5.9161
28.82500, 0.50, 24.0, 4.8990
28.87500, 0.50, 29.0, 5.3852
28.92500, 0.50, 24.0, 4.8990
28.97500, 0.50, 37.0, 6.0828
29.02500, 0.50, 40.0, 6.3246
29.07500, 0.50, 43.0, 6.5574
29.12500, 0.50, 28.0, 5.2915
29.17500, 0.50, 37.0, 6.0828
29.22500, 0.50, 35.0, 5.9161
29.27500, 0.50, 53.0, 7.2801
29.32500, 0.50, 52.0, 7.2111
29.37500, 0.50, 52.0, 7.2111
29.42500, 0.50, 57.0, 7.5498
29.47500, 0.50, 46.0, 6.7823
29.52500, 0.50, 24.0, 4.8990
29.57500, 0.50, 30.0, 5.4772
29.62500, 0.50, 24.0, 4.8990
29.67500, 0.50, 33.0, 5.7446
29.72500, 0.50, 24.0, 4.8990
29.77500, 0.50, 28.0, 5.2915
29.82500, 0.50, 30.0, 5.4772
29.87500, 0.50, 25.0, 5.0000
29.92500, 0.50, 26.0, 5.0990
29.97500, 0.50, 32.0, 5.6569
30.02500, 0.50, 28.0, 5.2915
30.07500, 0.50, 30.0, 5.4772
30.12500, 0.50, 24.0, 4.8990
30.17500, 0.50, 21.0, 4.5826
30.22500, 0.50, 30.0, 5.4772
30.27500, 0.50, 20.0, 4.4721
30.32500, 0.50, 27.0, 5.1962
30.37500, 0.50, 26.0, 5.0990
30.42500, 0.50, 24.0, 4.8990
30.47500, 0.50, 35.0, 5.9161
30.52500, 0.50, 22.0, 4.6904
30.57500, 0.50, 25.0, 5.0000
30.62500, 0.50, 24.0, 4.8990
30.67500, 0.50, 29.0, 5.3852
30.72500, 0.50, 24.0, 4.8990
30.77500, 0.50, 22.0, 4.6904
30.82500, 0.50, 24.0, 4.8990
30.87500, 0.50, 24.0, 4.8990
30.92500, 0.50, 27.0, 5.1962
30.97500, 0.50, 15.0, 3.8730
31.02500, 0.50, 25.0, 5.0000
31.07500, 0.50, 27.0, 5.1962
31.12500, 0.50, 24.0, 4.8990
31.17500, 0.50, 28.0, 5.2915
31.22500, 0.50, 32.0, 5.6569
31.27500, 0.50, 24.0, 4.8990
31.32500, 0.50, 33.0, 5.7446
31.37500, 0.50, 19.0, 4.3589
31.42500, 0.50, 27.0, 5.1962
31.47500, 0.50, 19.0, 4.3589
31.52500, 0.50, 25.0, 5.0000
31.57500, 0.50, 28.0, 5.2915
31.62500, 0.50, 24.0, 4.8990
31.67500, 0.50, 26.0, 5.0990
31.72500, 0.50, 27.0, 5.1962
31.77500, 0.50, 34.0, 5.8310
31.82500, 0.50, 20.0, 4.4721
31.87500, 0.50, 23.0, 4.7958
31.92500, 0.50, 29.0, 5.3852
31.97500, 0.50, 24.0, 4.8990
32.02500, 0.50, 34.0, 5.8310
32.07500, 0.50, 26.0, 5.0990
32.12500, 0.50, 27.0, 5.1962
32.17500, 0.50, 20.0, 4.4721
32.22500, 0.50, 22.0, 4.6904
32.27500, 0.50, 19.0, 4.3589
32.32500, 0.50, 20.0, 4.4721
32.37500, 0.50, 17.0, 4.1231
32.42500, 0.50, 17.0, 4.1231
32.47500, 0.50, 28.0, 5.2915
32.52500, 0.50, 33.0, 5.7446
32.57500, 0.50, 14.0, 3.7417
32.62500, 0.50, 25.0, 5.0000
32.67500, 0.50, 24.0, 4.8990
32.72500, 0.50, 20.0, 4.4721
32.77500, 0.50, 30.0, 5.4772
32.82500, 0.50, 22.0, 4.6904
32.87500, 0.50, 32.0, 5.6569
32.92500, 0.50, 23.0, 4.7958
32.97500, 0.50, 22.0, 4.6904
33.02500, 0.50, 20.0, 4.4721
33.07500, 0.50, 12.0, 3.4641
33.12500, 0.50, 20.0, 4.4721
33.17500, 0.50, 27.0, 5.1962
33.22500, 0.50, 19.0, 4.3589
33.27500, 0.50, 22.0, 4.6904
33.32500, 0.50, 26.0, 5.0990
33.37500, 0.50, 26.0, 5.0990
33.42500, 0.50, 18.0, 4.2426
33.47500, 0.50, 24.0, 4.8990
33.52500, 0.50, 25.0, 5.0000
33.57500, 0.50, 14.0, 3.7417
33.62500, 0.50, 23.0, 4.7958
33.67500, 0.50, 26.0, 5.0990
33.72500, 0.50, 20.0, 4.4721
33.77500, 0.50, 24.0, 4.8990
33.82500, 0.50, 30.0, 5.4772
33.87500, 0.50, 22.0, 4.6904
33.92500, 0.50, 19.0, 4.3589
33.97500, 0.50, 18.0, 4.2426
34.02500, 0.50, 24.0, 4.8990
34.07500, 0.50, 23.0, 4.7958
34.12500, 0.50, 22.0, 4.6904
34.17500, 0.50, 33.0, 5.7446
34.22500, 0.50, 28.0, 5.2915
34.27500, 0.50, 33.0, 5.7446
34.32500, 0.50, 30.0, 5.4772
34.37500, 0.50, 23.0, 4.7958
34.42500, 0.50, 24.0, 4.8990
34.47500, 0.50, 18.0, 4.2426
34.52500, 0.50, 17.0, 4.1231
34.57500, 0.50, 33.0, 5.7446
34.62500, 0.50, 19.0, 4.3589
34.67500, 0.50, 24.0, 4.8990
34.72500, 0.50, 17.0, 4.1231
34.77500, 0.50, 18.0, 4.2426
34.82500, 0.50, 11.0, 3.3166
34.87500, 0.50, 13.0, 3.6056
34.92500, 0.50, 18.0, 4.2426
34.97500, 0.50, 25.0, 5.0000
35.02500, 0.50, 26.0, 5.0990
35.07500, 0.50, 24.0, 4.8990
35.12500, 0.50, 17.0, 4.1231
35.17500, 0.50, 22.0, 4.6904
35.22500, 0.50, 20.0, 4.4721
35.27500, 0.50, 13.0, 3.6056
35.32500, 0.50, 29.0, 5.3852
35.37500, 0.50, 18.0, 4.2426
35.42500, 0.50, 21.0, 4.5826
35.47500, 0.50, 22.0, 4.6904
35.52500, 0.50, 19.0, 4.3589
35.57500, 0.50, 25.0, 5.0000
35.62500, 0.50, 19.0, 4.3589
35.67500, 0.50, 18.0, 4.2426
35.72500, 0.50, 22.0, 4.6904
35.77500, 0.50, 21.0, 4.5826
35.82500, 0.50, 25.0, 5.0000
35.87500, 0.50, 22.0, 4.6904
35.92500, 0.50, 27.0, 5.1962
35.97500, 0.50, 31.0, 5.5678
36.02500, 0.50, 25.0, 5.0000
36.07500, 0.50, 25.0, 5.0000
36.12500, 0.50, 25.0, 5.0000
36.17500, 0.50, 19.0, 4.3589
36.22500, 0.50, 33.0, 5.7446
36.27500, 0.50, 26.0, 5.0990
36.32500, 0.50, 28.0, 5.2915
36.37500, 0.50, 33.0, 5.7446
36.42500, 0.50, 30.0, 5.4772
36.47500, 0.50, 35.0, 5.9161
36.52500, 0.50, 33.0, 5.7446
36.57500, 0.50, 27.0, 5.1962
36.62500, 0.50, 24.0, 4.8990
36.67500, 0.50, 28.0, 5.2915
36.72500, 0.50, 20.0, 4.4721
36.77500, 0.50, 24.0, 4.8990
36.82500, 0.50, 28.0, 5.2915
36.87500, 0.50, 33.0, 5.7446
36.92500, 0.50, 38.0, 6.1644
36.97500, 0.50, 38.0, 6.1644
37.02500, 0.50, 31.0, 5.5678
37.07500, 0.50, 29.0, 5.3852
37.12500, 0.50, 27.0, 5.1962
37.17500, 0.50, 35.0, 5.9161
37.22500, 0.50, 44.0, 6.6332
37.27500, 0.50, 37.0, 6.0828
37.32500, 0.50, 33.0, 5.7446
37.37500, 0.50, 48.0, 6.9282
37.42500, 0.50, 34.0, 5.8310
37.47500, 0.50, 46.0, 6.7823
37.52500, 0.50, 51.0, 7.1414
37.57500, 0.50, 53.0, 7.2801
37.62500, 0.50, 73.0, 8.5440
37.67500, 0.50, 96.0, 9.7980
37.72500, 0.50, 125.0, 11.1803
37.77500, 0.50, 160.0, 12.6491
37.82500, 0.50, 309.0, 17.5784
37.87500, 0.50, 449.0, 21.1896
37.92500, 0.50, 789.0, 28.0891
37.97500, 0.50, 1312.0, 36.2215
38.02500, 0.50, 2028.0, 45.0333
38.07500, 0.50, 2526.0, 50.2593
38.12500, 0.50, 2368.0, 48.6621
38.17500, 0.50, 1739.0, 41.7013
38.22500, 0.50, 1040.0, 32.2490
38.27500, 0.50, 582.0, 24.1247
38.32500, 0.50, 276.0, 16.6132
38.37500, 0.50, 150.0, 12.2474
38.42500, 0.50, 104.0, 10.1980
38.47500, 0.50, 73.0, 8.5440
38.52500, 0.50, 67.0, 8.1854
38.57500, 0.50, 66.0, 8.1240
38.62500, 0.50, 55.0, 7.4162
38.67500, 0.50, 55.0, 7.4162
38.72500, 0.50, 47.0, 6.8557
38.77500, 0.50, 41.0, 6.4031
38.82500, 0.50, 37.0, 6.0828
38.87500, 0.50, 39.0, 6.2450
38.92500, 0.50, 36.0, 6.0000
38.97500, 0.50, 34.0, 5.8310
39.02500, 0.50, 32.0, 5.6569
39.07500, 0.50, 29.0, 5.3852
39.12500, 0.50, 20.0, 4.4721
39.17500, 0.50, 33.0, 5.7446
39.22500, 0.50, 23.0, 4.7958
39.27500, 0.50, 30.0, 5.4772
39.32500, 0.50, 19.0, 4.3589
39.37500, 0.50, 28.0, 5.2915
39.42500, 0.50, 24.0, 4.8990
39.47500, 0.50, 22.0, 4.6904
39.52500, 0.50, 30.0, 5.4772
39.57500, 0.50, 24.0, 4.8990
39.62500, 0.50, 29.0, 5.3852
39.67500, 0.50, 29.0, 5.3852
39.72500, 0.50, 20.0, 4.4721
39.77500, 0.50, 31.0, 5.5678
39.82500, 0.50, 24.0, 4.8990
39.87500, 0.50, 21.0, 4.5826
39.92500, 0.50, 21.0, 4.5826
39.97500, 0.50, 27.0, 5.1962
40.02500, 0.50, 24.0, 4.8990
40.07500, 0.50, 21.0, 4.5826
40.12500, 0.50, 20.0, 4.4721
40.17500, 0.50, 27.0, 5.1962
40.22500, 0.50, 22.0, 4.6904
40.27500, 0.50, 27.0, 5.1962
40.32500, 0.50, 23.0, 4.7958
40.37500, 0.50, 22.0, 4.6904
40.42500, 0.50, 21.0, 4.5826
40.47500, 0.50, 19.0, 4.3589
40.52500, 0.50, 21.0, 4.5826
40.57500, 0.50, 19.0, 4.3589
40.62500, 0.50, 22.0, 4.6904
40.67500, 0.50, 17.0, 4.1231
40.72500, 0.50, 18.0, 4.2426
40.77500, 0.50, 14.0, 3.7417
40.82500, 0.50, 12.0, 3.4641
40.87500, 0.50, 18.0, 4.2426
40.92500, 0.50, 12.0, 3.4641
40.97500, 0.50, 19.0, 4.3589
41.02500, 0.50, 19.0, 4.3589
41.07500, 0.50, 20.0, 4.4721
41.12500, 0.50, 23.0, 4.7958
41.17500, 0.50, 18.0, 4.2426
41.22500, 0.50, 21.0, 4.5826
41.27500, 0.50, 13.0, 3.6056
41.32500, 0.50, 22.0, 4.6904
41.37500, 0.50, 23.0, 4.7958
41.42500, 0.50, 20.0, 4.4721
41.47500, 0.50, 17.0, 4.1231
41.52500, 0.50, 17.0, 4.1231
41.57500, 0.50, 16.0, 4.0000
41.62500, 0.50, 23.0, 4.7958
41.67500, 0.50, 28.0, 5.2915
41.72500, 0.50, 21.0, 4.5826
41.77500, 0.50, 22.0, 4.6904
41.82500, 0.50, 22.0, 4.6904
41.87500, 0.50, 21.0, 4.5826
41.92500, 0.50, 29.0, 5.3852
41.97500, 0.50, 24.0, 4.8990
42.02500, 0.50, 11.0, 3.3166
42.07500, 0.50, 28.0, 5.2915
42.12500, 0.50, 23.0, 4.7958
42.17500, 0.50, 24.0, 4.8990
42.22500, 0.50, 17.0, 4.1231
42.27500, 0.50, 31.0, 5.5678
42.32500, 0.50, 25.0, 5.0000
42.37500, 0.50, 17.0, 4.1231
42.42500, 0.50, 25.0, 5.0000
42.47500, 0.50, 30.0, 5.4772
42.52500, 0.50, 21.0, 4.5826
42.57500, 0.50, 26.0, 5.0990
42.62500, 0.50, 21.0, 4.5826
42.67500, 0.50, 28.0, 5.2915
42.72500, 0.50, 27.0, 5.1962
42.77500, 0.50, 25.0, 5.0000
42.82500, 0.50, 22.0, 4.6904
42.87500, 0.50, 31.0, 5.5678
42.92500, 0.50, 25.0, 5.0000
42.97500, 0.50, 34.0, 5.8310
43.02500, 0.50, 52.0, 7.2111
43.07500, 0.50, 55.0, 7.4162
43.12500, 0.50, 66.0, 8.1240
43.17500, 0.50, 97.0, 9.8489
43.22500, 0.50, 117.0, 10.8167
43.27500, 0.50, 117.0, 10.8167
43.32500, 0.50, 118.0, 10.8628
43.37500, 0.50, 127.0, 11.2694
43.42500, 0.50, 75.0, 8.6603
43.47500, 0.50, 57.0, 7.5498
43.52500, 0.50, 46.0, 6.7823
43.57500, 0.50, 54.0, 7.3485
43.62500, 0.50, 45.0, 6.7082
43.67500, 0.50, 62.0, 7.8740
43.72500, 0.50, 39.0, 6.2450
43.77500, 0.50, 60.0, 7.7460
43.82500, 0.50, 62.0, 7.8740
43.87500, 0.50, 72.0, 8.4853
43.92500, 0.50, 106.0, 10.2956
43.97500, 0.50, 151.0, 12.2882
44.02500, 0.50, 218.0, 14.7648
44.07500, 0.50, 289.0, 17.0000
44.12500, 0.50, 503.0, 22.4277
44.17500, 0.50, 649.0, 25.4755
44.22500, 0.50, 881.0, 29.6816
44.27500, 0.50, 1017.0, 31.8904
44.32500, 0.50, 941.0, 30.6757
44.37500, 0.50, 712.0, 26.6833
44.42500, 0.50, 477.0, 21.8403
44.47500, 0.50, 362.0, 19.0263
44.52500, 0.50, 205.0, 14.3178
44.57500, 0.50, 120.0, 10.9545
44.62500, 0.50, 86.0, 9.2736
44.67500, 0.50, 62.0, 7.8740
44.72500, 0.50, 49.0, 7.0000
44.77500, 0.50, 44.0, 6.6332
44.82500, 0.50, 42.0, 6.4807
44.87500, 0.50, 34.0, 5.8310
44.92500, 0.50, 23.0, 4.7958
44.97500, 0.50, 30.0, 5.4772
45.02500, 0.50, 21.0, 4.5826
45.07500, 0.50, 18.0, 4.2426
45.12500, 0.50, 21.0, 4.5826
45.17500, 0.50, 17.0, 4.1231
45.22500, 0.50, 31.0, 5.5678
45.27500, 0.50, 18.0, 4.2426
45.32500, 0.50, 20.0, 4.4721
45.37500, 0.50, 15.0, 3.8730
45.42500, 0.50, 11.0, 3.3166
45.47500, 0.50, 20.0, 4.4721
45.52500, 0.50, 18.0, 4.2426
45.57500, 0.50, 17.0, 4.1231
45.62500, 0.50, 14.0, 3.7417
45.67500, 0.50, 10.0, 3.1623
45.72500, 0.50, 14.0, 3.7417
45.77500, 0.50, 17.0, 4.1231
45.82500, 0.50, 14.0, 3.7417
45.87500, 0.50, 22.0, 4.6904
45.92500, 0.50, 16.0, 4.0000
45.97500, 0.50, 19.0, 4.3589
46.02500, 0.50, 18.0, 4.2426
46.07500, 0.50, 20.0, 4.4721
46.12500, 0.50, 12.0, 3.4641
46.17500, 0.50, 25.0, 5.0000
46.22500, 0.50, 13.0, 3.6056
46.27500, 0.50, 16.0, 4.0000
46.32500, 0.50, 10.0, 3.1623
46.37500, 0.50, 14.0, 3.7417
46.42500, 0.50, 18.0, 4.2426
46.47500, 0.50, 12.0, 3.4641
46.52500, 0.50, 17.0, 4.1231
46.57500, 0.50, 12.0, 3.4641
46.62500, 0.50, 16.0, 4.0000
46.67500, 0.50, 14.0, 3.7417
46.72500, 0.50, 14.0, 3.7417
46.77500, 0.50, 13.0, 3.6056
46.82500, 0.50, 14.0, 3.7417
46.87500, 0.50, 9.0, 3.0000
46.92500, 0.50, 15.0, 3.8730
46.97500, 0.50, 8.0, 2.8284
47.02500, 0.50, 9.0, 3.0000
47.07500, 0.50, 11.0, 3.3166
47.12500, 0.50, 15.0, 3.8730
47.17500, 0.50, 12.0, 3.4641
47.22500, 0.50, 12.0, 3.4641
47.27500, 0.50, 11.0, 3.3166
47.32500, 0.50, 6.0, 2.4495
47.37500, 0.50, 9.0, 3.0000
47.42500, 0.50, 7.0, 2.6458
47.47500, 0.50, 10.0, 3.1623
47.52500, 0.50, 9.0, 3.0000
47.57500, 0.50, 12.0, 3.4641
47.62500, 0.50, 16.0, 4.0000
47.67500, 0.50, 10.0, 3.1623
47.72500, 0.50, 10.0, 3.1623
47.77500, 0.50, 13.0, 3.6056
47.82500, 0.50, 10.0, 3.1623
47.87500, 0.50, 11.0, 3.3166
47.92500, 0.50, 7.0, 2.6458
47.97500, 0.50, 8.0, 2.8284
48.02500, 0.50, 14.0, 3.7417
48.07500, 0.50, 12.0, 3.4641
48.12500, 0.50, 12.0, 3.4641
48.17500, 0.50, 10.0, 3.1623
48.22500, 0.50, 7.0, 2.6458
48.27500, 0.50, 7.0, 2.6458
48.32500, 0.50, 11.0, 3.3166
48.37500, 0.50, 16.0, 4.0000
48.42500, 0.50, 13.0, 3.6056
48.47500, 0.50, 10.0, 3.1623
48.52500, 0.50, 14.0, 3.7417
48.57500, 0.50, 6.0, 2.4495
48.62500, 0.50, 9.0, 3.0000
48.67500, 0.50, 14.0, 3.7417
48.72500, 0.50, 7.0, 2.6458
48.77500, 0.50, 15.0, 3.8730
48.82500, 0.50, 7.0, 2.6458
48.87500, 0.50, 11.0, 3.3166
48.92500, 0.50, 6.0, 2.4495
48.97500, 0.50, 15.0, 3.8730
49.02500, 0.50, 7.0, 2.6458
49.07500, 0.50, 7.0, 2.6458
49.12500, 0.50, 6.0, 2.4495
49.17500, 0.50, 13.0, 3.6056
49.22500, 0.50, 12.0, 3.4641
49.27500, 0.50, 12.0, 3.4641
49.32500, 0.50, 12.0, 3.4641
49.37500, 0.50, 12.0, 3.4641
49.42500, 0.50, 9.0, 3.0000
49.47500, 0.50, 16.0, 4.0000
49.52500, 0.50, 11.0, 3.3166
49.57500, 0.50, 13.0, 3.6056
49.62500, 0.50, 17.0, 4.1231
49.67500, 0.50, 8.0, 2.8284
49.72500, 0.50, 11.0, 3.3166
49.77500, 0.50, 6.0, 2.4495
49.82500, 0.50, 4.0, 2.0000
49.87500, 0.50, 9.0, 3.0000
49.92500, 0.50, 7.0, 2.6458
49.97500, 0.50, 14.0, 3.7417
50.02500, 0.50, 14.0, 3.7417
50.07500, 0.50, 17.0, 4.1231
50.12500, 0.50, 15.0, 3.8730
50.17500, 0.50, 19.0, 4.3589
50.22500, 0.50, 19.0, 4.3589
50.27500, 0.50, 33.0, 5.7446
50.32500, 0.50, 30.0, 5.4772
50.37500, 0.50, 39.0, 6.2450
50.42500, 0.50, 41.0, 6.4031
50.47500, 0.50, 29.0, 5.3852
50.52500, 0.50, 28.0, 5.2915
50.57500, 0.50, 31.0, 5.5678
50.62500, 0.50, 24.0, 4.8990
50.67500, 0.50, 17.0, 4.1231
50.72500, 0.50, 22.0, 4.6904
50.77500, 0.50, 17.0, 4.1231
50.82500, 0.50, 10.0, 3.1623
50.87500, 0.50, 16.0, 4.0000
50.92500, 0.50, 13.0, 3.6056
50.97500, 0.50, 19.0, 4.3589
51.02500, 0.50, 8.0, 2.8284
51.07500, 0.50, 9.0, 3.0000
51.12500, 0.50, 12.0, 3.4641
51.17500, 0.50, 14.0, 3.7417
51.22500, 0.50, 6.0, 2.4495
51.27500, 0.50, 6.0, 2.4495
51.32500, 0.50, 12.0, 3.4641
51.37500, 0.50, 6.0, 2.4495
51.42500, 0.50, 7.0, 2.6458
51.47500, 0.50, 10.0, 3.1623
51.52500, 0.50, 9.0, 3.0000
51.57500, 0.50, 8.0, 2.8284
51.62500, 0.50, 6.0, 2.4495
51.67500, 0.50, 11.0, 3.3166
51.72500, 0.50, 6.0, 2.4495
51.77500, 0.50, 12.0, 3.4641
51.82500, 0.50, 10.0, 3.1623
51.87500, 0.50, 4.0, 2.0000
51.92500, 0.50, 4.0, 2.0000
51.97500, 0.50, 12.0, 3.4641
52.02500, 0.50, 10.0, 3.1623
52.07500, 0.50, 7.0, 2.6458
52.12500, 0.50, 8.0, 2.8284
52.17500, 0.50, 7.0, 2.6458
52.22500, 0.50, 8.0, 2.8284
52.27500, 0.50, 7.0, 2.6458
52.32500, 0.50, 5.0, 2.2361
52.37500, 0.50, 7.0, 2.6458
52.42500, 0.50, 5.0, 2.2361
52.47500, 0.50, 5.0, 2.2361
52.52500, 0.50, 7.0, 2.6458
52.57500, 0.50, 9.0, 3.0000
52.62500, 0.50, 8.0, 2.8284
52.67500, 0.50, 6.0, 2.4495
52.72500, 0.50, 7.0, 2.6458
52.77500, 0.50, 9.0, 3.0000
52.82500, 0.50, 8.0, 2.8284
52.87500, 0.50, 15.0, 3.8730
52.92500, 0.50, 10.0, 3.1623
52.97500, 0.50, 12.0, 3.4641
53.02500, 0.50, 4.0, 2.0000
53.07500, 0.50, 5.0, 2.2361
53.12500, 0.50, 6.0, 2.4495
53.17500, 0.50, 7.0, 2.6458
53.22500, 0.50, 5.0, 2.2361
53.27500, 0.50, 6.0, 2.4495
53.32500, 0.50, 11.0, 3.3166
53.37500, 0.50, 9.0, 3.0000
53.42500, 0.50, 9.0, 3.0000
53.47500, 0.50, 6.0, 2.4495
53.52500, 0.50, 6.0, 2.4495
53.57500, 0.50, 11.0, 3.3166
53.62500, 0.50, 3.0, 1.7321
53.67500, 0.50, 8.0, 2.8284
53.72500, 0.50, 4.0, 2.0000
53.77500, 0.50, 11.0, 3.3166
53.82500, 0.50, 9.0, 3.0000
53.87500, 0.50, 8.0, 2.8284
53.92500, 0.50, 6.0, 2.4495
53.97500, 0.50, 10.0, 3.1623
54.02500, 0.50, 8.0, 2.8284
54.07500, 0.50, 8.0, 2.8284
54.12500, 0.50, 9.0, 3.0000
54.17500, 0.50, 7.0, 2.6458
54.22500, 0.50, 6.0, 2.4495
54.27500, 0.50, 10.0, 3.1623
54.32500, 0.50, 13.0, 3.6056
54.37500, 0.50, 6.0, 2.4495
54.42500, 0.50, 7.0, 2.6458
54.47500, 0.50, 8.0, 2.8284
54.52500, 0.50, 15.0, 3.8730
54.57500, 0.50, 4.0, 2.0000
54.62500, 0.50, 8.0, 2.8284
54.67500, 0.50, 8.0, 2.8284
54.72500, 0.50, 6.0, 2.4495
54.77500, 0.50, 9.0, 3.0000
54.82500, 0.50, 9.0, 3.0000
54.87500, 0.50, 4.0, 2.0000
54.92500, 0.50, 12.0, 3.4641
54.97500, 0.50, 6.0, 2.4495
55.02500, 0.50, 4.0, 2.0000
55.07500, 0.50, 8.0, 2.8284
55.12500, 0.50, 3.0, 1.7321
55.17500, 0.50, 11.0, 3.3166
55.22500, 0.50, 7.0, 2.6458
55.27500, 0.50, 9.0, 3.0000
55.32500, 0.50, 9.0, 3.0000
55.37500, 0.50, 8.0, 2.8284
55.42500, 0.50, 6.0, 2.4495
55.47500, 0.50, 7.0, 2.6458
55.52500, 0.50, 7.0, 2.6458
55.57500, 0.50, 11.0, 3.3166
55.62500, 0.50, 7.0, 2.6458
55.67500, 0.50, 7.0, 2.6458
55.72500, 0.50, 4.0, 2.0000
55.77500, 0.50, 13.0, 3.6056
55.82500, 0.50, 3.0, 1.7321
55.87500, 0.50, 7.0, 2.6458
55.92500, 0.50, 3.0, 1.7321
55.97500, 0.50, 11.0, 3.3166
56.02500, 0.50, 6.0, 2.4495
56.07500, 0.50, 4.0, 2.0000
56.12500, 0.50, 8.0, 2.8284
56.17500, 0.50, 7.0, 2.6458
56.22500, 0.50, 7.0, 2.6458
56.27500, 0.50, 5.0, 2.2361
56.32500, 0.50, 12.0, 3.4641
56.37500, 0.50, 10.0, 3.1623
56.42500, 0.50, 7.0, 2.6458
56.47500, 0.50, 11.0, 3.3166
56.52500, 0.50, 7.0, 2.6458
56.57500, 0.50, 8.0, 2.8284
56.62500, 0.50, 16.0, 4.0000
56.67500, 0.50, 7.0, 2.6458
56.72500, 0.50, 7.0, 2.6458
56.77500, 0.50, 10.0, 3.1623
56.82500, 0.50, 5.0, 2.2361
56.87500, 0.50, 7.0, 2.6458
56.92500, 0.50, 6.0, 2.4495
56.97500, 0.50, 9.0, 3.0000
57.02500, 0.50, 11.0, 3.3166
57.07500, 0.50, 10.0, 3.1623
57.12500, 0.50, 8.0, 2.8284
57.17500, 0.50, 5.0, 2.2361
57.22500, 0.50, 15.0, 3.8730
57.27500, 0.50, 10.0, 3.1623
57.32500, 0.50, 7.0, 2.6458
57.37500, 0.50, 12.0, 3.4641
57.42500, 0.50, 10.0, 3.1623
57.47500, 0.50, 9.0, 3.0000
57.52500, 0.50, 15.0, 3.8730
57.57500, 0.50, 8.0, 2.8284
57.62500, 0.50, 9.0, 3.0000
57.67500, 0.50, 7.0, 2.6458
57.72500, 0.50, 11.0, 3.3166
57.77500, 0.50, 5.0, 2.2361
57.82500, 0.50, 13.0, 3.6056
57.87500, 0.50, 5.0, 2.2361
57.92500, 0.50, 4.0, 2.0000
57.97500, 0.50, 7.0, 2.6458
58.02500, 0.50, 9.0, 3.0000
58.07500, 0.50, 3.0, 1.7321
58.12500, 0.50, 6.0, 2.4495
58.17500, 0.50, 4.0, 2.0000
58.22500, 0.50, 17.0, 4.1231
58.27500, 0.50, 11.0, 3.3166
58.32500, 0.50, 11.0, 3.3166
58.37500, 0.50, 4.0, 2.0000
58.42500, 0.50, 5.0, 2.2361
58.47500, 0.50, 11.0, 3.3166
58.52500, 0.50, 8.0, 2.8284
58.57500, 0.50, 8.0, 2.8284
58.62500, 0.50, 3.0, 1.7321
58.67500, 0.50, 9.0, 3.0000
58.72500, 0.50, 5.0, 2.2361
58.77500, 0.50, 3.0, 1.7321
58.82500, 0.50, 9.0, 3.0000
58.87500, 0.50, 10.0, 3.1623
58.92500, 0.50, 6.0, 2.4495
58.97500, 0.50, 7.0, 2.6458
59.02500, 0.50, 7.0, 2.6458
59.07500, 0.50, 10.0, 3.1623
59.12500, 0.50, 12.0, 3.4641
59.17500, 0.50, 6.0, 2.4495
59.22500, 0.50, 6.0, 2.4495
59.27500, 0.50, 7.0, 2.6458
59.32500, 0.50, 8.0, 2.8284
59.37500, 0.50, 6.0, 2.4495
59.42500, 0.50, 6.0, 2.4495
59.47500, 0.50, 6.0, 2.4495
59.52500, 0.50, 4.0, 2.0000
59.57500, 0.50, 7.0, 2.6458
59.62500, 0.50, 7.0, 2.6458
59.67500, 0.50, 14.0, 3.7417
59.72500, 0.50, 12.0, 3.4641
59.77500, 0.50, 10.0, 3.1623
59.82500, 0.50, 10.0, 3.1623
59.87500, 0.50, 8.0, 2.8284
59.92500, 0.50, 5.0, 2.2361
59.97500, 0.50, 7.0, 2.6458
60.02500, 0.50, 5.0, 2.2361
60.07500, 0.50, 9.0, 3.0000
60.12500, 0.50, 8.0, 2.8284
60.17500, 0.50, 9.0, 3.0000
60.22500, 0.50, 4.0, 2.0000
60.27500, 0.50, 6.0, 2.4495
60.32500, 0.50, 10.0, 3.1623
60.37500, 0.50, 5.0, 2.2361
60.42500, 0.50, 7.0, 2.6458
60.47500, 0.50, 9.0, 3.0000
60.52500, 0.50, 7.0, 2.6458
60.57500, 0.50, 8.0, 2.8284
60.62500, 0.50, 12.0, 3.4641
60.67500, 0.50, 6.0, 2.4495
60.72500, 0.50, 8.0, 2.8284
60.77500, 0.50, 11.0, 3.3166
60.82500, 0.50, 15.0, 3.8730
60.87500, 0.50, 7.0, 2.6458
60.92500, 0.50, 7.0, 2.6458
60.97500, 0.50, 13.0, 3.6056
61.02500, 0.50, 8.0, 2.8284
61.07500, 0.50, 11.0, 3.3166
61.12500, 0.50, 5.0, 2.2361
61.17500, 0.50, 9.0, 3.0000
61.22500, 0.50, 13.0, 3.6056
61.27500, 0.50, 10.0, 3.1623
61.32500, 0.50, 11.0, 3.3166
61.37500, 0.50, 10.0, 3.1623
61.42500, 0.50, 8.0, 2.8284
61.47500, 0.50, 8.0, 2.8284
61.52500, 0.50, 9.0, 3.0000
61.57500, 0.50, 11.0, 3.3166
61.62500, 0.50, 8.0, 2.8284
61.67500, 0.50, 5.0, 2.2361
61.72500, 0.50, 6.0, 2.4495
61.77500, 0.50, 2.0, 1.4142
61.82500, 0.50, 9.0, 3.0000
61.87500, 0.50, 6.0, 2.4495
61.92500, 0.50, 6.0, 2.4495
61.97500, 0.50, 6.0, 2.4495
62.02500, 0.50, 9.0, 3.0000
62.07500, 0.50, 8.0, 2.8284
62.12500, 0.50, 11.0, 3.3166
62.17500, 0.50, 9.0, 3.0000
62.22500, 0.50, 12.0, 3.4641
62.27500, 0.50, 11.0, 3.3166
62.32500, 0.50, 6.0, 2.4495
62.37500, 0.50, 10.0, 3.1623
62.42500, 0.50, 12.0, 3.4641
62.47500, 0.50, 13.0, 3.6056
62.52500, 0.50, 15.0, 3.8730
62.57500, 0.50, 7.0, 2.6458
62.62500, 0.50, 6.0, 2.4495
62.67500, 0.50, 15.0, 3.8730
62.72500, 0.50, 12.0, 3.4641
62.77500, 0.50, 13.0, 3.6056
62.82500, 0.50, 10.0, 3.1623
62.87500, 0.50, 14.0, 3.7417
62.92500, 0.50, 12.0, 3.4641
62.97500, 0.50, 20.0, 4.4721
63.02500, 0.50, 6.0, 2.4495
63.07500, 0.50, 15.0, 3.8730
63.12500, 0.50, 7.0, 2.6458
63.17500, 0.50, 13.0, 3.6056
63.22500, 0.50, 9.0, 3.0000
63.27500, 0.50, 9.0, 3.0000
63.32500, 0.50, 11.0, 3.3166
63.37500, 0.50, 15.0, 3.8730
63.42500, 0.50, 9.0, 3.0000
63.47500, 0.50, 13.0, 3.6056
63.52500, 0.50, 6.0, 2.4495
63.57500, 0.50, 7.0, 2.6458
63.62500, 0.50, 16.0, 4.0000
63.67500, 0.50, 15.0, 3.8730
63.72500, 0.50, 17.0, 4.1231
63.77500, 0.50, 17.0, 4.1231
63.82500, 0.50, 21.0, 4.5826
63.87500, 0.50, 21.0, 4.5826
63.92500, 0.50, 28.0, 5.2915
63.97500, 0.50, 31.0, 5.5678
64.02500, 0.50, 37.0, 6.0828
64.07500, 0.50, 54.0, 7.3485
64.12500, 0.50, 66.0, 8.1240
64.17500, 0.50, 92.0, 9.5917
64.22500, 0.50, 148.0, 12.1655
64.27500, 0.50, 240.0, 15.4919
64.32500, 0.50, 363.0, 19.0526
64.37500, 0.50, 530.0, 23.0217
64.42500, 0.50, 543.0, 23.3024
64.47500, 0.50, 494.0, 22.2261
64.52500, 0.50, 439.0, 20.9523
64.57500, 0.50, 368.0, 19.1833
64.62500, 0.50, 336.0, 18.3303
64.67500, 0.50, 212.0, 14.5602
64.72500, 0.50, 130.0, 11.4018
64.77500, 0.50, 81.0, 9.0000
64.82500, 0.50, 54.0, 7.3485
64.87500, 0.50, 39.0, 6.2450
64.92500, 0.50, 39.0, 6.2450
64.97500, 0.50, 29.0, 5.3852
65.02500, 0.50, 27.0, 5.1962
65.07500, 0.50, 20.0, 4.4721
65.12500, 0.50, 23.0, 4.7958
65.17500, 0.50, 9.0, 3.0000
65.22500, 0.50, 19.0, 4.3589
65.27500, 0.50, 18.0, 4.2426
65.32500, 0.50, 9.0, 3.0000
65.37500, 0.50, 17.0, 4.1231
65.42500, 0.50, 13.0, 3.6056
65.47500, 0.50, 10.0, 3.1623
65.52500, 0.50, 8.0, 2.8284
65.57500, 0.50, 12.0, 3.4641
65.62500, 0.50, 15.0, 3.8730
65.67500, 0.50, 17.0, 4.1231
65.72500, 0.50, 10.0, 3.1623
65.77500, 0.50, 11.0, 3.3166
65.82500, 0.50, 16.0, 4.0000
65.87500, 0.50, 12.0, 3.4641
65.92500, 0.50, 11.0, 3.3166
65.97500, 0.50, 14.0, 3.7417
66.02500, 0.50, 9.0, 3.0000
66.07500, 0.50, 12.0, 3.4641
66.12500, 0.50, 13.0, 3.6056
66.17500, 0.50, 5.0, 2.2361
66.22500, 0.50, 10.0, 3.1623
66.27500, 0.50, 8.0, 2.8284
66.32500, 0.50, 11.0, 3.3166
66.37500, 0.50, 10.0, 3.1623
66.42500, 0.50, 9.0, 3.0000
66.47500, 0.50, 9.0, 3.0000
66.52500, 0.50, 12.0, 3.4641
66.57500, 0.50, 10.0, 3.1623
66.62500, 0.50, 8.0, 2.8284
66.67500, 0.50, 8.0, 2.8284
66.72500, 0.50, 14.0, 3.7417
66.77500, 0.50, 3.0, 1.7321
66.82500, 0.50, 9.0, 3.0000
66.87500, 0.50, 10.0, 3.1623
66.92500, 0.50, 4.0, 2.0000
66.97500, 0.50, 8.0, 2.8284
67.02500, 0.50, 12.0, 3.4641
67.07500, 0.50, 8.0, 2.8284
67.12500, 0.50, 4.0, 2.0000
67.17500, 0.50, 17.0, 4.1231
67.22500, 0.50, 10.0, 3.1623
67.27500, 0.50, 8.0, 2.8284
67.32500, 0.50, 11.0, 3.3166
67.37500, 0.50, 7.0, 2.6458
67.42500, 0.50, 10.0, 3.1623
67.47500, 0.50, 6.0, 2.4495
67.52500, 0.50, 7.0, 2.6458
67.57500, 0.50, 8.0, 2.8284
67.62500, 0.50, 9.0, 3.0000
67.67500, 0.50, 15.0, 3.8730
67.72500, 0.50, 10.0, 3.1623
67.77500, 0.50, 2.0, 1.4142
67.82500, 0.50, 6.0, 2.4495
67.87500, 0.50, 13.0, 3.6056
67.92500, 0.50, 8.0, 2.8284
67.97500, 0.50, 11.0, 3.3166
68.02500, 0.50, 9.0, 3.0000
68.07500, 0.50, 9.0, 3.0000
68.12500, 0.50, 5.0, 2.2361
68.17500, 0.50, 5.0, 2.2361
68.22500, 0.50, 7.0, 2.6458
68.27500, 0.50, 5.0, 2.2361
68.32500, 0.50, 6.0, 2.4495
68.37500, 0.50, 16.0, 4.0000
68.42500, 0.50, 3.0, 1.7321
68.47500, 0.50, 9.0, 3.0000
68.52500, 0.50, 4.0, 2.0000
68.57500, 0.50, 9.0, 3.0000
68.62500, 0.50, 10.0, 3.1623
68.67500, 0.50, 17.0, 4.1231
68.72500, 0.50, 11.0, 3.3166
68.77500, 0.50, 11.0, 3.3166
68.82500, 0.50, 9.0, 3.0000
68.87500, 0.50, 12.0, 3.4641
68.92500, 0.50, 7.0, 2.6458
68.97500, 0.50, 7.0, 2.6458
69.02500, 0.50, 8.0, 2.8284
69.07500, 0.50, 6.0, 2.4495
69.12500, 0.50, 11.0, 3.3166
69.17500, 0.50, 9.0, 3.0000
69.22500, 0.50, 6.0, 2.4495
69.27500, 0.50, 7.0, 2.6458
69.32500, 0.50, 7.0, 2.6458
69.37500, 0.50, 10.0, 3.1623
69.42500, 0.50, 10.0, 3.1623
69.47500, 0.50, 5.0, 2.2361
69.52500, 0.50, 12.0, 3.4641
69.57500, 0.50, 8.0, 2.8284
69.62500, 0.50, 9.0, 3.0000
69.67500, 0.50, 9.0, 3.0000
69.72500, 0.50, 6.0, 2.4495
69.77500, 0.50, 13.0, 3.6056
69.82500, 0.50, 4.0, 2.0000
69.87500, 0.50, 8.0, 2.8284
69.92500, 0.50, 6.0, 2.4495
69.97500, 0.50, 11.0, 3.3166
70.02500, 0.50, 8.0, 2.8284
70.07500, 0.50, 9.0, 3.0000
70.12500, 0.50, 8.0, 2.8284
70.17500, 0.50, 8.0, 2.8284
70.22500, 0.50, 8.0, 2.8284
70.27500, 0.50, 4.0, 2.0000
70.32500, 0.50, 9.0, 3.0000
70.37500, 0.50, 7.0, 2.6458
70.42500, 0.50, 6.0, 2.4495
70.47500, 0.50, 13.0, 3.6056
70.52500, 0.50, 6.0, 2.4495
70.57500, 0.50, 8.0, 2.8284
70.62500, 0.50, 5.0, 2.2361
70.67500, 0.50, 4.0, 2.0000
70.72500, 0.50, 7.0, 2.6458
70.77500, 0.50, 11.0, 3.3166
70.82500, 0.50, 7.0, 2.6458
70.87500, 0.50, 10.0, 3.1623
70.92500, 0.50, 7.0, 2.6458
70.97500, 0.50, 8.0, 2.8284
71.02500, 0.50, 11.0, 3.3166
71.07500, 0.50, 10.0, 3.1623
71.12500, 0.50, 16.0, 4.0000
71.17500, 0.50, 6.0, 2.4495
71.22500, 0.50, 10.0, 3.1623
71.27500, 0.50, 12.0, 3.4641
71.32500, 0.50, 9.0, 3.0000
71.37500, 0.50, 7.0, 2.6458
71.42500, 0.50, 10.0, 3.1623
71.47500, 0.50, 5.0, 2.2361
71.52500, 0.50, 9.0, 3.0000
71.57500, 0.50, 14.0, 3.7417
71.62500, 0.50, 12.0, 3.4641
71.67500, 0.50, 10.0, 3.1623
71.72500, 0.50, 9.0, 3.0000
71.77500, 0.50, 11.0, 3.3166
71.82500, 0.50, 9.0, 3.0000
71.87500, 0.50, 12.0, 3.4641
71.92500, 0.50, 8.0, 2.8284
71.97500, 0.50, 7.0, 2.6458
72.02500, 0.50, 10.0, 3.1623
72.07500, 0.50, 9.0, 3.0000
72.12500, 0.50, 7.0, 2.6458
72.17500, 0.50, 9.0, 3.0000
72.22500, 0.50, 9.0, 3.0000
72.27500, 0.50, 8.0, 2.8284
72.32500, 0.50, 4.0, 2.0000
72.37500, 0.50, 8.0, 2.8284
72.42500, 0.50, 10.0, 3.1623
72.47500, 0.50, 10.0, 3.1623
72.52500, 0.50, 10.0, 3.1623
72.57500, 0.50, 12.0, 3.4641
72.62500, 0.50, 6.0, 2.4495
72.67500, 0.50, 10.0, 3.1623
72.72500, 0.50, 9.0, 3.0000
72.77500, 0.50, 11.0, 3.3166
72.82500, 0.50, 10.0, 3.1623
72.87500, 0.50, 7.0, 2.6458
72.92500, 0.50, 6.0, 2.4495
72.97500, 0.50, 11.0, 3.3166
73.02500, 0.50, 7.0, 2.6458
73.07500, 0.50, 11.0, 3.3166
73.12500, 0.50, 4.0, 2.0000
73.17500, 0.50, 8.0, 2.8284
73.22500, 0.50, 8.0, 2.8284
73.27500, 0.50, 5.0, 2.2361
73.32500, 0.50, 9.0, 3.0000
73.37500, 0.50, 12.0, 3.4641
73.42500, 0.50, 8.0, 2.8284
73.47500, 0.50, 7.0, 2.6458
73.52500, 0.50, 11.0, 3.3166
73.57500, 0.50, 16.0, 4.0000
73.62500, 0.50, 16.0, 4.0000
73.67500, 0.50, 13.0, 3.6056
73.72500, 0.50, 20.0, 4.4721
73.77500, 0.50, 16.0, 4.0000
73.82500, 0.50, 12.0, 3.4641
73.87500, 0.50, 8.0, 2.8284
73.92500, 0.50, 14.0, 3.7417
73.97500, 0.50, 16.0, 4.0000
74.02500, 0.50, 29.0, 5.3852
74.07500, 0.50, 16.0, 4.0000
74.12500, 0.50, 23.0, 4.7958
74.17500, 0.50, 27.0, 5.1962
74.22500, 0.50, 15.0, 3.8730
74.27500, 0.50, 25.0, 5.0000
74.32500, 0.50, 20.0, 4.4721
74.37500, 0.50, 10.0, 3.1623
74.42500, 0.50, 10.0, 3.1623
74.47500, 0.50, 14.0, 3.7417
74.52500, 0.50, 8.0, 2.8284
74.57500, 0.50, 9.0, 3.0000
74.62500, 0.50, 17.0, 4.1231
74.67500, 0.50, 11.0, 3.3166
74.72500, 0.50, 13.0, 3.6056
74.77500, 0.50, 11.0, 3.3166
74.82500, 0.50, 10.0, 3.1623
74.87500, 0.50, 15.0, 3.8730
74.92500, 0.50, 11.0, 3.3166
74.97500, 0.50, 8.0, 2.8284
75.02500, 0.50, 8.0, 2.8284
75.07500, 0.50, 11.0, 3.3166
75.12500, 0.50, 13.0, 3.6056
75.17500, 0.50, 8.0, 2.8284
75.22500, 0.50, 8.0, 2.8284
75.27500, 0.50, 15.0, 3.8730
75.32500, 0.50, 9.0, 3.0000
75.37500, 0.50, 13.0, 3.6056
75.42500, 0.50, 7.0, 2.6458
75.47500, 0.50, 14.0, 3.7417
75.52500, 0.50, 9.0, 3.0000
75.57500, 0.50, 23.0, 4.7958
75.62500, 0.50, 9.0, 3.0000
75.67500, 0.50, 12.0, 3.4641
75.72500, 0.50, 7.0, 2.6458
75.77500, 0.50, 8.0, 2.8284
75.82500, 0.50, 9.0, 3.0000
75.87500, 0.50, 12.0, 3.4641
75.92500, 0.50, 12.0, 3.4641
75.97500, 0.50, 12.0, 3.4641
76.02500, 0.50, 16.0, 4.0000
76.07500, 0.50, 10.0, 3.1623
76.12500, 0.50, 9.0, 3.0000
76.17500, 0.50, 9.0, 3.0000
76.22500, 0.50, 19.0, 4.3589
76.27500, 0.50, 15.0, 3.8730
76.32500, 0.50, 11.0, 3.3166
76.37500, 0.50, 15.0, 3.8730
76.42500, 0.50, 15.0, 3.8730
76.47500, 0.50, 18.0, 4.2426
76.52500, 0.50, 22.0, 4.6904
76.57500, 0.50, 22.0, 4.6904
76.62500, 0.50, 17.0, 4.1231
76.67500, 0.50, 27.0, 5.1962
76.72500, 0.50, 15.0, 3.8730
76.77500, 0.50, 29.0, 5.3852
76.82500, 0.50, 33.0, 5.7446
76.87500, 0.50, 29.0, 5.3852
76.92500, 0.50, 29.0, 5.3852
76.97500, 0.50, 39.0, 6.2450
77.02500, 0.50, 67.0, 8.1854
77.07500, 0.50, 104.0, 10.1980
77.12500, 0.50, 120.0, 10.9545
77.17500, 0.50, 168.0, 12.9615
77.22500, 0.50, 263.0, 16.2173
77.27500, 0.50, 363.0, 19.0526
77.32500, 0.50, 502.0, 22.4054
77.37500, 0.50, 533.0, 23.0868
77.42500, 0.50, 542.0, 23.2809
77.47500, 0.50, 416.0, 20.3961
77.52500, 0.50, 380.0, 19.4936
77.57500, 0.50, 342.0, 18.4932
77.62500, 0.50, 339.0, 18.4120
77.67500, 0.50, 216.0, 14.6969
77.72500, 0.50, 162.0, 12.7279
77.77500, 0.50, 88.0, 9.3808
77.82500, 0.50, 71.0, 8.4261
77.87500, 0.50, 52.0, 7.2111
77.92500, 0.50, 34.0, 5.8310
77.97500, 0.50, 43.0, 6.5574
78.02500, 0.50, 35.0, 5.9161
78.07500, 0.50, 29.0, 5.3852
78.12500, 0.50, 20.0, 4.4721
78.17500, 0.50, 23.0, 4.7958
78.22500, 0.50, 18.0, 4.2426
78.27500, 0.50, 20.0, 4.4721
78.32500, 0.50, 15.0, 3.8730
78.37500, 0.50, 13.0, 3.6056
78.42500, 0.50, 22.0, 4.6904
78.47500, 0.50, 20.0, 4.4721
78.52500, 0.50, 11.0, 3.3166
78.57500, 0.50, 11.0, 3.3166
78.62500, 0.50, 18.0, 4.2426
78.67500, 0.50, 12.0, 3.4641
78.72500, 0.50, 12.0, 3.4641
78.77500, 0.50, 9.0, 3.0000
78.82500, 0.50, 11.0, 3.3166
78.87500, 0.50, 16.0, 4.0000
78.92500, 0.50, 19.0, 4.3589
78.97500, 0.50, 20.0, 4.4721
79.02500, 0.50, 15.0, 3.8730
79.07500, 0.50, 10.0, 3.1623
79.12500, 0.50, 9.0, 3.0000
79.17500, 0.50, 21.0, 4.5826
79.22500, 0.50, 9.0, 3.0000
79.27500, 0.50, 9.0, 3.0000
79.32500, 0.50, 11.0, 3.3166
79.37500, 0.50, 13.0, 3.6056
79.42500, 0.50, 16.0, 4.0000
79.47500, 0.50, 9.0, 3.0000
79.52500, 0.50, 5.0, 2.2361
79.57500, 0.50, 10.0, 3.1623
79.62500, 0.50, 10.0, 3.1623
79.67500, 0.50, 10.0, 3.1623
79.72500, 0.50, 11.0, 3.3166
79.77500, 0.50, 12.0, 3.4641
79.82500, 0.50, 6.0, 2.4495
79.87500, 0.50, 14.0, 3.7417
79.92500, 0.50, 12.0, 3.4641
79.97500, 0.50, 11.0, 3.3166