File: G04002.csv
[Measurement conditions]
Sample identification,100%Ag-EA
Comment - 1,"Configuration=Programmable xy with programmable z platforms, Owner=User, Creation date=02/07/2021 13:22:25"
Comment - 2,"Goniometer=Theta/Theta; Minimum step size 2Theta:0.0001; Minimum step size Omega:0.0001"
Comment - 3,"Sample stage=Programmable xy-platform with programmable z-adjustment; Minimum step size X:0.01; Minimum step size Y:0.01; Minimum step size Z:0.001"
Comment - 4,"Diffractometer system=EMPYREAN"
Comment - 5,"Measurement program=C:\PANalytical\Data Collector\Programs\Knapp Group (CK)\Songming Liu\20-80°, 0.05° step, 0.5s-step.xrdmp, Created identifier={D6D0720B-9417-4404-86A5-80CEFF14CAE1}, Created by=User, Id=WL:EMPYREANGI:User, Creation date=20/06/2024 10:10:34"
Anode material,Cu
K-Alpha1 wavelength,1.5405980
K-Alpha2 wavelength,1.5444260
Ratio K-Alpha2/K-Alpha1,0.500
Divergence slit,Fixed,0.76mm
Monochromator used,NO
Generator voltage, 40
Tube current, 40
File date and time,15/Jul/2024 12:26
Unit cell,
h k l, 0 0 0
Scan axis,2Theta
Scan range,20.00000,80.00000
Scan step size,0.0500000
No. of points, 1200
Scan type,CONTINUOUS
Omega,1.0000
X,-2.84
Y,1.54
Z,20.312
Time per step,0.50
[Scan points]
Angle, TimePerStep, Intensity, ESD
20.02500, 0.50, 76.0, 8.7178
20.07500, 0.50, 93.0, 9.6437
20.12500, 0.50, 90.0, 9.4868
20.17500, 0.50, 93.0, 9.6437
20.22500, 0.50, 89.0, 9.4340
20.27500, 0.50, 78.0, 8.8318
20.32500, 0.50, 74.0, 8.6023
20.37500, 0.50, 87.0, 9.3274
20.42500, 0.50, 84.0, 9.1652
20.47500, 0.50, 89.0, 9.4340
20.52500, 0.50, 77.0, 8.7750
20.57500, 0.50, 95.0, 9.7468
20.62500, 0.50, 92.0, 9.5917
20.67500, 0.50, 67.0, 8.1854
20.72500, 0.50, 98.0, 9.8995
20.77500, 0.50, 72.0, 8.4853
20.82500, 0.50, 84.0, 9.1652
20.87500, 0.50, 99.0, 9.9499
20.92500, 0.50, 78.0, 8.8318
20.97500, 0.50, 99.0, 9.9499
21.02500, 0.50, 78.0, 8.8318
21.07500, 0.50, 95.0, 9.7468
21.12500, 0.50, 89.0, 9.4340
21.17500, 0.50, 101.0, 10.0499
21.22500, 0.50, 98.0, 9.8995
21.27500, 0.50, 91.0, 9.5394
21.32500, 0.50, 90.0, 9.4868
21.37500, 0.50, 100.0, 10.0000
21.42500, 0.50, 78.0, 8.8318
21.47500, 0.50, 80.0, 8.9443
21.52500, 0.50, 90.0, 9.4868
21.57500, 0.50, 99.0, 9.9499
21.62500, 0.50, 95.0, 9.7468
21.67500, 0.50, 103.0, 10.1489
21.72500, 0.50, 84.0, 9.1652
21.77500, 0.50, 93.0, 9.6437
21.82500, 0.50, 83.0, 9.1104
21.87500, 0.50, 74.0, 8.6023
21.92500, 0.50, 78.0, 8.8318
21.97500, 0.50, 92.0, 9.5917
22.02500, 0.50, 92.0, 9.5917
22.07500, 0.50, 83.0, 9.1104
22.12500, 0.50, 83.0, 9.1104
22.17500, 0.50, 78.0, 8.8318
22.22500, 0.50, 97.0, 9.8489
22.27500, 0.50, 96.0, 9.7980
22.32500, 0.50, 87.0, 9.3274
22.37500, 0.50, 90.0, 9.4868
22.42500, 0.50, 88.0, 9.3808
22.47500, 0.50, 96.0, 9.7980
22.52500, 0.50, 91.0, 9.5394
22.57500, 0.50, 85.0, 9.2195
22.62500, 0.50, 94.0, 9.6954
22.67500, 0.50, 97.0, 9.8489
22.72500, 0.50, 88.0, 9.3808
22.77500, 0.50, 81.0, 9.0000
22.82500, 0.50, 91.0, 9.5394
22.87500, 0.50, 85.0, 9.2195
22.92500, 0.50, 102.0, 10.0995
22.97500, 0.50, 75.0, 8.6603
23.02500, 0.50, 91.0, 9.5394
23.07500, 0.50, 80.0, 8.9443
23.12500, 0.50, 102.0, 10.0995
23.17500, 0.50, 74.0, 8.6023
23.22500, 0.50, 76.0, 8.7178
23.27500, 0.50, 96.0, 9.7980
23.32500, 0.50, 85.0, 9.2195
23.37500, 0.50, 97.0, 9.8489
23.42500, 0.50, 93.0, 9.6437
23.47500, 0.50, 79.0, 8.8882
23.52500, 0.50, 82.0, 9.0554
23.57500, 0.50, 84.0, 9.1652
23.62500, 0.50, 83.0, 9.1104
23.67500, 0.50, 93.0, 9.6437
23.72500, 0.50, 88.0, 9.3808
23.77500, 0.50, 77.0, 8.7750
23.82500, 0.50, 82.0, 9.0554
23.87500, 0.50, 92.0, 9.5917
23.92500, 0.50, 72.0, 8.4853
23.97500, 0.50, 78.0, 8.8318
24.02500, 0.50, 97.0, 9.8489
24.07500, 0.50, 65.0, 8.0623
24.12500, 0.50, 84.0, 9.1652
24.17500, 0.50, 81.0, 9.0000
24.22500, 0.50, 93.0, 9.6437
24.27500, 0.50, 77.0, 8.7750
24.32500, 0.50, 67.0, 8.1854
24.37500, 0.50, 77.0, 8.7750
24.42500, 0.50, 88.0, 9.3808
24.47500, 0.50, 82.0, 9.0554
24.52500, 0.50, 82.0, 9.0554
24.57500, 0.50, 64.0, 8.0000
24.62500, 0.50, 102.0, 10.0995
24.67500, 0.50, 84.0, 9.1652
24.72500, 0.50, 85.0, 9.2195
24.77500, 0.50, 81.0, 9.0000
24.82500, 0.50, 67.0, 8.1854
24.87500, 0.50, 77.0, 8.7750
24.92500, 0.50, 86.0, 9.2736
24.97500, 0.50, 85.0, 9.2195
25.02500, 0.50, 73.0, 8.5440
25.07500, 0.50, 80.0, 8.9443
25.12500, 0.50, 76.0, 8.7178
25.17500, 0.50, 90.0, 9.4868
25.22500, 0.50, 82.0, 9.0554
25.27500, 0.50, 93.0, 9.6437
25.32500, 0.50, 80.0, 8.9443
25.37500, 0.50, 74.0, 8.6023
25.42500, 0.50, 80.0, 8.9443
25.47500, 0.50, 80.0, 8.9443
25.52500, 0.50, 63.0, 7.9373
25.57500, 0.50, 77.0, 8.7750
25.62500, 0.50, 71.0, 8.4261
25.67500, 0.50, 89.0, 9.4340
25.72500, 0.50, 72.0, 8.4853
25.77500, 0.50, 69.0, 8.3066
25.82500, 0.50, 73.0, 8.5440
25.87500, 0.50, 72.0, 8.4853
25.92500, 0.50, 101.0, 10.0499
25.97500, 0.50, 75.0, 8.6603
26.02500, 0.50, 62.0, 7.8740
26.07500, 0.50, 71.0, 8.4261
26.12500, 0.50, 78.0, 8.8318
26.17500, 0.50, 49.0, 7.0000
26.22500, 0.50, 72.0, 8.4853
26.27500, 0.50, 62.0, 7.8740
26.32500, 0.50, 84.0, 9.1652
26.37500, 0.50, 81.0, 9.0000
26.42500, 0.50, 69.0, 8.3066
26.47500, 0.50, 75.0, 8.6603
26.52500, 0.50, 81.0, 9.0000
26.57500, 0.50, 67.0, 8.1854
26.62500, 0.50, 82.0, 9.0554
26.67500, 0.50, 78.0, 8.8318
26.72500, 0.50, 70.0, 8.3666
26.77500, 0.50, 67.0, 8.1854
26.82500, 0.50, 62.0, 7.8740
26.87500, 0.50, 63.0, 7.9373
26.92500, 0.50, 54.0, 7.3485
26.97500, 0.50, 76.0, 8.7178
27.02500, 0.50, 65.0, 8.0623
27.07500, 0.50, 62.0, 7.8740
27.12500, 0.50, 71.0, 8.4261
27.17500, 0.50, 66.0, 8.1240
27.22500, 0.50, 61.0, 7.8102
27.27500, 0.50, 61.0, 7.8102
27.32500, 0.50, 53.0, 7.2801
27.37500, 0.50, 61.0, 7.8102
27.42500, 0.50, 70.0, 8.3666
27.47500, 0.50, 68.0, 8.2462
27.52500, 0.50, 73.0, 8.5440
27.57500, 0.50, 58.0, 7.6158
27.62500, 0.50, 65.0, 8.0623
27.67500, 0.50, 62.0, 7.8740
27.72500, 0.50, 72.0, 8.4853
27.77500, 0.50, 54.0, 7.3485
27.82500, 0.50, 55.0, 7.4162
27.87500, 0.50, 60.0, 7.7460
27.92500, 0.50, 66.0, 8.1240
27.97500, 0.50, 41.0, 6.4031
28.02500, 0.50, 70.0, 8.3666
28.07500, 0.50, 64.0, 8.0000
28.12500, 0.50, 61.0, 7.8102
28.17500, 0.50, 57.0, 7.5498
28.22500, 0.50, 63.0, 7.9373
28.27500, 0.50, 57.0, 7.5498
28.32500, 0.50, 65.0, 8.0623
28.37500, 0.50, 50.0, 7.0711
28.42500, 0.50, 51.0, 7.1414
28.47500, 0.50, 51.0, 7.1414
28.52500, 0.50, 62.0, 7.8740
28.57500, 0.50, 77.0, 8.7750
28.62500, 0.50, 60.0, 7.7460
28.67500, 0.50, 54.0, 7.3485
28.72500, 0.50, 54.0, 7.3485
28.77500, 0.50, 49.0, 7.0000
28.82500, 0.50, 53.0, 7.2801
28.87500, 0.50, 69.0, 8.3066
28.92500, 0.50, 58.0, 7.6158
28.97500, 0.50, 52.0, 7.2111
29.02500, 0.50, 57.0, 7.5498
29.07500, 0.50, 57.0, 7.5498
29.12500, 0.50, 58.0, 7.6158
29.17500, 0.50, 51.0, 7.1414
29.22500, 0.50, 57.0, 7.5498
29.27500, 0.50, 65.0, 8.0623
29.32500, 0.50, 68.0, 8.2462
29.37500, 0.50, 46.0, 6.7823
29.42500, 0.50, 53.0, 7.2801
29.47500, 0.50, 54.0, 7.3485
29.52500, 0.50, 45.0, 6.7082
29.57500, 0.50, 58.0, 7.6158
29.62500, 0.50, 43.0, 6.5574
29.67500, 0.50, 43.0, 6.5574
29.72500, 0.50, 56.0, 7.4833
29.77500, 0.50, 50.0, 7.0711
29.82500, 0.50, 48.0, 6.9282
29.87500, 0.50, 51.0, 7.1414
29.92500, 0.50, 48.0, 6.9282
29.97500, 0.50, 53.0, 7.2801
30.02500, 0.50, 55.0, 7.4162
30.07500, 0.50, 50.0, 7.0711
30.12500, 0.50, 44.0, 6.6332
30.17500, 0.50, 47.0, 6.8557
30.22500, 0.50, 51.0, 7.1414
30.27500, 0.50, 55.0, 7.4162
30.32500, 0.50, 56.0, 7.4833
30.37500, 0.50, 54.0, 7.3485
30.42500, 0.50, 55.0, 7.4162
30.47500, 0.50, 47.0, 6.8557
30.52500, 0.50, 44.0, 6.6332
30.57500, 0.50, 43.0, 6.5574
30.62500, 0.50, 52.0, 7.2111
30.67500, 0.50, 56.0, 7.4833
30.72500, 0.50, 45.0, 6.7082
30.77500, 0.50, 45.0, 6.7082
30.82500, 0.50, 57.0, 7.5498
30.87500, 0.50, 42.0, 6.4807
30.92500, 0.50, 52.0, 7.2111
30.97500, 0.50, 53.0, 7.2801
31.02500, 0.50, 40.0, 6.3246
31.07500, 0.50, 50.0, 7.0711
31.12500, 0.50, 46.0, 6.7823
31.17500, 0.50, 38.0, 6.1644
31.22500, 0.50, 33.0, 5.7446
31.27500, 0.50, 38.0, 6.1644
31.32500, 0.50, 39.0, 6.2450
31.37500, 0.50, 42.0, 6.4807
31.42500, 0.50, 50.0, 7.0711
31.47500, 0.50, 42.0, 6.4807
31.52500, 0.50, 39.0, 6.2450
31.57500, 0.50, 38.0, 6.1644
31.62500, 0.50, 46.0, 6.7823
31.67500, 0.50, 39.0, 6.2450
31.72500, 0.50, 51.0, 7.1414
31.77500, 0.50, 42.0, 6.4807
31.82500, 0.50, 32.0, 5.6569
31.87500, 0.50, 36.0, 6.0000
31.92500, 0.50, 33.0, 5.7446
31.97500, 0.50, 40.0, 6.3246
32.02500, 0.50, 47.0, 6.8557
32.07500, 0.50, 45.0, 6.7082
32.12500, 0.50, 30.0, 5.4772
32.17500, 0.50, 65.0, 8.0623
32.22500, 0.50, 45.0, 6.7082
32.27500, 0.50, 39.0, 6.2450
32.32500, 0.50, 31.0, 5.5678
32.37500, 0.50, 31.0, 5.5678
32.42500, 0.50, 45.0, 6.7082
32.47500, 0.50, 27.0, 5.1962
32.52500, 0.50, 37.0, 6.0828
32.57500, 0.50, 41.0, 6.4031
32.62500, 0.50, 33.0, 5.7446
32.67500, 0.50, 41.0, 6.4031
32.72500, 0.50, 46.0, 6.7823
32.77500, 0.50, 31.0, 5.5678
32.82500, 0.50, 33.0, 5.7446
32.87500, 0.50, 47.0, 6.8557
32.92500, 0.50, 36.0, 6.0000
32.97500, 0.50, 43.0, 6.5574
33.02500, 0.50, 32.0, 5.6569
33.07500, 0.50, 30.0, 5.4772
33.12500, 0.50, 43.0, 6.5574
33.17500, 0.50, 30.0, 5.4772
33.22500, 0.50, 35.0, 5.9161
33.27500, 0.50, 34.0, 5.8310
33.32500, 0.50, 32.0, 5.6569
33.37500, 0.50, 31.0, 5.5678
33.42500, 0.50, 33.0, 5.7446
33.47500, 0.50, 26.0, 5.0990
33.52500, 0.50, 32.0, 5.6569
33.57500, 0.50, 34.0, 5.8310
33.62500, 0.50, 41.0, 6.4031
33.67500, 0.50, 32.0, 5.6569
33.72500, 0.50, 30.0, 5.4772
33.77500, 0.50, 39.0, 6.2450
33.82500, 0.50, 29.0, 5.3852
33.87500, 0.50, 34.0, 5.8310
33.92500, 0.50, 22.0, 4.6904
33.97500, 0.50, 34.0, 5.8310
34.02500, 0.50, 26.0, 5.0990
34.07500, 0.50, 44.0, 6.6332
34.12500, 0.50, 33.0, 5.7446
34.17500, 0.50, 31.0, 5.5678
34.22500, 0.50, 38.0, 6.1644
34.27500, 0.50, 44.0, 6.6332
34.32500, 0.50, 36.0, 6.0000
34.37500, 0.50, 31.0, 5.5678
34.42500, 0.50, 34.0, 5.8310
34.47500, 0.50, 35.0, 5.9161
34.52500, 0.50, 28.0, 5.2915
34.57500, 0.50, 37.0, 6.0828
34.62500, 0.50, 25.0, 5.0000
34.67500, 0.50, 31.0, 5.5678
34.72500, 0.50, 30.0, 5.4772
34.77500, 0.50, 33.0, 5.7446
34.82500, 0.50, 40.0, 6.3246
34.87500, 0.50, 30.0, 5.4772
34.92500, 0.50, 40.0, 6.3246
34.97500, 0.50, 32.0, 5.6569
35.02500, 0.50, 26.0, 5.0990
35.07500, 0.50, 28.0, 5.2915
35.12500, 0.50, 29.0, 5.3852
35.17500, 0.50, 40.0, 6.3246
35.22500, 0.50, 24.0, 4.8990
35.27500, 0.50, 25.0, 5.0000
35.32500, 0.50, 24.0, 4.8990
35.37500, 0.50, 23.0, 4.7958
35.42500, 0.50, 19.0, 4.3589
35.47500, 0.50, 19.0, 4.3589
35.52500, 0.50, 31.0, 5.5678
35.57500, 0.50, 31.0, 5.5678
35.62500, 0.50, 31.0, 5.5678
35.67500, 0.50, 34.0, 5.8310
35.72500, 0.50, 45.0, 6.7082
35.77500, 0.50, 23.0, 4.7958
35.82500, 0.50, 32.0, 5.6569
35.87500, 0.50, 36.0, 6.0000
35.92500, 0.50, 33.0, 5.7446
35.97500, 0.50, 33.0, 5.7446
36.02500, 0.50, 31.0, 5.5678
36.07500, 0.50, 36.0, 6.0000
36.12500, 0.50, 34.0, 5.8310
36.17500, 0.50, 31.0, 5.5678
36.22500, 0.50, 26.0, 5.0990
36.27500, 0.50, 34.0, 5.8310
36.32500, 0.50, 41.0, 6.4031
36.37500, 0.50, 41.0, 6.4031
36.42500, 0.50, 35.0, 5.9161
36.47500, 0.50, 35.0, 5.9161
36.52500, 0.50, 33.0, 5.7446
36.57500, 0.50, 34.0, 5.8310
36.62500, 0.50, 26.0, 5.0990
36.67500, 0.50, 33.0, 5.7446
36.72500, 0.50, 39.0, 6.2450
36.77500, 0.50, 36.0, 6.0000
36.82500, 0.50, 32.0, 5.6569
36.87500, 0.50, 34.0, 5.8310
36.92500, 0.50, 34.0, 5.8310
36.97500, 0.50, 37.0, 6.0828
37.02500, 0.50, 30.0, 5.4772
37.07500, 0.50, 36.0, 6.0000
37.12500, 0.50, 24.0, 4.8990
37.17500, 0.50, 49.0, 7.0000
37.22500, 0.50, 39.0, 6.2450
37.27500, 0.50, 29.0, 5.3852
37.32500, 0.50, 31.0, 5.5678
37.37500, 0.50, 39.0, 6.2450
37.42500, 0.50, 48.0, 6.9282
37.47500, 0.50, 43.0, 6.5574
37.52500, 0.50, 52.0, 7.2111
37.57500, 0.50, 55.0, 7.4162
37.62500, 0.50, 60.0, 7.7460
37.67500, 0.50, 84.0, 9.1652
37.72500, 0.50, 85.0, 9.2195
37.77500, 0.50, 130.0, 11.4018
37.82500, 0.50, 187.0, 13.6748
37.87500, 0.50, 308.0, 17.5499
37.92500, 0.50, 604.0, 24.5764
37.97500, 0.50, 975.0, 31.2250
38.02500, 0.50, 1559.0, 39.4842
38.07500, 0.50, 2004.0, 44.7661
38.12500, 0.50, 1949.0, 44.1475
38.17500, 0.50, 1493.0, 38.6394
38.22500, 0.50, 1057.0, 32.5115
38.27500, 0.50, 573.0, 23.9374
38.32500, 0.50, 257.0, 16.0312
38.37500, 0.50, 153.0, 12.3693
38.42500, 0.50, 112.0, 10.5830
38.47500, 0.50, 72.0, 8.4853
38.52500, 0.50, 82.0, 9.0554
38.57500, 0.50, 54.0, 7.3485
38.62500, 0.50, 61.0, 7.8102
38.67500, 0.50, 40.0, 6.3246
38.72500, 0.50, 33.0, 5.7446
38.77500, 0.50, 36.0, 6.0000
38.82500, 0.50, 25.0, 5.0000
38.87500, 0.50, 33.0, 5.7446
38.92500, 0.50, 30.0, 5.4772
38.97500, 0.50, 38.0, 6.1644
39.02500, 0.50, 37.0, 6.0828
39.07500, 0.50, 19.0, 4.3589
39.12500, 0.50, 30.0, 5.4772
39.17500, 0.50, 35.0, 5.9161
39.22500, 0.50, 28.0, 5.2915
39.27500, 0.50, 35.0, 5.9161
39.32500, 0.50, 24.0, 4.8990
39.37500, 0.50, 30.0, 5.4772
39.42500, 0.50, 23.0, 4.7958
39.47500, 0.50, 16.0, 4.0000
39.52500, 0.50, 27.0, 5.1962
39.57500, 0.50, 28.0, 5.2915
39.62500, 0.50, 27.0, 5.1962
39.67500, 0.50, 17.0, 4.1231
39.72500, 0.50, 27.0, 5.1962
39.77500, 0.50, 23.0, 4.7958
39.82500, 0.50, 23.0, 4.7958
39.87500, 0.50, 21.0, 4.5826
39.92500, 0.50, 16.0, 4.0000
39.97500, 0.50, 21.0, 4.5826
40.02500, 0.50, 29.0, 5.3852
40.07500, 0.50, 28.0, 5.2915
40.12500, 0.50, 21.0, 4.5826
40.17500, 0.50, 25.0, 5.0000
40.22500, 0.50, 27.0, 5.1962
40.27500, 0.50, 20.0, 4.4721
40.32500, 0.50, 20.0, 4.4721
40.37500, 0.50, 26.0, 5.0990
40.42500, 0.50, 23.0, 4.7958
40.47500, 0.50, 18.0, 4.2426
40.52500, 0.50, 33.0, 5.7446
40.57500, 0.50, 16.0, 4.0000
40.62500, 0.50, 23.0, 4.7958
40.67500, 0.50, 15.0, 3.8730
40.72500, 0.50, 19.0, 4.3589
40.77500, 0.50, 21.0, 4.5826
40.82500, 0.50, 20.0, 4.4721
40.87500, 0.50, 19.0, 4.3589
40.92500, 0.50, 20.0, 4.4721
40.97500, 0.50, 30.0, 5.4772
41.02500, 0.50, 24.0, 4.8990
41.07500, 0.50, 16.0, 4.0000
41.12500, 0.50, 24.0, 4.8990
41.17500, 0.50, 16.0, 4.0000
41.22500, 0.50, 17.0, 4.1231
41.27500, 0.50, 23.0, 4.7958
41.32500, 0.50, 28.0, 5.2915
41.37500, 0.50, 22.0, 4.6904
41.42500, 0.50, 29.0, 5.3852
41.47500, 0.50, 20.0, 4.4721
41.52500, 0.50, 22.0, 4.6904
41.57500, 0.50, 27.0, 5.1962
41.62500, 0.50, 26.0, 5.0990
41.67500, 0.50, 22.0, 4.6904
41.72500, 0.50, 16.0, 4.0000
41.77500, 0.50, 18.0, 4.2426
41.82500, 0.50, 20.0, 4.4721
41.87500, 0.50, 24.0, 4.8990
41.92500, 0.50, 18.0, 4.2426
41.97500, 0.50, 19.0, 4.3589
42.02500, 0.50, 19.0, 4.3589
42.07500, 0.50, 22.0, 4.6904
42.12500, 0.50, 20.0, 4.4721
42.17500, 0.50, 23.0, 4.7958
42.22500, 0.50, 25.0, 5.0000
42.27500, 0.50, 25.0, 5.0000
42.32500, 0.50, 21.0, 4.5826
42.37500, 0.50, 26.0, 5.0990
42.42500, 0.50, 23.0, 4.7958
42.47500, 0.50, 28.0, 5.2915
42.52500, 0.50, 22.0, 4.6904
42.57500, 0.50, 16.0, 4.0000
42.62500, 0.50, 20.0, 4.4721
42.67500, 0.50, 23.0, 4.7958
42.72500, 0.50, 18.0, 4.2426
42.77500, 0.50, 36.0, 6.0000
42.82500, 0.50, 20.0, 4.4721
42.87500, 0.50, 20.0, 4.4721
42.92500, 0.50, 20.0, 4.4721
42.97500, 0.50, 20.0, 4.4721
43.02500, 0.50, 18.0, 4.2426
43.07500, 0.50, 20.0, 4.4721
43.12500, 0.50, 17.0, 4.1231
43.17500, 0.50, 28.0, 5.2915
43.22500, 0.50, 15.0, 3.8730
43.27500, 0.50, 27.0, 5.1962
43.32500, 0.50, 31.0, 5.5678
43.37500, 0.50, 20.0, 4.4721
43.42500, 0.50, 24.0, 4.8990
43.47500, 0.50, 28.0, 5.2915
43.52500, 0.50, 22.0, 4.6904
43.57500, 0.50, 26.0, 5.0990
43.62500, 0.50, 33.0, 5.7446
43.67500, 0.50, 40.0, 6.3246
43.72500, 0.50, 33.0, 5.7446
43.77500, 0.50, 50.0, 7.0711
43.82500, 0.50, 46.0, 6.7823
43.87500, 0.50, 49.0, 7.0000
43.92500, 0.50, 73.0, 8.5440
43.97500, 0.50, 97.0, 9.8489
44.02500, 0.50, 139.0, 11.7898
44.07500, 0.50, 213.0, 14.5945
44.12500, 0.50, 314.0, 17.7200
44.17500, 0.50, 440.0, 20.9762
44.22500, 0.50, 650.0, 25.4951
44.27500, 0.50, 711.0, 26.6646
44.32500, 0.50, 728.0, 26.9815
44.37500, 0.50, 543.0, 23.3024
44.42500, 0.50, 464.0, 21.5407
44.47500, 0.50, 276.0, 16.6132
44.52500, 0.50, 198.0, 14.0712
44.57500, 0.50, 127.0, 11.2694
44.62500, 0.50, 83.0, 9.1104
44.67500, 0.50, 61.0, 7.8102
44.72500, 0.50, 58.0, 7.6158
44.77500, 0.50, 43.0, 6.5574
44.82500, 0.50, 38.0, 6.1644
44.87500, 0.50, 16.0, 4.0000
44.92500, 0.50, 34.0, 5.8310
44.97500, 0.50, 20.0, 4.4721
45.02500, 0.50, 21.0, 4.5826
45.07500, 0.50, 15.0, 3.8730
45.12500, 0.50, 19.0, 4.3589
45.17500, 0.50, 17.0, 4.1231
45.22500, 0.50, 25.0, 5.0000
45.27500, 0.50, 18.0, 4.2426
45.32500, 0.50, 16.0, 4.0000
45.37500, 0.50, 16.0, 4.0000
45.42500, 0.50, 18.0, 4.2426
45.47500, 0.50, 15.0, 3.8730
45.52500, 0.50, 24.0, 4.8990
45.57500, 0.50, 10.0, 3.1623
45.62500, 0.50, 15.0, 3.8730
45.67500, 0.50, 16.0, 4.0000
45.72500, 0.50, 22.0, 4.6904
45.77500, 0.50, 16.0, 4.0000
45.82500, 0.50, 13.0, 3.6056
45.87500, 0.50, 13.0, 3.6056
45.92500, 0.50, 12.0, 3.4641
45.97500, 0.50, 23.0, 4.7958
46.02500, 0.50, 15.0, 3.8730
46.07500, 0.50, 11.0, 3.3166
46.12500, 0.50, 16.0, 4.0000
46.17500, 0.50, 18.0, 4.2426
46.22500, 0.50, 14.0, 3.7417
46.27500, 0.50, 18.0, 4.2426
46.32500, 0.50, 15.0, 3.8730
46.37500, 0.50, 14.0, 3.7417
46.42500, 0.50, 9.0, 3.0000
46.47500, 0.50, 20.0, 4.4721
46.52500, 0.50, 14.0, 3.7417
46.57500, 0.50, 13.0, 3.6056
46.62500, 0.50, 14.0, 3.7417
46.67500, 0.50, 12.0, 3.4641
46.72500, 0.50, 14.0, 3.7417
46.77500, 0.50, 8.0, 2.8284
46.82500, 0.50, 14.0, 3.7417
46.87500, 0.50, 13.0, 3.6056
46.92500, 0.50, 18.0, 4.2426
46.97500, 0.50, 11.0, 3.3166
47.02500, 0.50, 9.0, 3.0000
47.07500, 0.50, 10.0, 3.1623
47.12500, 0.50, 13.0, 3.6056
47.17500, 0.50, 14.0, 3.7417
47.22500, 0.50, 12.0, 3.4641
47.27500, 0.50, 10.0, 3.1623
47.32500, 0.50, 8.0, 2.8284
47.37500, 0.50, 15.0, 3.8730
47.42500, 0.50, 14.0, 3.7417
47.47500, 0.50, 19.0, 4.3589
47.52500, 0.50, 15.0, 3.8730
47.57500, 0.50, 10.0, 3.1623
47.62500, 0.50, 15.0, 3.8730
47.67500, 0.50, 16.0, 4.0000
47.72500, 0.50, 17.0, 4.1231
47.77500, 0.50, 15.0, 3.8730
47.82500, 0.50, 13.0, 3.6056
47.87500, 0.50, 18.0, 4.2426
47.92500, 0.50, 10.0, 3.1623
47.97500, 0.50, 22.0, 4.6904
48.02500, 0.50, 7.0, 2.6458
48.07500, 0.50, 15.0, 3.8730
48.12500, 0.50, 13.0, 3.6056
48.17500, 0.50, 13.0, 3.6056
48.22500, 0.50, 10.0, 3.1623
48.27500, 0.50, 9.0, 3.0000
48.32500, 0.50, 18.0, 4.2426
48.37500, 0.50, 7.0, 2.6458
48.42500, 0.50, 10.0, 3.1623
48.47500, 0.50, 5.0, 2.2361
48.52500, 0.50, 14.0, 3.7417
48.57500, 0.50, 10.0, 3.1623
48.62500, 0.50, 13.0, 3.6056
48.67500, 0.50, 14.0, 3.7417
48.72500, 0.50, 15.0, 3.8730
48.77500, 0.50, 10.0, 3.1623
48.82500, 0.50, 5.0, 2.2361
48.87500, 0.50, 8.0, 2.8284
48.92500, 0.50, 10.0, 3.1623
48.97500, 0.50, 10.0, 3.1623
49.02500, 0.50, 9.0, 3.0000
49.07500, 0.50, 9.0, 3.0000
49.12500, 0.50, 16.0, 4.0000
49.17500, 0.50, 11.0, 3.3166
49.22500, 0.50, 15.0, 3.8730
49.27500, 0.50, 12.0, 3.4641
49.32500, 0.50, 8.0, 2.8284
49.37500, 0.50, 10.0, 3.1623
49.42500, 0.50, 11.0, 3.3166
49.47500, 0.50, 11.0, 3.3166
49.52500, 0.50, 9.0, 3.0000
49.57500, 0.50, 8.0, 2.8284
49.62500, 0.50, 10.0, 3.1623
49.67500, 0.50, 9.0, 3.0000
49.72500, 0.50, 5.0, 2.2361
49.77500, 0.50, 22.0, 4.6904
49.82500, 0.50, 8.0, 2.8284
49.87500, 0.50, 4.0, 2.0000
49.92500, 0.50, 12.0, 3.4641
49.97500, 0.50, 10.0, 3.1623
50.02500, 0.50, 14.0, 3.7417
50.07500, 0.50, 8.0, 2.8284
50.12500, 0.50, 8.0, 2.8284
50.17500, 0.50, 10.0, 3.1623
50.22500, 0.50, 18.0, 4.2426
50.27500, 0.50, 11.0, 3.3166
50.32500, 0.50, 8.0, 2.8284
50.37500, 0.50, 9.0, 3.0000
50.42500, 0.50, 14.0, 3.7417
50.47500, 0.50, 10.0, 3.1623
50.52500, 0.50, 11.0, 3.3166
50.57500, 0.50, 11.0, 3.3166
50.62500, 0.50, 8.0, 2.8284
50.67500, 0.50, 8.0, 2.8284
50.72500, 0.50, 7.0, 2.6458
50.77500, 0.50, 13.0, 3.6056
50.82500, 0.50, 7.0, 2.6458
50.87500, 0.50, 10.0, 3.1623
50.92500, 0.50, 14.0, 3.7417
50.97500, 0.50, 7.0, 2.6458
51.02500, 0.50, 10.0, 3.1623
51.07500, 0.50, 6.0, 2.4495
51.12500, 0.50, 12.0, 3.4641
51.17500, 0.50, 8.0, 2.8284
51.22500, 0.50, 8.0, 2.8284
51.27500, 0.50, 8.0, 2.8284
51.32500, 0.50, 13.0, 3.6056
51.37500, 0.50, 10.0, 3.1623
51.42500, 0.50, 7.0, 2.6458
51.47500, 0.50, 8.0, 2.8284
51.52500, 0.50, 19.0, 4.3589
51.57500, 0.50, 9.0, 3.0000
51.62500, 0.50, 9.0, 3.0000
51.67500, 0.50, 7.0, 2.6458
51.72500, 0.50, 4.0, 2.0000
51.77500, 0.50, 10.0, 3.1623
51.82500, 0.50, 12.0, 3.4641
51.87500, 0.50, 10.0, 3.1623
51.92500, 0.50, 7.0, 2.6458
51.97500, 0.50, 13.0, 3.6056
52.02500, 0.50, 8.0, 2.8284
52.07500, 0.50, 11.0, 3.3166
52.12500, 0.50, 13.0, 3.6056
52.17500, 0.50, 12.0, 3.4641
52.22500, 0.50, 6.0, 2.4495
52.27500, 0.50, 6.0, 2.4495
52.32500, 0.50, 13.0, 3.6056
52.37500, 0.50, 16.0, 4.0000
52.42500, 0.50, 11.0, 3.3166
52.47500, 0.50, 10.0, 3.1623
52.52500, 0.50, 9.0, 3.0000
52.57500, 0.50, 14.0, 3.7417
52.62500, 0.50, 11.0, 3.3166
52.67500, 0.50, 9.0, 3.0000
52.72500, 0.50, 13.0, 3.6056
52.77500, 0.50, 8.0, 2.8284
52.82500, 0.50, 9.0, 3.0000
52.87500, 0.50, 7.0, 2.6458
52.92500, 0.50, 17.0, 4.1231
52.97500, 0.50, 10.0, 3.1623
53.02500, 0.50, 7.0, 2.6458
53.07500, 0.50, 13.0, 3.6056
53.12500, 0.50, 10.0, 3.1623
53.17500, 0.50, 5.0, 2.2361
53.22500, 0.50, 14.0, 3.7417
53.27500, 0.50, 7.0, 2.6458
53.32500, 0.50, 11.0, 3.3166
53.37500, 0.50, 10.0, 3.1623
53.42500, 0.50, 13.0, 3.6056
53.47500, 0.50, 11.0, 3.3166
53.52500, 0.50, 12.0, 3.4641
53.57500, 0.50, 7.0, 2.6458
53.62500, 0.50, 7.0, 2.6458
53.67500, 0.50, 12.0, 3.4641
53.72500, 0.50, 6.0, 2.4495
53.77500, 0.50, 12.0, 3.4641
53.82500, 0.50, 13.0, 3.6056
53.87500, 0.50, 9.0, 3.0000
53.92500, 0.50, 8.0, 2.8284
53.97500, 0.50, 10.0, 3.1623
54.02500, 0.50, 13.0, 3.6056
54.07500, 0.50, 7.0, 2.6458
54.12500, 0.50, 14.0, 3.7417
54.17500, 0.50, 7.0, 2.6458
54.22500, 0.50, 5.0, 2.2361
54.27500, 0.50, 10.0, 3.1623
54.32500, 0.50, 14.0, 3.7417
54.37500, 0.50, 13.0, 3.6056
54.42500, 0.50, 12.0, 3.4641
54.47500, 0.50, 14.0, 3.7417
54.52500, 0.50, 10.0, 3.1623
54.57500, 0.50, 16.0, 4.0000
54.62500, 0.50, 12.0, 3.4641
54.67500, 0.50, 7.0, 2.6458
54.72500, 0.50, 12.0, 3.4641
54.77500, 0.50, 11.0, 3.3166
54.82500, 0.50, 13.0, 3.6056
54.87500, 0.50, 10.0, 3.1623
54.92500, 0.50, 9.0, 3.0000
54.97500, 0.50, 7.0, 2.6458
55.02500, 0.50, 11.0, 3.3166
55.07500, 0.50, 10.0, 3.1623
55.12500, 0.50, 11.0, 3.3166
55.17500, 0.50, 10.0, 3.1623
55.22500, 0.50, 8.0, 2.8284
55.27500, 0.50, 7.0, 2.6458
55.32500, 0.50, 10.0, 3.1623
55.37500, 0.50, 12.0, 3.4641
55.42500, 0.50, 8.0, 2.8284
55.47500, 0.50, 11.0, 3.3166
55.52500, 0.50, 4.0, 2.0000
55.57500, 0.50, 11.0, 3.3166
55.62500, 0.50, 7.0, 2.6458
55.67500, 0.50, 10.0, 3.1623
55.72500, 0.50, 6.0, 2.4495
55.77500, 0.50, 7.0, 2.6458
55.82500, 0.50, 12.0, 3.4641
55.87500, 0.50, 6.0, 2.4495
55.92500, 0.50, 10.0, 3.1623
55.97500, 0.50, 7.0, 2.6458
56.02500, 0.50, 10.0, 3.1623
56.07500, 0.50, 3.0, 1.7321
56.12500, 0.50, 9.0, 3.0000
56.17500, 0.50, 17.0, 4.1231
56.22500, 0.50, 6.0, 2.4495
56.27500, 0.50, 10.0, 3.1623
56.32500, 0.50, 10.0, 3.1623
56.37500, 0.50, 13.0, 3.6056
56.42500, 0.50, 13.0, 3.6056
56.47500, 0.50, 10.0, 3.1623
56.52500, 0.50, 8.0, 2.8284
56.57500, 0.50, 10.0, 3.1623
56.62500, 0.50, 15.0, 3.8730
56.67500, 0.50, 8.0, 2.8284
56.72500, 0.50, 13.0, 3.6056
56.77500, 0.50, 16.0, 4.0000
56.82500, 0.50, 12.0, 3.4641
56.87500, 0.50, 7.0, 2.6458
56.92500, 0.50, 8.0, 2.8284
56.97500, 0.50, 10.0, 3.1623
57.02500, 0.50, 10.0, 3.1623
57.07500, 0.50, 3.0, 1.7321
57.12500, 0.50, 9.0, 3.0000
57.17500, 0.50, 11.0, 3.3166
57.22500, 0.50, 11.0, 3.3166
57.27500, 0.50, 14.0, 3.7417
57.32500, 0.50, 5.0, 2.2361
57.37500, 0.50, 13.0, 3.6056
57.42500, 0.50, 15.0, 3.8730
57.47500, 0.50, 6.0, 2.4495
57.52500, 0.50, 12.0, 3.4641
57.57500, 0.50, 6.0, 2.4495
57.62500, 0.50, 13.0, 3.6056
57.67500, 0.50, 9.0, 3.0000
57.72500, 0.50, 3.0, 1.7321
57.77500, 0.50, 7.0, 2.6458
57.82500, 0.50, 15.0, 3.8730
57.87500, 0.50, 12.0, 3.4641
57.92500, 0.50, 8.0, 2.8284
57.97500, 0.50, 3.0, 1.7321
58.02500, 0.50, 5.0, 2.2361
58.07500, 0.50, 12.0, 3.4641
58.12500, 0.50, 12.0, 3.4641
58.17500, 0.50, 14.0, 3.7417
58.22500, 0.50, 10.0, 3.1623
58.27500, 0.50, 6.0, 2.4495
58.32500, 0.50, 7.0, 2.6458
58.37500, 0.50, 9.0, 3.0000
58.42500, 0.50, 8.0, 2.8284
58.47500, 0.50, 6.0, 2.4495
58.52500, 0.50, 10.0, 3.1623
58.57500, 0.50, 8.0, 2.8284
58.62500, 0.50, 6.0, 2.4495
58.67500, 0.50, 5.0, 2.2361
58.72500, 0.50, 12.0, 3.4641
58.77500, 0.50, 9.0, 3.0000
58.82500, 0.50, 14.0, 3.7417
58.87500, 0.50, 8.0, 2.8284
58.92500, 0.50, 9.0, 3.0000
58.97500, 0.50, 5.0, 2.2361
59.02500, 0.50, 7.0, 2.6458
59.07500, 0.50, 10.0, 3.1623
59.12500, 0.50, 11.0, 3.3166
59.17500, 0.50, 7.0, 2.6458
59.22500, 0.50, 13.0, 3.6056
59.27500, 0.50, 6.0, 2.4495
59.32500, 0.50, 8.0, 2.8284
59.37500, 0.50, 4.0, 2.0000
59.42500, 0.50, 7.0, 2.6458
59.47500, 0.50, 9.0, 3.0000
59.52500, 0.50, 10.0, 3.1623
59.57500, 0.50, 9.0, 3.0000
59.62500, 0.50, 6.0, 2.4495
59.67500, 0.50, 11.0, 3.3166
59.72500, 0.50, 6.0, 2.4495
59.77500, 0.50, 8.0, 2.8284
59.82500, 0.50, 10.0, 3.1623
59.87500, 0.50, 9.0, 3.0000
59.92500, 0.50, 7.0, 2.6458
59.97500, 0.50, 12.0, 3.4641
60.02500, 0.50, 8.0, 2.8284
60.07500, 0.50, 6.0, 2.4495
60.12500, 0.50, 4.0, 2.0000
60.17500, 0.50, 13.0, 3.6056
60.22500, 0.50, 10.0, 3.1623
60.27500, 0.50, 7.0, 2.6458
60.32500, 0.50, 6.0, 2.4495
60.37500, 0.50, 17.0, 4.1231
60.42500, 0.50, 5.0, 2.2361
60.47500, 0.50, 7.0, 2.6458
60.52500, 0.50, 7.0, 2.6458
60.57500, 0.50, 5.0, 2.2361
60.62500, 0.50, 9.0, 3.0000
60.67500, 0.50, 7.0, 2.6458
60.72500, 0.50, 6.0, 2.4495
60.77500, 0.50, 11.0, 3.3166
60.82500, 0.50, 14.0, 3.7417
60.87500, 0.50, 4.0, 2.0000
60.92500, 0.50, 5.0, 2.2361
60.97500, 0.50, 11.0, 3.3166
61.02500, 0.50, 7.0, 2.6458
61.07500, 0.50, 10.0, 3.1623
61.12500, 0.50, 10.0, 3.1623
61.17500, 0.50, 14.0, 3.7417
61.22500, 0.50, 9.0, 3.0000
61.27500, 0.50, 12.0, 3.4641
61.32500, 0.50, 8.0, 2.8284
61.37500, 0.50, 11.0, 3.3166
61.42500, 0.50, 14.0, 3.7417
61.47500, 0.50, 6.0, 2.4495
61.52500, 0.50, 14.0, 3.7417
61.57500, 0.50, 5.0, 2.2361
61.62500, 0.50, 9.0, 3.0000
61.67500, 0.50, 4.0, 2.0000
61.72500, 0.50, 9.0, 3.0000
61.77500, 0.50, 6.0, 2.4495
61.82500, 0.50, 6.0, 2.4495
61.87500, 0.50, 14.0, 3.7417
61.92500, 0.50, 9.0, 3.0000
61.97500, 0.50, 11.0, 3.3166
62.02500, 0.50, 5.0, 2.2361
62.07500, 0.50, 9.0, 3.0000
62.12500, 0.50, 10.0, 3.1623
62.17500, 0.50, 7.0, 2.6458
62.22500, 0.50, 7.0, 2.6458
62.27500, 0.50, 11.0, 3.3166
62.32500, 0.50, 9.0, 3.0000
62.37500, 0.50, 7.0, 2.6458
62.42500, 0.50, 7.0, 2.6458
62.47500, 0.50, 5.0, 2.2361
62.52500, 0.50, 4.0, 2.0000
62.57500, 0.50, 9.0, 3.0000
62.62500, 0.50, 6.0, 2.4495
62.67500, 0.50, 10.0, 3.1623
62.72500, 0.50, 14.0, 3.7417
62.77500, 0.50, 14.0, 3.7417
62.82500, 0.50, 20.0, 4.4721
62.87500, 0.50, 12.0, 3.4641
62.92500, 0.50, 15.0, 3.8730
62.97500, 0.50, 8.0, 2.8284
63.02500, 0.50, 12.0, 3.4641
63.07500, 0.50, 16.0, 4.0000
63.12500, 0.50, 9.0, 3.0000
63.17500, 0.50, 20.0, 4.4721
63.22500, 0.50, 14.0, 3.7417
63.27500, 0.50, 7.0, 2.6458
63.32500, 0.50, 11.0, 3.3166
63.37500, 0.50, 12.0, 3.4641
63.42500, 0.50, 10.0, 3.1623
63.47500, 0.50, 8.0, 2.8284
63.52500, 0.50, 12.0, 3.4641
63.57500, 0.50, 12.0, 3.4641
63.62500, 0.50, 14.0, 3.7417
63.67500, 0.50, 13.0, 3.6056
63.72500, 0.50, 19.0, 4.3589
63.77500, 0.50, 21.0, 4.5826
63.82500, 0.50, 26.0, 5.0990
63.87500, 0.50, 17.0, 4.1231
63.92500, 0.50, 16.0, 4.0000
63.97500, 0.50, 20.0, 4.4721
64.02500, 0.50, 25.0, 5.0000
64.07500, 0.50, 41.0, 6.4031
64.12500, 0.50, 43.0, 6.5574
64.17500, 0.50, 46.0, 6.7823
64.22500, 0.50, 94.0, 9.6954
64.27500, 0.50, 136.0, 11.6619
64.32500, 0.50, 194.0, 13.9284
64.37500, 0.50, 285.0, 16.8819
64.42500, 0.50, 328.0, 18.1108
64.47500, 0.50, 312.0, 17.6635
64.52500, 0.50, 264.0, 16.2481
64.57500, 0.50, 246.0, 15.6844
64.62500, 0.50, 202.0, 14.2127
64.67500, 0.50, 148.0, 12.1655
64.72500, 0.50, 92.0, 9.5917
64.77500, 0.50, 52.0, 7.2111
64.82500, 0.50, 53.0, 7.2801
64.87500, 0.50, 31.0, 5.5678
64.92500, 0.50, 25.0, 5.0000
64.97500, 0.50, 19.0, 4.3589
65.02500, 0.50, 13.0, 3.6056
65.07500, 0.50, 16.0, 4.0000
65.12500, 0.50, 22.0, 4.6904
65.17500, 0.50, 14.0, 3.7417
65.22500, 0.50, 15.0, 3.8730
65.27500, 0.50, 10.0, 3.1623
65.32500, 0.50, 15.0, 3.8730
65.37500, 0.50, 12.0, 3.4641
65.42500, 0.50, 21.0, 4.5826
65.47500, 0.50, 16.0, 4.0000
65.52500, 0.50, 10.0, 3.1623
65.57500, 0.50, 9.0, 3.0000
65.62500, 0.50, 8.0, 2.8284
65.67500, 0.50, 7.0, 2.6458
65.72500, 0.50, 10.0, 3.1623
65.77500, 0.50, 21.0, 4.5826
65.82500, 0.50, 16.0, 4.0000
65.87500, 0.50, 13.0, 3.6056
65.92500, 0.50, 8.0, 2.8284
65.97500, 0.50, 9.0, 3.0000
66.02500, 0.50, 11.0, 3.3166
66.07500, 0.50, 11.0, 3.3166
66.12500, 0.50, 9.0, 3.0000
66.17500, 0.50, 8.0, 2.8284
66.22500, 0.50, 8.0, 2.8284
66.27500, 0.50, 5.0, 2.2361
66.32500, 0.50, 10.0, 3.1623
66.37500, 0.50, 9.0, 3.0000
66.42500, 0.50, 12.0, 3.4641
66.47500, 0.50, 12.0, 3.4641
66.52500, 0.50, 10.0, 3.1623
66.57500, 0.50, 6.0, 2.4495
66.62500, 0.50, 7.0, 2.6458
66.67500, 0.50, 7.0, 2.6458
66.72500, 0.50, 15.0, 3.8730
66.77500, 0.50, 11.0, 3.3166
66.82500, 0.50, 11.0, 3.3166
66.87500, 0.50, 9.0, 3.0000
66.92500, 0.50, 12.0, 3.4641
66.97500, 0.50, 10.0, 3.1623
67.02500, 0.50, 14.0, 3.7417
67.07500, 0.50, 14.0, 3.7417
67.12500, 0.50, 6.0, 2.4495
67.17500, 0.50, 5.0, 2.2361
67.22500, 0.50, 13.0, 3.6056
67.27500, 0.50, 5.0, 2.2361
67.32500, 0.50, 9.0, 3.0000
67.37500, 0.50, 9.0, 3.0000
67.42500, 0.50, 8.0, 2.8284
67.47500, 0.50, 7.0, 2.6458
67.52500, 0.50, 6.0, 2.4495
67.57500, 0.50, 10.0, 3.1623
67.62500, 0.50, 8.0, 2.8284
67.67500, 0.50, 13.0, 3.6056
67.72500, 0.50, 4.0, 2.0000
67.77500, 0.50, 6.0, 2.4495
67.82500, 0.50, 13.0, 3.6056
67.87500, 0.50, 9.0, 3.0000
67.92500, 0.50, 8.0, 2.8284
67.97500, 0.50, 7.0, 2.6458
68.02500, 0.50, 9.0, 3.0000
68.07500, 0.50, 10.0, 3.1623
68.12500, 0.50, 7.0, 2.6458
68.17500, 0.50, 9.0, 3.0000
68.22500, 0.50, 5.0, 2.2361
68.27500, 0.50, 6.0, 2.4495
68.32500, 0.50, 8.0, 2.8284
68.37500, 0.50, 8.0, 2.8284
68.42500, 0.50, 4.0, 2.0000
68.47500, 0.50, 9.0, 3.0000
68.52500, 0.50, 13.0, 3.6056
68.57500, 0.50, 14.0, 3.7417
68.62500, 0.50, 7.0, 2.6458
68.67500, 0.50, 9.0, 3.0000
68.72500, 0.50, 6.0, 2.4495
68.77500, 0.50, 12.0, 3.4641
68.82500, 0.50, 11.0, 3.3166
68.87500, 0.50, 12.0, 3.4641
68.92500, 0.50, 11.0, 3.3166
68.97500, 0.50, 5.0, 2.2361
69.02500, 0.50, 4.0, 2.0000
69.07500, 0.50, 6.0, 2.4495
69.12500, 0.50, 7.0, 2.6458
69.17500, 0.50, 10.0, 3.1623
69.22500, 0.50, 8.0, 2.8284
69.27500, 0.50, 8.0, 2.8284
69.32500, 0.50, 5.0, 2.2361
69.37500, 0.50, 6.0, 2.4495
69.42500, 0.50, 5.0, 2.2361
69.47500, 0.50, 9.0, 3.0000
69.52500, 0.50, 7.0, 2.6458
69.57500, 0.50, 6.0, 2.4495
69.62500, 0.50, 6.0, 2.4495
69.67500, 0.50, 9.0, 3.0000
69.72500, 0.50, 8.0, 2.8284
69.77500, 0.50, 9.0, 3.0000
69.82500, 0.50, 8.0, 2.8284
69.87500, 0.50, 4.0, 2.0000
69.92500, 0.50, 8.0, 2.8284
69.97500, 0.50, 13.0, 3.6056
70.02500, 0.50, 8.0, 2.8284
70.07500, 0.50, 7.0, 2.6458
70.12500, 0.50, 6.0, 2.4495
70.17500, 0.50, 4.0, 2.0000
70.22500, 0.50, 8.0, 2.8284
70.27500, 0.50, 12.0, 3.4641
70.32500, 0.50, 6.0, 2.4495
70.37500, 0.50, 9.0, 3.0000
70.42500, 0.50, 7.0, 2.6458
70.47500, 0.50, 7.0, 2.6458
70.52500, 0.50, 4.0, 2.0000
70.57500, 0.50, 12.0, 3.4641
70.62500, 0.50, 8.0, 2.8284
70.67500, 0.50, 9.0, 3.0000
70.72500, 0.50, 6.0, 2.4495
70.77500, 0.50, 12.0, 3.4641
70.82500, 0.50, 6.0, 2.4495
70.87500, 0.50, 10.0, 3.1623
70.92500, 0.50, 3.0, 1.7321
70.97500, 0.50, 11.0, 3.3166
71.02500, 0.50, 13.0, 3.6056
71.07500, 0.50, 6.0, 2.4495
71.12500, 0.50, 6.0, 2.4495
71.17500, 0.50, 7.0, 2.6458
71.22500, 0.50, 5.0, 2.2361
71.27500, 0.50, 4.0, 2.0000
71.32500, 0.50, 5.0, 2.2361
71.37500, 0.50, 7.0, 2.6458
71.42500, 0.50, 7.0, 2.6458
71.47500, 0.50, 10.0, 3.1623
71.52500, 0.50, 10.0, 3.1623
71.57500, 0.50, 8.0, 2.8284
71.62500, 0.50, 6.0, 2.4495
71.67500, 0.50, 11.0, 3.3166
71.72500, 0.50, 5.0, 2.2361
71.77500, 0.50, 6.0, 2.4495
71.82500, 0.50, 5.0, 2.2361
71.87500, 0.50, 7.0, 2.6458
71.92500, 0.50, 9.0, 3.0000
71.97500, 0.50, 7.0, 2.6458
72.02500, 0.50, 12.0, 3.4641
72.07500, 0.50, 3.0, 1.7321
72.12500, 0.50, 5.0, 2.2361
72.17500, 0.50, 11.0, 3.3166
72.22500, 0.50, 8.0, 2.8284
72.27500, 0.50, 9.0, 3.0000
72.32500, 0.50, 7.0, 2.6458
72.37500, 0.50, 8.0, 2.8284
72.42500, 0.50, 11.0, 3.3166
72.47500, 0.50, 8.0, 2.8284
72.52500, 0.50, 7.0, 2.6458
72.57500, 0.50, 9.0, 3.0000
72.62500, 0.50, 10.0, 3.1623
72.67500, 0.50, 7.0, 2.6458
72.72500, 0.50, 6.0, 2.4495
72.77500, 0.50, 8.0, 2.8284
72.82500, 0.50, 6.0, 2.4495
72.87500, 0.50, 10.0, 3.1623
72.92500, 0.50, 8.0, 2.8284
72.97500, 0.50, 13.0, 3.6056
73.02500, 0.50, 4.0, 2.0000
73.07500, 0.50, 4.0, 2.0000
73.12500, 0.50, 5.0, 2.2361
73.17500, 0.50, 6.0, 2.4495
73.22500, 0.50, 7.0, 2.6458
73.27500, 0.50, 13.0, 3.6056
73.32500, 0.50, 9.0, 3.0000
73.37500, 0.50, 8.0, 2.8284
73.42500, 0.50, 8.0, 2.8284
73.47500, 0.50, 14.0, 3.7417
73.52500, 0.50, 6.0, 2.4495
73.57500, 0.50, 11.0, 3.3166
73.62500, 0.50, 6.0, 2.4495
73.67500, 0.50, 11.0, 3.3166
73.72500, 0.50, 12.0, 3.4641
73.77500, 0.50, 9.0, 3.0000
73.82500, 0.50, 11.0, 3.3166
73.87500, 0.50, 9.0, 3.0000
73.92500, 0.50, 12.0, 3.4641
73.97500, 0.50, 8.0, 2.8284
74.02500, 0.50, 6.0, 2.4495
74.07500, 0.50, 5.0, 2.2361
74.12500, 0.50, 7.0, 2.6458
74.17500, 0.50, 5.0, 2.2361
74.22500, 0.50, 6.0, 2.4495
74.27500, 0.50, 4.0, 2.0000
74.32500, 0.50, 7.0, 2.6458
74.37500, 0.50, 9.0, 3.0000
74.42500, 0.50, 10.0, 3.1623
74.47500, 0.50, 5.0, 2.2361
74.52500, 0.50, 3.0, 1.7321
74.57500, 0.50, 7.0, 2.6458
74.62500, 0.50, 4.0, 2.0000
74.67500, 0.50, 7.0, 2.6458
74.72500, 0.50, 11.0, 3.3166
74.77500, 0.50, 7.0, 2.6458
74.82500, 0.50, 7.0, 2.6458
74.87500, 0.50, 9.0, 3.0000
74.92500, 0.50, 4.0, 2.0000
74.97500, 0.50, 10.0, 3.1623
75.02500, 0.50, 9.0, 3.0000
75.07500, 0.50, 8.0, 2.8284
75.12500, 0.50, 9.0, 3.0000
75.17500, 0.50, 10.0, 3.1623
75.22500, 0.50, 8.0, 2.8284
75.27500, 0.50, 13.0, 3.6056
75.32500, 0.50, 7.0, 2.6458
75.37500, 0.50, 10.0, 3.1623
75.42500, 0.50, 5.0, 2.2361
75.47500, 0.50, 6.0, 2.4495
75.52500, 0.50, 9.0, 3.0000
75.57500, 0.50, 8.0, 2.8284
75.62500, 0.50, 10.0, 3.1623
75.67500, 0.50, 11.0, 3.3166
75.72500, 0.50, 10.0, 3.1623
75.77500, 0.50, 12.0, 3.4641
75.82500, 0.50, 8.0, 2.8284
75.87500, 0.50, 10.0, 3.1623
75.92500, 0.50, 8.0, 2.8284
75.97500, 0.50, 7.0, 2.6458
76.02500, 0.50, 12.0, 3.4641
76.07500, 0.50, 9.0, 3.0000
76.12500, 0.50, 9.0, 3.0000
76.17500, 0.50, 15.0, 3.8730
76.22500, 0.50, 10.0, 3.1623
76.27500, 0.50, 10.0, 3.1623
76.32500, 0.50, 5.0, 2.2361
76.37500, 0.50, 11.0, 3.3166
76.42500, 0.50, 9.0, 3.0000
76.47500, 0.50, 5.0, 2.2361
76.52500, 0.50, 12.0, 3.4641
76.57500, 0.50, 10.0, 3.1623
76.62500, 0.50, 14.0, 3.7417
76.67500, 0.50, 12.0, 3.4641
76.72500, 0.50, 12.0, 3.4641
76.77500, 0.50, 20.0, 4.4721
76.82500, 0.50, 24.0, 4.8990
76.87500, 0.50, 21.0, 4.5826
76.92500, 0.50, 34.0, 5.8310
76.97500, 0.50, 24.0, 4.8990
77.02500, 0.50, 41.0, 6.4031
77.07500, 0.50, 55.0, 7.4162
77.12500, 0.50, 87.0, 9.3274
77.17500, 0.50, 109.0, 10.4403
77.22500, 0.50, 126.0, 11.2250
77.27500, 0.50, 187.0, 13.6748
77.32500, 0.50, 215.0, 14.6629
77.37500, 0.50, 290.0, 17.0294
77.42500, 0.50, 264.0, 16.2481
77.47500, 0.50, 218.0, 14.7648
77.52500, 0.50, 206.0, 14.3527
77.57500, 0.50, 184.0, 13.5647
77.62500, 0.50, 143.0, 11.9583
77.67500, 0.50, 138.0, 11.7473
77.72500, 0.50, 84.0, 9.1652
77.77500, 0.50, 74.0, 8.6023
77.82500, 0.50, 52.0, 7.2111
77.87500, 0.50, 54.0, 7.3485
77.92500, 0.50, 30.0, 5.4772
77.97500, 0.50, 31.0, 5.5678
78.02500, 0.50, 18.0, 4.2426
78.07500, 0.50, 24.0, 4.8990
78.12500, 0.50, 23.0, 4.7958
78.17500, 0.50, 11.0, 3.3166
78.22500, 0.50, 9.0, 3.0000
78.27500, 0.50, 9.0, 3.0000
78.32500, 0.50, 17.0, 4.1231
78.37500, 0.50, 8.0, 2.8284
78.42500, 0.50, 11.0, 3.3166
78.47500, 0.50, 4.0, 2.0000
78.52500, 0.50, 7.0, 2.6458
78.57500, 0.50, 6.0, 2.4495
78.62500, 0.50, 7.0, 2.6458
78.67500, 0.50, 6.0, 2.4495
78.72500, 0.50, 11.0, 3.3166
78.77500, 0.50, 3.0, 1.7321
78.82500, 0.50, 11.0, 3.3166
78.87500, 0.50, 10.0, 3.1623
78.92500, 0.50, 14.0, 3.7417
78.97500, 0.50, 11.0, 3.3166
79.02500, 0.50, 8.0, 2.8284
79.07500, 0.50, 2.0, 1.4142
79.12500, 0.50, 9.0, 3.0000
79.17500, 0.50, 8.0, 2.8284
79.22500, 0.50, 11.0, 3.3166
79.27500, 0.50, 10.0, 3.1623
79.32500, 0.50, 13.0, 3.6056
79.37500, 0.50, 7.0, 2.6458
79.42500, 0.50, 6.0, 2.4495
79.47500, 0.50, 15.0, 3.8730
79.52500, 0.50, 7.0, 2.6458
79.57500, 0.50, 8.0, 2.8284
79.62500, 0.50, 8.0, 2.8284
79.67500, 0.50, 7.0, 2.6458
79.72500, 0.50, 9.0, 3.0000
79.77500, 0.50, 10.0, 3.1623
79.82500, 0.50, 7.0, 2.6458
79.87500, 0.50, 5.0, 2.2361
79.92500, 0.50, 6.0, 2.4495
79.97500, 0.50, 6.0, 2.4495